Workbook

Sheet Statistics

Sheet Album
A1: Id | B1: Artist | C1: Title | D1: Year | E1: TrackCount | F1: Type | G1: Category | H1: Notes | I1: Path | J1: Exclude | K1: In List?
A2: 1 | B2: Passion | C2: Our Soul's Desire | D2: 1997 | E2: 14 | F2: Live | K2: =IF(COUNTIF(Track!$B:$B,C2)>0,"","NO")
A3: 2 | B3: Passion | C3: Live Worship from the 268 Generation | D3: 1998 | E3: 13 | F3: Live | I3: AlbumArt/600/Live Worship from the 268 Generation.jpg | K3: =IF(COUNTIF(Track!$B:$B,C3)>0,"","NO")
A4: 3 | B4: Passion | C4: Better Is One Day | D4: 1999 | E4: 12 | F4: Live | I4: AlbumArt/600/Better Is One Day.jpg | K4: =IF(COUNTIF(Track!$B:$B,C4)>0,"","NO")
A5: 4 | B5: Passion | C5: One Day Live | D5: 2000 | E5: 12 | F5: Live | I5: AlbumArt/600/One Day Live.jpg | K5: =IF(COUNTIF(Track!$B:$B,C5)>0,"","NO")
A6: 5 | B6: Passion | C6: The Road to One Day | D6: 2000 | E6: 12 | F6: Studio | I6: AlbumArt/600/The Road to One Day.jpg | K6: =IF(COUNTIF(Track!$B:$B,C6)>0,"","NO")
A7: 6 | B7: Passion | C7: Our Love is Loud | D7: 2002 | E7: 13 | F7: Live | I7: AlbumArt/600/Our Love is Loud.jpg | K7: =IF(COUNTIF(Track!$B:$B,C7)>0,"","NO")
A8: 7 | B8: Passion | C8: Sacred Revolution: Songs From OneDay 03 | D8: 2003 | E8: 13 | F8: Live | I8: AlbumArt/600/Sacred Revolution.jpg | K8: =IF(COUNTIF(Track!$B:$B,C8)>0,"","NO")
A9: 8 | B9: Passion | C9: Hymns Ancient and Modern | D9: 2004 | E9: 14 | F9: Live | I9: AlbumArt/600/Hymns Ancient and Modern.jpg | K9: =IF(COUNTIF(Track!$B:$B,C9)>0,"","NO")
A10: 9 | B10: Passion | C10: How Great Is Our God | D10: 2005 | E10: 13 | F10: Live | I10: AlbumArt/600/How Great Is Our God.jpg | K10: =IF(COUNTIF(Track!$B:$B,C10)>0,"","NO")
A11: 10 | B11: Passion | C11: Passion 05 | D11: 2005 | E11: 2 | F11: Compilation | I11: AlbumArt/600/Passion 05.jpg | K11: =IF(COUNTIF(Track!$B:$B,C11)>0,"","NO")
A12: 11 | B12: Passion | C12: Everything Glorious | D12: 2006 | E12: 13 | F12: Live | I12: AlbumArt/600/Everything Glorious.jpg | K12: =IF(COUNTIF(Track!$B:$B,C12)>0,"","NO")
A13: 12 | B13: Passion | C13: The Best of Passion (So Far) | D13: 2006 | E13: 30 | F13: Compilation | I13: AlbumArt/600/The Best of Passion (So Far).jpg | J13: Exclude | K13: =IF(COUNTIF(Track!$B:$B,C13)>0,"","NO") -> NO
A14: 13 | B14: Passion | C14: The Early Session | D14: 2006 | E14: 4 | F14: Compilation | I14: AlbumArt/600/The Early Session 01.jpg | K14: =IF(COUNTIF(Track!$B:$B,C14)>0,"","NO")
A15: 14 | B15: Passion | C15: Live From Passion07 | D15: 2007 | E15: 6 | F15: Compilation | I15: AlbumArt/600/Live From Passion07 Pt. 1.jpg | K15: =IF(COUNTIF(Track!$B:$B,C15)>0,"","NO")
A16: 15 | B16: Passion | C16: A Generation United for His Renown | D16: 2008 | E16: 14 | F16: Compilation | I16: AlbumArt/600/A Generation United for His Renown.jpg | K16: =IF(COUNTIF(Track!$B:$B,C16)>0,"","NO")
A17: 16 | B17: Passion | C17: God of This City | D17: 2008 | E17: 14 | F17: Live | I17: AlbumArt/600/God of This City.jpg | K17: =IF(COUNTIF(Track!$B:$B,C17)>0,"","NO")
A18: 17 | B18: Passion | C18: Awakening | D18: 2010 | E18: 12 | F18: Live | I18: AlbumArt/600/Awakening.jpg | K18: =IF(COUNTIF(Track!$B:$B,C18)>0,"","NO")
A19: 18 | B19: Passion | C19: Here for You | D19: 2011 | E19: 15 | F19: Live | I19: AlbumArt/600/Here for You.jpg | K19: =IF(COUNTIF(Track!$B:$B,C19)>0,"","NO")
A20: 19 | B20: Passion | C20: White Flag | D20: 2012 | E20: 17 | F20: Live | I20: AlbumArt/600/White Flag.jpg | K20: =IF(COUNTIF(Track!$B:$B,C20)>0,"","NO")
A21: 20 | B21: Passion | C21: Let the Future Begin | D21: 2013 | E21: 15 | F21: Live | I21: AlbumArt/600/Let the Future Begin.jpg | K21: =IF(COUNTIF(Track!$B:$B,C21)>0,"","NO")
A22: 21 | B22: Passion | C22: Take It All | D22: 2014 | E22: 14 | F22: Live | I22: AlbumArt/600/Take It All.jpg | K22: =IF(COUNTIF(Track!$B:$B,C22)>0,"","NO")
A23: 22 | B23: Passion | C23: The Essential Collection | D23: 2014 | E23: 15 | F23: Compilation | I23: AlbumArt/600/The Essential Collection.jpg | J23: Exclude | K23: =IF(COUNTIF(Track!$B:$B,C23)>0,"","NO") -> NO
A24: 23 | B24: Passion | C24: Even So Come | D24: 2015 | E24: 16 | F24: Live | I24: AlbumArt/600/Even So Come.jpg | K24: =IF(COUNTIF(Track!$B:$B,C24)>0,"","NO")
A25: 24 | B25: Passion | C25: Salvation's Tide Is Rising | D25: 2016 | E25: 10 | F25: Studio | I25: AlbumArt/600/Salvation's Tide Is Rising.jpg | K25: =IF(COUNTIF(Track!$B:$B,C25)>0,"","NO")
A26: 25 | B26: Passion | C26: Glorioso Día | D26: 2017 | F26: Studio | I26: AlbumArt/600/Glorioso D¡a.jpg | J26: Exclude | K26: =IF(COUNTIF(Track!$B:$B,C26)>0,"","NO") -> NO
A27: 26 | B27: Passion | C27: Worthy of Your Name | D27: 2017 | E27: 13 | F27: Live | I27: AlbumArt/600/Worthy of Your Name.jpg | K27: =IF(COUNTIF(Track!$B:$B,C27)>0,"","NO")
A28: 27 | B28: Passion | C28: Whole Heart | D28: 2018 | E28: 11 | F28: Live | I28: AlbumArt/600/Whole Heart.jpg | K28: =IF(COUNTIF(Track!$B:$B,C28)>0,"","NO")
A29: 28 | B29: Passion | C29: Behold The Lamb | D29: 2019 | E29: 2 | F29: Live | I29: AlbumArt/600/Behold The Lamb.jpg | K29: =IF(COUNTIF(Track!$B:$B,C29)>0,"","NO")
A30: 29 | B30: Passion | C30: Follow You Anywhere | D30: 2019 | E30: 10 | F30: Live | I30: AlbumArt/600/Follow You Anywhere.jpg | K30: =IF(COUNTIF(Track!$B:$B,C30)>0,"","NO")
A31: 30 | B31: Passion | C31: Hope Has A Name | D31: 2020 | E31: 7 | F31: Studio | I31: AlbumArt/600/Hope Has A Name.jpg | K31: =IF(COUNTIF(Track!$B:$B,C31)>0,"","NO")
A32: 31 | B32: Passion | C32: Passion Collection | D32: 2020 | E32: 58 | F32: Compilation | I32: AlbumArt/600/Passion Collection.jpg | J32: Exclude | K32: =IF(COUNTIF(Track!$B:$B,C32)>0,"","NO") -> NO
A33: 32 | B33: Passion | C33: Roar (Live from Passion 2020) | D33: 2020 | E33: 12 | F33: Live | I33: AlbumArt/600/Roar (Live from Passion 2020).jpg | K33: =IF(COUNTIF(Track!$B:$B,C33)>0,"","NO")

Sheet Track
A1: Id | B1: Album | C1: Year | D1: Track | E1: Title | F1: AltTitle | G1: CcliNumber | H1: Author | I1: Key | J1: Tempo | K1: Performer | L1: Notes
B2: Our Soul's Desire | C2: 1997 | D2: 1 | E2: Glorify | G2: =INDEX([1]Songs!$L:$L,MATCH(E2,[1]Songs!$E:$E,0)) -> #N/A
B3: Our Soul's Desire | C3: 1997 | D3: 2 | E3: Sweet Wind | G3: =INDEX([1]Songs!$L:$L,MATCH(E3,[1]Songs!$E:$E,0)) -> #N/A
B4: Our Soul's Desire | C4: 1997 | D4: 3 | E4: As We Pray | G4: =INDEX([1]Songs!$L:$L,MATCH(E4,[1]Songs!$E:$E,0)) -> #N/A
B5: Our Soul's Desire | C5: 1997 | D5: 4 | E5: You Are Worthy of My Praise | G5: =INDEX([1]Songs!$L:$L,MATCH(E5,[1]Songs!$E:$E,0)) -> #N/A
B6: Our Soul's Desire | C6: 1997 | D6: 5 | E6: Lord Of The Heavens | G6: =INDEX([1]Songs!$L:$L,MATCH(E6,[1]Songs!$E:$E,0)) -> #N/A
B7: Our Soul's Desire | C7: 1997 | D7: 6 | E7: Break Our Hearts | G7: =INDEX([1]Songs!$L:$L,MATCH(E7,[1]Songs!$E:$E,0)) -> #N/A
B8: Our Soul's Desire | C8: 1997 | D8: 7 | E8: We Fall Down | G8: =INDEX([1]Songs!$L:$L,MATCH(E8,[1]Songs!$E:$E,0)) -> #N/A
B9: Our Soul's Desire | C9: 1997 | D9: 8 | E9: Mercy Rain | G9: =INDEX([1]Songs!$L:$L,MATCH(E9,[1]Songs!$E:$E,0)) -> #N/A
B10: Our Soul's Desire | C10: 1997 | D10: 9 | E10: Spirit Fall On Me | G10: =INDEX([1]Songs!$L:$L,MATCH(E10,[1]Songs!$E:$E,0)) -> #N/A
B11: Our Soul's Desire | C11: 1997 | D11: 10 | E11: You Alone | G11: =INDEX([1]Songs!$L:$L,MATCH(E11,[1]Songs!$E:$E,0)) -> #N/A
B12: Our Soul's Desire | C12: 1997 | D12: 11 | E12: Amazing Love | G12: =INDEX([1]Songs!$L:$L,MATCH(E12,[1]Songs!$E:$E,0)) -> #N/A
B13: Our Soul's Desire | C13: 1997 | D13: 12 | E13: O For A Thousand Tounges To Sing | G13: =INDEX([1]Songs!$L:$L,MATCH(E13,[1]Songs!$E:$E,0)) -> #N/A
... B52: One Day Live | C52: 2000 | D52: 12 | E52: America | G52: =INDEX([1]Songs!$L:$L,MATCH(E52,[1]Songs!$E:$E,0)) -> #N/A
B53: The Road to One Day | C53: 2000 | D53: 1 | E53: Salvation | G53: =INDEX([1]Songs!$L:$L,MATCH(E53,[1]Songs!$E:$E,0)) -> #N/A | H53: Charlie Hall
B54: The Road to One Day | C54: 2000 | D54: 2 | E54: Shout To The North | G54: =INDEX([1]Songs!$L:$L,MATCH(E54,[1]Songs!$E:$E,0)) -> #N/A | H54: Charlie Hall
B55: The Road to One Day | C55: 2000 | D55: 3 | E55: The Noise We Make | G55: =INDEX([1]Songs!$L:$L,MATCH(E55,[1]Songs!$E:$E,0)) -> #N/A | H55: Chris Tomlin
B56: The Road to One Day | C56: 2000 | D56: 4 | E56: Break Our Hearts | G56: =INDEX([1]Songs!$L:$L,MATCH(E56,[1]Songs!$E:$E,0)) -> #N/A | H56: Shelley Nirider
B57: The Road to One Day | C57: 2000 | D57: 5 | E57: Make A Joyful Noise / I Will Not Be Silent | G57: =INDEX([1]Songs!$L:$L,MATCH(E57,[1]Songs!$E:$E,0)) -> #N/A | H57: David Crowder
B58: The Road to One Day | C58: 2000 | D58: 6 | E58: Kindness | G58: =INDEX([1]Songs!$L:$L,MATCH(E58,[1]Songs!$E:$E,0)) -> #N/A | H58: Chris Tomlin
B59: The Road to One Day | C59: 2000 | D59: 7 | E59: Holy Visitation | G59: =INDEX([1]Songs!$L:$L,MATCH(E59,[1]Songs!$E:$E,0)) -> #N/A | H59: Charlie Hall
B60: The Road to One Day | C60: 2000 | D60: 8 | E60: We Are Hungry | G60: =INDEX([1]Songs!$L:$L,MATCH(E60,[1]Songs!$E:$E,0)) -> #N/A | H60: Steve Fee
B61: The Road to One Day | C61: 2000 | D61: 9 | E61: Prelude | G61: =INDEX([1]Songs!$L:$L,MATCH(E61,[1]Songs!$E:$E,0)) -> #N/A
B62: The Road to One Day | C62: 2000 | D62: 10 | E62: Holy Roar | G62: =INDEX([1]Songs!$L:$L,MATCH(E62,[1]Songs!$E:$E,0)) -> #N/A | H62: Christy Nockels
B63: The Road to One Day | C63: 2000 | D63: 11 | E63: Did You Feel The Mountains Tremble? | G63: =INDEX([1]Songs!$L:$L,MATCH(E63,[1]Songs!$E:$E,0)) -> #N/A | H63: Matt Redman
B64: The Road to One Day | C64: 2000 | D64: 12 | E64: Jesus, Lover Of My Soul | G64: =INDEX([1]Songs!$L:$L,MATCH(E64,[1]Songs!$E:$E,0)) -> #N/A | H64: Shelly Nirider
B65: Our Love is Loud | C65: 2002 | D65: 1 | E65: Here I Am To Worship | G65: =INDEX([1]Songs!$L:$L,MATCH(E65,[1]Songs!$E:$E,0)) -> 3266032 | H65: Chris Tomlin
B66: Our Love is Loud | C66: 2002 | D66: 2 | E66: Enough | G66: =INDEX([1]Songs!$L:$L,MATCH(E66,[1]Songs!$E:$E,0)) -> 3599479 | H66: Chris Tomlin
B67: Our Love is Loud | C67: 2002 | D67: 3 | E67: Famous One | G67: =INDEX([1]Songs!$L:$L,MATCH(E67,[1]Songs!$E:$E,0)) -> #N/A | H67: Chris Tomlin
B68: Our Love is Loud | C68: 2002 | D68: 4 | E68: Prepare The Way | G68: =INDEX([1]Songs!$L:$L,MATCH(E68,[1]Songs!$E:$E,0)) -> #N/A | H68: Charlie Hall
B69: Our Love is Loud | C69: 2002 | D69: 5 | E69: Sweep Me Away | G69: =INDEX([1]Songs!$L:$L,MATCH(E69,[1]Songs!$E:$E,0)) -> #N/A | H69: Charlie Hall
B70: Our Love is Loud | C70: 2002 | D70: 6 | E70: Madly | G70: =INDEX([1]Songs!$L:$L,MATCH(E70,[1]Songs!$E:$E,0)) -> #N/A | H70: Charlie Hall
B71: Our Love is Loud | C71: 2002 | D71: 7 | E71: Psalm 126 | G71: =INDEX([1]Songs!$L:$L,MATCH(E71,[1]Songs!$E:$E,0)) -> #N/A | H71: Charlie Hall
B72: Our Love is Loud | C72: 2002 | D72: 8 | E72: Wonderful King | G72: =INDEX([1]Songs!$L:$L,MATCH(E72,[1]Songs!$E:$E,0)) -> #N/A | H72: David Crowder Band
B73: Our Love is Loud | C73: 2002 | D73: 9 | E73: Our Love Is Loud | G73: =INDEX([1]Songs!$L:$L,MATCH(E73,[1]Songs!$E:$E,0)) -> #N/A | H73: David Crowder Band
... B77: Our Love is Loud | C77: 2002 | D77: 13 | E77: Dance In The River | G77: =INDEX([1]Songs!$L:$L,MATCH(E77,[1]Songs!$E:$E,0)) -> #N/A | H77: Chris Tomlin
B78: Sacred Revolution: Songs From OneDay 03 | C78: 2003 | D78: 1 | E78: O Praise Him | F78: All This for a King | G78: =INDEX([1]Songs!$L:$L,MATCH(E78,[1]Songs!$E:$E,0)) -> 4158022
B79: Sacred Revolution: Songs From OneDay 03 | C79: 2003 | D79: 2 | E79: O Come Let Us Adore Him | G79: =INDEX([1]Songs!$L:$L,MATCH(E79,[1]Songs!$E:$E,0)) -> #N/A
B80: Sacred Revolution: Songs From OneDay 03 | C80: 2003 | D80: 3 | E80: Holy Is the Lord | G80: =INDEX([1]Songs!$L:$L,MATCH(E80,[1]Songs!$E:$E,0)) -> 4158039
B81: Sacred Revolution: Songs From OneDay 03 | C81: 2003 | D81: 4 | E81: Come Let Us Return to the Lord | G81: =INDEX([1]Songs!$L:$L,MATCH(E81,[1]Songs!$E:$E,0)) -> #N/A
...

Sheet Rejected Compilations
A1: # | B1: Year | C1: Album | D1: Track | E1: Title | F1: Alt Title | G1: Author | H1: Key | I1: Tempo | J1: CCLI# | K1: Notes
B2: 2006 | C2: The Best of Passion (So Far) | D2: 1 | E2: Come And Listen | G2: David Crowder Band
B3: 2006 | C3: The Best of Passion (So Far) | D3: 2 | E3: You Alone | G3: Sam Perry
B4: 2006 | C4: The Best of Passion (So Far) | D4: 3 | E4: His Renown | G4: Christy Nockels
B5: 2006 | C5: The Best of Passion (So Far) | D5: 4 | E5: You're Worthy Of My Praise | G5: Charlie Hall
B6: 2006 | C6: The Best of Passion (So Far) | D6: 5 | E6: You Are My King | F6: Amazing Love | G6: Christy Nockels
B7: 2006 | C7: The Best of Passion (So Far) | D7: 6 | E7: Better Is One Day | G7: Charlie Hall
B8: 2006 | C8: The Best of Passion (So Far) | D8: 7 | E8: Did You Feel The Mountains Tremble? | G8: Matt Redman
B9: 2006 | C9: The Best of Passion (So Far) | D9: 8 | E9: Salvation | G9: Charlie Hall
B10: 2006 | C10: The Best of Passion (So Far) | D10: 9 | E10: Grace Flows Down | G10: Christy Nockels
B11: 2006 | C11: The Best of Passion (So Far) | D11: 10 | E11: We Fall Down | G11: Chris Tomlin
B12: 2006 | C12: The Best of Passion (So Far) | D12: 11 | E12: Our Love Is Loud | G12: David Crowder Band
B13: 2006 | C13: The Best of Passion (So Far) | D13: 12 | E13: Enough | G13: Chris Tomlin
B14: 2006 | C14: The Best of Passion (So Far) | D14: 13 | E14: Famous One | G14: Chris Tomlin
B15: 2006 | C15: The Best of Passion (So Far) | D15: 14 | E15: Blessed Be The Name | G15: Matt Redman
B16: 2006 | C16: The Best of Passion (So Far) | D16: 15 | E16: How Great Thou Art | G16: Charlie Hall
B17: 2006 | C17: The Best of Passion (So Far) | D17: 16 | E17: Holy Is The Lord | G17: Chris Tomlin
B18: 2006 | C18: The Best of Passion (So Far) | D18: 17 | E18: O Praise Him | F18: All This For A King | G18: David Crowder Band
B19: 2006 | C19: The Best of Passion (So Far) | D19: 18 | E19: Sing To The King | G19: Candi Pearson
B20: 2006 | C20: The Best of Passion (So Far) | D20: 19 | E20: Take My Life | F20: And Let It Be | G20: Chris Tomlin
B21: 2006 | C21: The Best of Passion (So Far) | D21: 20 | E21: No One Like You | G21: David Crowder Band
B22: 2006 | C22: The Best of Passion (So Far) | D22: 21 | E22: Marvelous Light | G22: Charlie Hall
B23: 2006 | C23: The Best of Passion (So Far) | D23: 22 | E23: How Great Is Our God | G23: Chris Tomlin
B24: 2006 | C24: The Best of Passion (So Far) | D24: 23 | E24: Here Is Our King | G24: David Crowder Band
B25: 2006 | C25: The Best of Passion (So Far) | D25: 24 | E25: Indescribable | G25: Chris Tomlin
B26: 2006 | C26: The Best of Passion (So Far) | D26: 25 | E26: All Over The World | G26: Matt Redman
B27: 2006 | C27: The Best of Passion (So Far) | D27: 26 | E27: You Never Let Go | G27: Matt Redman
B28: 2006 | C28: The Best of Passion (So Far) | D28: 27 | E28: Jesus Paid It All | G28: Kristian Stanfill
B29: 2006 | C29: The Best of Passion (So Far) | D29: 28 | E29: You Are My Joy | G29: David Crowder Band
B30: 2006 | C30: The Best of Passion (So Far) | D30: 29 | E30: Glorious | G30: Chris Tomlin
B31: 2006 | C31: The Best of Passion (So Far) | D31: 30 | E31: Jesus Lover Of My Soul | G31: Shelley Nirider
B32: 2014 | C32: Passion: The Essential Collection | D32: 1 | E32: Holy Is The Lord | G32: Chris Tomlin
B33: 2014 | C33: Passion: The Essential Collection | D33: 2 | E33: One Thing Remains | G33: Kristian Stanfill
B34: 2014 | C34: Passion: The Essential Collection | D34: 3 | E34: 10,000 Reasons | F34: Bless the Lord | G34: Matt Redman
B35: 2014 | C35: Passion: The Essential Collection | D35: 4 | E35: Our God | G35: Chris Tomlin
B36: 2014 | C36: Passion: The Essential Collection | D36: 5 | E36: How He Loves | G36: David Crowder Band
B37: 2014 | C37: Passion: The Essential Collection | D37: 6 | E37: Healing Is In Your Hands | G37: Christy Nockels
B38: 2014 | C38: Passion: The Essential Collection | D38: 7 | E38: Whom Shall I Fear | F38: God of Angels Armies | G38: Chris Tomlin
B39: 2014 | C39: Passion: The Essential Collection | D39: 8 | E39: You Never Let Me Go | G39: Matt Redman
B40: 2014 | C40: Passion: The Essential Collection | D40: 9 | E40: Amazing Grace | F40: My Chains Are Gone | G40: Chris Tomlin
...
