Workbook

Sheet Statistics
A1: Section | B1: Publication Date | C1: Album | D1: Song Count
A2: 1990-1999 | B2: 1988 | C2: Spirit and Truth | D2: 11
B3: 1990 | C3: Show Your Glory | D3: 14
B4: 1992 | C4: The Power of Your Love | D4: 16
B5: 1993 | C5: Stone's Been Rolled Away | D5: 14
B6: 1994 | C6: People Just Like Us | D6: 14
B7: 1995 | C7: Friends in High Places | D7: 15
B8: 1996 | C8: God Is in the House | D8: 15
B9: 1997 | C9: All Things Are Possible | D9: 15
B10: 1998 | C10: Touching Heaven Changing Earth | D10: 15
B11: 1999 | C11: By Your Side | D11: 14 | E11: =SUM(D2:D11) -> 143
A12: 2000-2009 | B12: 2000 | C12: For This Cause | D12: 14
B13: 2001 | C13: You Are My World | D13: 13
B14: 2002 | C14: Blessed | D14: 14
B15: 2003 | C15: Hope | D15: 18
B16: 2004 | C16: For All You've Done | D16: 15
B17: 2005 | C17: God He Reigns | D17: 15
B18: 2006 | C18: Mighty to Save | D18: 14
B19: 2007 | C19: Saviour King | D19: 14
B20: 2008 | C20: This Is Our God | D20: 16
B21: 2009 | C21: Faith + Hope + Love | D21: 13 | E21: =SUM(D12:D21) -> 146
A22: 2010-2020 | B22: 2010 | C22: A Beautiful Exchange | D22: 13
B23: 2011 | C23: God Is Able | D23: 13
B24: 2012 | C24: Cornerstone | D24: 13
B25: 2013 | C25: Glorious Ruins | D25: 11
B26: 2014 | C26: No Other Name | D26: 11
B27: 2015 | C27: Open Heaven / River Wild | D27: 12
B28: 2016 | C28: Let There Be Light | D28: 12
B29: 2017 | C29: The Peace Project | D29: 12
B30: 2018 | C30: There Is More | D30: 12
B31: 2019 | C31: Awake | D31: 15
B32: 2020 | C32: Take Heart (Again) | D32: 12 | E32: =SUM(D22:D32) -> 136

Sheet Album
A1: Id | B1: Artist | C1: Title | D1: Year | E1: TrackCount | F1: Type | G1: Category | H1: Notes | I1: Path | J1: Exclude | K1: In List?
A2: 1 | B2: Hillsong Worship | C2: Spirit and Truth | D2: 1988 | E2: 11 | F2: Studio | I2: AlbumArt/600/Spirit and Truth.jpg | K2: =IF(COUNTIF(Track!$B:$B,C2)>0,"","NO")
A3: 2 | B3: Hillsong Worship | C3: Show Your Glory | D3: 1990 | E3: 14 | F3: Studio | I3: AlbumArt/600/Show Your Glory.jpg | K3: =IF(COUNTIF(Track!$B:$B,C3)>0,"","NO")
A4: 3 | B4: Hillsong Worship | C4: The Power of Your Love | D4: 1992 | E4: 16 | F4: Live | I4: AlbumArt/600/The Power of Your Love.jpg | K4: =IF(COUNTIF(Track!$B:$B,C4)>0,"","NO")
A5: 4 | B5: Hillsong Worship | C5: Stone's Been Rolled Away | D5: 1993 | E5: 14 | F5: Live | I5: AlbumArt/600/Stone's Been Rolled Away.jpg | K5: =IF(COUNTIF(Track!$B:$B,C5)>0,"","NO")
A6: 5 | B6: Hillsong Worship | C6: People Just Like Us | D6: 1994 | E6: 14 | F6: Live | I6: AlbumArt/600/People.jpg | K6: =IF(COUNTIF(Track!$B:$B,C6)>0,"","NO")
A7: 6 | B7: Hillsong Worship | C7: Friends in High Places | D7: 1995 | E7: 15 | F7: Live | I7: AlbumArt/600/Friends in High Places.jpg | K7: =IF(COUNTIF(Track!$B:$B,C7)>0,"","NO")
A8: 7 | B8: Hillsong Worship | C8: God Is in the House | D8: 1996 | E8: 15 | F8: Live | I8: AlbumArt/600/God Is in the House.jpg | K8: =IF(COUNTIF(Track!$B:$B,C8)>0,"","NO")
A9: 8 | B9: Hillsong Worship | C9: Shout To The Lord | D9: 1996 | E9: 16 | F9: Live | I9: AlbumArt/600/Shout To The Lord.jpg | K9: =IF(COUNTIF(Track!$B:$B,C9)>0,"","NO")
A10: 9 | B10: Hillsong Worship | C10: Simply Worship | D10: 1996 | E10: 12 | F10: Live | I10: AlbumArt/600/Simply Worship.jpg | K10: =IF(COUNTIF(Track!$B:$B,C10)>0,"","NO")
A11: 10 | B11: Hillsong Worship | C11: All Things Are Possible | D11: 1997 | E11: 15 | F11: Live | I11: AlbumArt/600/All Things Are Possible.jpg | K11: =IF(COUNTIF(Track!$B:$B,C11)>0,"","NO")
A12: 11 | B12: Hillsong Worship | C12: Simply Worship 2 | D12: 1997 | E12: 12 | F12: Live | I12: AlbumArt/600/Simply Worship 2.jpg | K12: =IF(COUNTIF(Track!$B:$B,C12)>0,"","NO")
A13: 12 | B13: Hillsong Worship | C13: Shout to the Lord 2000 | D13: 1998 | E13: 16 | F13: Live | I13: AlbumArt/600/Shout to the Lord 2000.jpg | K13: =IF(COUNTIF(Track!$B:$B,C13)>0,"","NO")
... A17: 16 | B17: Hillsong United | C17: Everyday | D17: 1999 | E17: 10 | F17: Live | I17: AlbumArt/600/Everyday.jpg | K17: =IF(COUNTIF(Track!$B:$B,C17)>0,"","NO")
A18: 17 | B18: Hillsong Worship | C18: The Secret Place | D18: 1999 | E18: 10 | F18: Live | G18: Instrumental | I18: AlbumArt/600/The Secret Place.jpg | J18: Exclude | K18: =IF(COUNTIF(Track!$B:$B,C18)>0,"","NO") -> NO
A19: 18 | B19: Hillsong United | C19: Best Friend | D19: 2000 | E19: 10 | F19: Live | I19: AlbumArt/600/Best Friend.jpg | K19: =IF(COUNTIF(Track!$B:$B,C19)>0,"","NO")
A20: 19 | B20: Hillsong Worship | C20: For This Cause | D20: 2000 | E20: 14 | F20: Live | I20: AlbumArt/600/For This Cause.jpg | K20: =IF(COUNTIF(Track!$B:$B,C20)>0,"","NO")
A21: 20 | B21: Hillsong Worship | C21: Overwhelmed | D21: 2000 | E21: 12 | F21: Live | I21: AlbumArt/600/Overwhelmed.jpg | K21: =IF(COUNTIF(Track!$B:$B,C21)>0,"","NO")
A22: 21 | B22: Hillsong Worship | C22: Christmas | D22: 2001 | E22: 14 | F22: Live | G22: Christmas | I22: AlbumArt/600/Christmas.jpg | K22: =IF(COUNTIF(Track!$B:$B,C22)>0,"","NO")
A23: 22 | B23: Hillsong United | C23: King of Majesty | D23: 2001 | E23: 11 | F23: Live | I23: AlbumArt/600/King of Majesty.jpg | K23: =IF(COUNTIF(Track!$B:$B,C23)>0,"","NO")
A24: 23 | B24: Hillsong Worship | C24: You Are My World | D24: 2001 | E24: 13 | F24: Live | I24: AlbumArt/600/You Are My World.jpg | K24: =IF(COUNTIF(Track!$B:$B,C24)>0,"","NO")
A25: 24 | B25: Hillsong Worship | C25: Blessed | D25: 2002 | E25: 14 | F25: Live | I25: AlbumArt/600/Blessed.jpg | K25: =IF(COUNTIF(Track!$B:$B,C25)>0,"","NO")
A26: 25 | B26: Hillsong Worship | C26: Extravagant Worship: The Songs Of Darlene Zschech | D26: 2002 | E26: 23 | F26: Live | G26: Compilation | I26: AlbumArt/600/Extravagant Worship, The Songs Of Darlene Zschech.jpg | J26: Exclude | K26: =IF(COUNTIF(Track!$B:$B,C26)>0,"","NO") -> NO
A27: 26 | B27: Hillsong Worship | C27: Extravagant Worship: The Songs Of Reuben Morgan | D27: 2002 | E27: 22 | F27: Live | G27: Compilation | I27: AlbumArt/600/Extravagant Worship, The Songs Of Reuben Morgan.jpg | J27: Exclude | K27: =IF(COUNTIF(Track!$B:$B,C27)>0,"","NO") -> NO
A28: 27 | B28: Hillsong United | C28: To the Ends of the Earth | D28: 2002 | E28: 14 | F28: Live | I28: AlbumArt/600/To the Ends of the Earth.jpg | K28: =IF(COUNTIF(Track!$B:$B,C28)>0,"","NO")
A29: 28 | B29: Hillsong Worship | C29: Forever | D29: 2003 | E29: 10 | F29: Live | G29: Instrumental | I29: AlbumArt/600/Forever.jpg | J29: Exclude | K29: =IF(COUNTIF(Track!$B:$B,C29)>0,"","NO") -> NO
A30: 29 | B30: Hillsong Worship | C30: Hope | D30: 2003 | E30: 18 | F30: Live | I30: AlbumArt/600/Hope.jpg | K30: =IF(COUNTIF(Track!$B:$B,C30)>0,"","NO")
A31: 30 | B31: Hillsong Worship | C31: Faithful | D31: 2004 | E31: 12 | F31: Live | I31: AlbumArt/600/Faithful.jpg | K31: =IF(COUNTIF(Track!$B:$B,C31)>0,"","NO")
A32: 31 | B32: Hillsong Worship | C32: For All You've Done | D32: 2004 | E32: 15 | F32: Live | I32: AlbumArt/600/For All You've Done.jpg | K32: =IF(COUNTIF(Track!$B:$B,C32)>0,"","NO")
A33: 32 | B33: Hillsong United | C33: More Than Life | D33: 2004 | E33: 15 | F33: Live | I33: AlbumArt/600/More Than Life.jpg | K33: =IF(COUNTIF(Track!$B:$B,C33)>0,"","NO")
A34: 33 | B34: Hillsong Worship | C34: Unified, Praise | D34: 2004 | E34: 11 | F34: Live | I34: AlbumArt/600/Unified, Praise.jpg | K34: =IF(COUNTIF(Track!$B:$B,C34)>0,"","NO")
A35: 34 | B35: Hillsong Worship | C35: God He Reigns | D35: 2005 | E35: 15 | F35: Live | I35: AlbumArt/600/God He Reigns.jpg | K35: =IF(COUNTIF(Track!$B:$B,C35)>0,"","NO")
A36: 35 | B36: Hillsong United | C36: Look to You | D36: 2005 | E36: 13 | F36: Live | I36: AlbumArt/600/Look to You.jpg | K36: =IF(COUNTIF(Track!$B:$B,C36)>0,"","NO")
A37: 36 | B37: Hillsong Worship | C37: Ultimate Worship, Hillsong | D37: 2005 | E37: 17 | F37: Live | G37: Compilation | I37: AlbumArt/600/Ultimate Worship, Hillsong.jpg | J37: Exclude | K37: =IF(COUNTIF(Track!$B:$B,C37)>0,"","NO") -> NO
A38: 37 | B38: Hillsong Worship | C38: Celebrating Christmas | D38: 2006 | E38: 12 | F38: Live | G38: Christmas | I38: AlbumArt/600/Celebrating Christmas.jpg | K38: =IF(COUNTIF(Track!$B:$B,C38)>0,"","NO")
A39: 38 | B39: Hillsong Worship | C39: Mighty to Save | D39: 2006 | E39: 14 | F39: Live | I39: AlbumArt/600/Mighty to Save.jpg | K39: =IF(COUNTIF(Track!$B:$B,C39)>0,"","NO")
A40: 39 | B40: Hillsong Worship | C40: Songs For Communion | D40: 2006 | E40: 14 | F40: Live | I40: AlbumArt/600/Songs For Communion.jpg | K40: =IF(COUNTIF(Track!$B:$B,C40)>0,"","NO")
A41: 40 | B41: Hillsong United | C41: United We Stand | D41: 2006 | E41: 17 | F41: Live | I41: AlbumArt/600/United We Stand.jpg | K41: =IF(COUNTIF(Track!$B:$B,C41)>0,"","NO")
A42: 41 | B42: Hillsong United | C42: All of the Above | D42: 2007 | E42: 14 | F42: Studio | I42: AlbumArt/600/All of the Above.jpg | K42: =IF(COUNTIF(Track!$B:$B,C42)>0,"","NO")
A43: 42 | B43: Hillsong Worship | C43: Saviour King | D43: 2007 | E43: 14 | F43: Live | I43: AlbumArt/600/Saviour King.jpg | K43: =IF(COUNTIF(Track!$B:$B,C43)>0,"","NO")
...

Sheet Track
A1: Id | B1: Album | C1: Year | D1: Track | E1: Title | F1: AltTitle | G1: CcliNumber | H1: Author | I1: Key | J1: Tempo | K1: Performer | L1: Notes
A2: =INDEX(Album!$A:$A, MATCH(B2,Album!$C:$C,0)) -> 1 | B2: Spirit and Truth | C2: =INDEX(Album!$D:$D, MATCH(B2,Album!$C:$C,0)) -> 1988 | D2: 1 | E2: Heaven Suffers Violence | H2: Brian Houston
A3: =INDEX(Album!$A:$A, MATCH(B3,Album!$C:$C,0)) -> 1 | B3: Spirit and Truth | C3: =INDEX(Album!$D:$D, MATCH(B3,Album!$C:$C,0)) -> 1988 | D3: 2 | E3: With Your Love | H3: Geoff Bullock
A4: =INDEX(Album!$A:$A, MATCH(B4,Album!$C:$C,0)) -> 1 | B4: Spirit and Truth | C4: =INDEX(Album!$D:$D, MATCH(B4,Album!$C:$C,0)) -> 1988 | D4: 3 | E4: We're Not Looking Back | H4: Geoff Bullock
A5: =INDEX(Album!$A:$A, MATCH(B5,Album!$C:$C,0)) -> 1 | B5: Spirit and Truth | C5: =INDEX(Album!$D:$D, MATCH(B5,Album!$C:$C,0)) -> 1988 | D5: 4 | E5: I Will Lift My Voice | H5: Geoff Bullock
A6: =INDEX(Album!$A:$A, MATCH(B6,Album!$C:$C,0)) -> 1 | B6: Spirit and Truth | C6: =INDEX(Album!$D:$D, MATCH(B6,Album!$C:$C,0)) -> 1988 | D6: 5 | E6: We've Come To Worship The Lord | H6: Geoff Bullock
A7: =INDEX(Album!$A:$A, MATCH(B7,Album!$C:$C,0)) -> 1 | B7: Spirit and Truth | C7: =INDEX(Album!$D:$D, MATCH(B7,Album!$C:$C,0)) -> 1988 | D7: 6 | E7: Lift High His Name | H7: Geoff Bullock
A8: =INDEX(Album!$A:$A, MATCH(B8,Album!$C:$C,0)) -> 1 | B8: Spirit and Truth | C8: =INDEX(Album!$D:$D, MATCH(B8,Album!$C:$C,0)) -> 1988 | D8: 7 | E8: The Power Of God | H8: Brian Houston, Geoff Bullock
A9: =INDEX(Album!$A:$A, MATCH(B9,Album!$C:$C,0)) -> 1 | B9: Spirit and Truth | C9: =INDEX(Album!$D:$D, MATCH(B9,Album!$C:$C,0)) -> 1988 | D9: 8 | E9: He Is The King | H9: Geoff Bullock
A10: =INDEX(Album!$A:$A, MATCH(B10,Album!$C:$C,0)) -> 1 | B10: Spirit and Truth | C10: =INDEX(Album!$D:$D, MATCH(B10,Album!$C:$C,0)) -> 1988 | D10: 9 | E10: We Will Not Bow To The World | H10: Brian Houston, Geoff Bullock
A11: =INDEX(Album!$A:$A, MATCH(B11,Album!$C:$C,0)) -> 1 | B11: Spirit and Truth | C11: =INDEX(Album!$D:$D, MATCH(B11,Album!$C:$C,0)) -> 1988 | D11: 10 | E11: The Heavens Shall Declare | H11: Geoff Bullock
A12: =INDEX(Album!$A:$A, MATCH(B12,Album!$C:$C,0)) -> 1 | B12: Spirit and Truth | C12: =INDEX(Album!$D:$D, MATCH(B12,Album!$C:$C,0)) -> 1988 | D12: 11 | E12: The Lord's Prayer | H12: Rob Eastwood
A13: =INDEX(Album!$A:$A, MATCH(B13,Album!$C:$C,0)) -> 2 | B13: Show Your Glory | C13: =INDEX(Album!$D:$D, MATCH(B13,Album!$C:$C,0)) -> 1990 | D13: 1 | E13: Without Him
A14: =INDEX(Album!$A:$A, MATCH(B14,Album!$C:$C,0)) -> 2 | B14: Show Your Glory | C14: =INDEX(Album!$D:$D, MATCH(B14,Album!$C:$C,0)) -> 1990 | D14: 2 | E14: The Enemy's Defeated
A15: =INDEX(Album!$A:$A, MATCH(B15,Album!$C:$C,0)) -> 2 | B15: Show Your Glory | C15: =INDEX(Album!$D:$D, MATCH(B15,Album!$C:$C,0)) -> 1990 | D15: 3 | E15: Revival
A16: =INDEX(Album!$A:$A, MATCH(B16,Album!$C:$C,0)) -> 2 | B16: Show Your Glory | C16: =INDEX(Album!$D:$D, MATCH(B16,Album!$C:$C,0)) -> 1990 | D16: 4 | E16: Sanctify
A17: =INDEX(Album!$A:$A, MATCH(B17,Album!$C:$C,0)) -> 2 | B17: Show Your Glory | C17: =INDEX(Album!$D:$D, MATCH(B17,Album!$C:$C,0)) -> 1990 | D17: 5 | E17: Armed And Dangerous
A18: =INDEX(Album!$A:$A, MATCH(B18,Album!$C:$C,0)) -> 2 | B18: Show Your Glory | C18: =INDEX(Album!$D:$D, MATCH(B18,Album!$C:$C,0)) -> 1990 | D18: 6 | E18: Fire
A19: =INDEX(Album!$A:$A, MATCH(B19,Album!$C:$C,0)) -> 2 | B19: Show Your Glory | C19: =INDEX(Album!$D:$D, MATCH(B19,Album!$C:$C,0)) -> 1990 | D19: 7 | E19: Praise Him
A20: =INDEX(Album!$A:$A, MATCH(B20,Album!$C:$C,0)) -> 2 | B20: Show Your Glory | C20: =INDEX(Album!$D:$D, MATCH(B20,Album!$C:$C,0)) -> 1990 | D20: 8 | E20: Show Your Glory
A21: =INDEX(Album!$A:$A, MATCH(B21,Album!$C:$C,0)) -> 2 | B21: Show Your Glory | C21: =INDEX(Album!$D:$D, MATCH(B21,Album!$C:$C,0)) -> 1990 | D21: 9 | E21: I Am Not Ashamed
A22: =INDEX(Album!$A:$A, MATCH(B22,Album!$C:$C,0)) -> 2 | B22: Show Your Glory | C22: =INDEX(Album!$D:$D, MATCH(B22,Album!$C:$C,0)) -> 1990 | D22: 10 | E22: Lord Take My Eyes
A23: =INDEX(Album!$A:$A, MATCH(B23,Album!$C:$C,0)) -> 2 | B23: Show Your Glory | C23: =INDEX(Album!$D:$D, MATCH(B23,Album!$C:$C,0)) -> 1990 | D23: 11 | E23: Blessing
A24: =INDEX(Album!$A:$A, MATCH(B24,Album!$C:$C,0)) -> 2 | B24: Show Your Glory | C24: =INDEX(Album!$D:$D, MATCH(B24,Album!$C:$C,0)) -> 1990 | D24: 12 | E24: Holy
... A26: =INDEX(Album!$A:$A, MATCH(B26,Album!$C:$C,0)) -> 2 | B26: Show Your Glory | C26: =INDEX(Album!$D:$D, MATCH(B26,Album!$C:$C,0)) -> 1990 | D26: 14 | E26: Show Your Glory (Alternate Mix)
A27: =INDEX(Album!$A:$A, MATCH(B27,Album!$C:$C,0)) -> 3 | B27: The Power of Your Love | C27: =INDEX(Album!$D:$D, MATCH(B27,Album!$C:$C,0)) -> 1992 | D27: 1 | E27: The Time Has Come | H27: Geoff Bullock
A28: =INDEX(Album!$A:$A, MATCH(B28,Album!$C:$C,0)) -> 3 | B28: The Power of Your Love | C28: =INDEX(Album!$D:$D, MATCH(B28,Album!$C:$C,0)) -> 1992 | D28: 2 | E28: We Will Rise | H28: Bullock
A29: =INDEX(Album!$A:$A, MATCH(B29,Album!$C:$C,0)) -> 3 | B29: The Power of Your Love | C29: =INDEX(Album!$D:$D, MATCH(B29,Album!$C:$C,0)) -> 1992 | D29: 3 | E29: You Placed Your Love | H29: Bullock
A30: =INDEX(Album!$A:$A, MATCH(B30,Album!$C:$C,0)) -> 3 | B30: The Power of Your Love | C30: =INDEX(Album!$D:$D, MATCH(B30,Album!$C:$C,0)) -> 1992 | D30: 4 | E30: Your Love | H30: Bullock
A31: =INDEX(Album!$A:$A, MATCH(B31,Album!$C:$C,0)) -> 3 | B31: The Power of Your Love | C31: =INDEX(Album!$D:$D, MATCH(B31,Album!$C:$C,0)) -> 1992 | D31: 5 | E31: Blessed Be | H31: Bullock
A32: =INDEX(Album!$A:$A, MATCH(B32,Album!$C:$C,0)) -> 3 | B32: The Power of Your Love | C32: =INDEX(Album!$D:$D, MATCH(B32,Album!$C:$C,0)) -> 1992 | D32: 6 | E32: You Are My Rock | H32: Bullock
A33: =INDEX(Album!$A:$A, MATCH(B33,Album!$C:$C,0)) -> 3 | B33: The Power of Your Love | C33: =INDEX(Album!$D:$D, MATCH(B33,Album!$C:$C,0)) -> 1992 | D33: 7 | E33: Hear Me Calling | H33: Bullock
A34: =INDEX(Album!$A:$A, MATCH(B34,Album!$C:$C,0)) -> 3 | B34: The Power of Your Love | C34: =INDEX(Album!$D:$D, MATCH(B34,Album!$C:$C,0)) -> 1992 | D34: 8 | E34: Refresh My Heart | H34: Bullock
A35: =INDEX(Album!$A:$A, MATCH(B35,Album!$C:$C,0)) -> 3 | B35: The Power of Your Love | C35: =INDEX(Album!$D:$D, MATCH(B35,Album!$C:$C,0)) -> 1992 | D35: 9 | E35: The Power of Your Love | H35: Bullock
A36: =INDEX(Album!$A:$A, MATCH(B36,Album!$C:$C,0)) -> 3 | B36: The Power of Your Love | C36: =INDEX(Album!$D:$D, MATCH(B36,Album!$C:$C,0)) -> 1992 | D36: 10 | E36: Lord We Come | H36: Bullock
A37: =INDEX(Album!$A:$A, MATCH(B37,Album!$C:$C,0)) -> 3 | B37: The Power of Your Love | C37: =INDEX(Album!$D:$D, MATCH(B37,Album!$C:$C,0)) -> 1992 | D37: 11 | E37: I Will Worship You | H37: Bullock
A38: =INDEX(Album!$A:$A, MATCH(B38,Album!$C:$C,0)) -> 3 | B38: The Power of Your Love | C38: =INDEX(Album!$D:$D, MATCH(B38,Album!$C:$C,0)) -> 1992 | D38: 12 | E38: You Are My God | H38: Bullock & Gail Dunshea
... A42: =INDEX(Album!$A:$A, MATCH(B42,Album!$C:$C,0)) -> 3 | B42: The Power of Your Love | C42: =INDEX(Album!$D:$D, MATCH(B42,Album!$C:$C,0)) -> 1992 | D42: 16 | E42: The Great Southland | H42: Bullock
A43: =INDEX(Album!$A:$A, MATCH(B43,Album!$C:$C,0)) -> 4 | B43: Stone's Been Rolled Away | C43: =INDEX(Album!$D:$D, MATCH(B43,Album!$C:$C,0)) -> 1993 | D43: 1 | E43: The Stone's Been Rolled Away | H43: Geoff Bullock | K43: Darlene Zschech, b. Geoff Bullock
A44: =INDEX(Album!$A:$A, MATCH(B44,Album!$C:$C,0)) -> 4 | B44: Stone's Been Rolled Away | C44: =INDEX(Album!$D:$D, MATCH(B44,Album!$C:$C,0)) -> 1993 | D44: 2 | E44: You Give Me Shelter | H44: Geoff Bullock | K44: Sylvia Pettit & Steve McPherson
...

Sheet Rejected (Compilations)
A1: Year | B1: Album | C1: Band | D1: Song # | E1: Title | F1: Author | G1: Worship leader(s) | H1: Length | I1: CCLI# | J1: Original Key | K1: Notes
A2: 2016 | B2: Of Dirt and Grace: Live from the Land | C2: Worship | D2: 1 | E2: Here Now (Madness) | F2: Joel Houston, Michael Guy Chislett | G2: Joel Houston, Taya Smith, Jad Gillies | H2: 0.31527778
A3: 2016 | B3: Of Dirt and Grace: Live from the Land | C3: Worship | D3: 2 | E3: Say the Word | F3: Houston | G3: Jad Gillies | H3: 0.15486111
A4: 2016 | B4: Of Dirt and Grace: Live from the Land | C4: Worship | D4: 3 | E4: Heart Like Heaven (Falling) | F4: Matt Crocker, Houston | G4: Matt Crocker | H4: 0.34305556
A5: 2016 | B5: Of Dirt and Grace: Live from the Land | C5: Worship | D5: 4 | E5: Touch the Sky | F5: Houston, Dylan Thomas, Chislett | G5: Taya Smith[4] | H5: 0.17013889
A6: 2016 | B6: Of Dirt and Grace: Live from the Land | C6: Worship | D6: 5 | E6: Street Called Mercy | F6: Crocker, Houston | G6: Jonathon Douglass, Taya Smith, Matt Crocker | H6: 0.16458333
A7: 2016 | B7: Of Dirt and Grace: Live from the Land | C7: Worship | D7: 6 | E7: When I Lost My Heart to You (Hallelujah) | F7: Houston | G7: Taya Smith, Matt Crocker | H7: 0.34791667
A8: 2016 | B8: Of Dirt and Grace: Live from the Land | C8: Worship | D8: 7 | E8: Even When It Hurts (Praise Song) | F8: Houston | G8: Taya Smith[4] | H8: 0.24305556
A9: 2016 | B9: Of Dirt and Grace: Live from the Land | C9: Worship | D9: 8 | E9: Prince of Peace | F9: Thomas, Houston, Crocker | G9: Taya Smith[12][4] | H9: 0.34166667
A10: 2016 | B10: Of Dirt and Grace: Live from the Land | C10: Worship | D10: 9 | E10: Empires | F10: Houston, Thomas, Chris Davenport, Ben Tennikoff | G10: Joel Houston | H10: 0.30347222
A11: 2016 | B11: Of Dirt and Grace: Live from the Land | C11: Worship | D11: 10 | E11: Rule | F11: Crocker, Houston, Tennikoff | G11: Matt Crocker | H11: 0.16458333
A12: 2016 | B12: Of Dirt and Grace: Live from the Land | C12: Worship | D12: 11 | E12: Captain | F12: Benjamin Hastings, Seth Simmons | G12: Jad Gillies | H12: 0.26666667
A13: 2016 | B13: Of Dirt and Grace: Live from the Land | C13: Worship | D13: 12 | E13: Closer Than You Know | F13: Houston, Crocker, Chislett | G13: Joel Houston, Taya Smith | H13: 0.41875
... A29: 2012 | B29: Live in Miami: Welcome to the Aftermath | C29: Worship | D29: 4 | E29: Search My Heart | F29: Joel Houston, Matt Crocker | G29: Jad Gillies | H29: 0.29375
A30: 2012 | B30: Live in Miami: Welcome to the Aftermath | C30: Worship | D30: 5 | E30: Mighty to Save | F30: Reuben Morgan, Ben Fielding | G30: Joel Houston | H30: 0.21666667 | K30: Popular
A31: 2012 | B31: Live in Miami: Welcome to the Aftermath | C31: Worship | D31: 6 | E31: Hosanna | F31: Brooke Fraser | G31: Hayley Law | H31: 0.26388889
A32: 2012 | B32: Live in Miami: Welcome to the Aftermath | C32: Worship | D32: 7 | E32: All I Need Is You | F32: Marty Sampson | G32: Jad Gillies | H32: 0.24722222
A33: 2012 | B33: Live in Miami: Welcome to the Aftermath | C33: Worship | D33: 8 | E33: Bones | F33: Joel Houston, Jill McCloghry | G33: Jill McCloghry | H33: 0.17152778
A34: 2012 | B34: Live in Miami: Welcome to the Aftermath | C34: Worship | D34: 9 | E34: Nova | F34: Joel Houston, Matt Crocker, Michael Guy Chislett | G34: Matt Crocker | H34: 0.25138889
A35: 2012 | B35: Live in Miami: Welcome to the Aftermath | C35: Worship | D35: 10 | E35: Aftermath | F35: Joel Houston | G35: Joel Houston | H35: 0.3375
A36: 2012 | B36: Live in Miami: Welcome to the Aftermath | C36: Worship | D36: 11 | E36: Freedom Is Here / Shout Unto God | F36: Reuben Morgan, Scott Ligertwood / Joel Houston, Marty Sampson | G36: Jad Gillies / Joel Houston | H36: 0.32013889
A37: 2012 | B37: Live in Miami: Welcome to the Aftermath | C37: Worship | D37: 12 | E37: Like An Avalanche | F37: Joel Houston, Dylan Thomas | G37: Hayley Law | H37: 0.26527778
A38: 2012 | B38: Live in Miami: Welcome to the Aftermath | C38: Worship | D38: 13 | E38: Rhythms of Grace | F38: Chris Davenport, Dean Ussher | G38: Jad Gillies | H38: 0.26527778
A39: 2012 | B39: Live in Miami: Welcome to the Aftermath | C39: Worship | D39: 14 | E39: Oh You Bring | F39: Matt Crocker | G39: Matt Crocker | H39: 0.26666667
A40: 2012 | B40: Live in Miami: Welcome to the Aftermath | C40: Worship | D40: 15 | E40: The Stand | F40: Joel Houston | G40: Joel Houston | H40: 0.20416667
A41: 2012 | B41: Live in Miami: Welcome to the Aftermath | C41: Worship | D41: 16 | E41: From the Inside Out | F41: Joel Houston | G41: Joel Houston | H41: 0.22083333
A42: 2012 | B42: Live in Miami: Welcome to the Aftermath | C42: Worship | D42: 17 | E42: A Song to Sing... | F42: Joel Houston | G42: Joel Houston | H42: 0.11666667
... A77: 2008 | B77: The I Heart Revolution: With Hearts as One | C77: Worship | D77: 30 | E77: Solution | F77: Joel Houston and Matt Crocker | G77: Joel Houston | H77: 0.24652778
