Workbook

Sheet CcliCombined
A1: Index | B1: Title | C1: Author | D1: CCLI # | E1: Publication Year | F1: Source | G1: In Ccws? | H1: In S&S?
A2: 5 | B2: 10,000 Reasons (Bless The Lord) | C2: Jonas Myrin, Matt Redman | D2: 6016351 | E2: 2011 | F2: CcliTop100Canada | G2: =IF(COUNTIF([1]Index!$H$2:$H$187,D2)>0,"","NO") -> #VALUE!
A3: 63 | B3: Across The Lands | C3: Keith Getty, Stuart Townend | D3: 3709898 | F3: CcliTop100Uk | G3: =IF(COUNTIF([1]Index!$H$2:$H$187,D3)>0,"","NO") -> #VALUE! | H3: =IF(COUNTIF([2]Sheet1!$K$2:$K$233,D3)>0,"","NO") -> #VALUE!
A4: 78 | B4: Agnus Dei | C4: Michael W. Smith | D4: 626713 | E4: 1990 | F4: CcliTop100Canada | G4: =IF(COUNTIF([1]Index!$H$2:$H$187,D4)>0,"","NO") -> #VALUE! | H4: =IF(COUNTIF([2]Sheet1!$K$2:$K$233,D4)>0,"","NO") -> #VALUE!
A5: 76 | B5: All Heaven Declares | C5: Noel Richards, Tricia Richards | D5: 120556 | F5: CcliTop100Uk | G5: =IF(COUNTIF([1]Index!$H$2:$H$187,D5)>0,"","NO") -> #VALUE!
A6: 95 | B6: All Who Are Thirsty | C6: Brenton Brown, Glenn Robertson | D6: 2489542 | E6: 1998 | F6: CcliTop100Canada | G6: =IF(COUNTIF([1]Index!$H$2:$H$187,D6)>0,"","NO") -> #VALUE! | H6: =IF(COUNTIF([2]Sheet1!$K$2:$K$233,D6)>0,"","NO") -> #VALUE!
A7: 24 | B7: Amazing Grace (My Chains Are Gone) | C7: Chris Tomlin, John Newton, Louie Giglio | D7: 4768151 | E7: 2006 | F7: CcliTop100Canada | G7: =IF(COUNTIF([1]Index!$H$2:$H$187,D7)>0,"","NO") -> #VALUE!
A8: 49 | B8: Another In The Fire | C8: Chris Davenport, Joel Houston | D8: 7124907 | F8: CcliTop100Usa | G8: =IF(COUNTIF([1]Index!$H$2:$H$187,D8)>0,"","NO") -> #VALUE!
A9: 79 | B9: As The Deer | C9: Martin Nystrom | D9: 1431 | F9: CcliTop100Uk | G9: =IF(COUNTIF([1]Index!$H$2:$H$187,D9)>0,"","NO") -> #VALUE!
A10: 73 | B10: At The Cross | C10: Hillsong Worship | D10: 29499 | F10: PraiseChartsTop100AllTime | G10: =IF(COUNTIF([1]Index!$H$2:$H$187,D10)>0,"","NO") -> #VALUE!
A11: 89 | B11: At The Cross (Love Ran Red) | C11: Chris Tomlin, Ed Cash, Jonas Myrin, Matt Armstrong, Matt Redman | D11: 7017786 | E11: 2014 | F11: CcliTop100Canada | G11: =IF(COUNTIF([1]Index!$H$2:$H$187,D11)>0,"","NO") -> #VALUE!
A12: 74 | B12: At Your Name | C12: Phil Wickham, Tim Hughes | D12: 5942543 | F12: CcliTop100Uk | G12: =IF(COUNTIF([1]Index!$H$2:$H$187,D12)>0,"","NO") -> #VALUE! | H12: =IF(COUNTIF([2]Sheet1!$K$2:$K$233,D12)>0,"","NO") -> #VALUE!
A13: 16 | B13: Be Still | C13: David J. Evans | D13: 120824 | F13: CcliTop100Uk | G13: =IF(COUNTIF([1]Index!$H$2:$H$187,D13)>0,"","NO") -> #VALUE! | H13: =IF(COUNTIF([2]Sheet1!$K$2:$K$233,D13)>0,"","NO") -> #VALUE!
A14: 90 | B14: Be The Centre | C14: Michael Frye | D14: 2650429 | F14: CcliTop100Uk | G14: =IF(COUNTIF([1]Index!$H$2:$H$187,D14)>0,"","NO") -> #VALUE! | H14: =IF(COUNTIF([2]Sheet1!$K$2:$K$233,D14)>0,"","NO") -> #VALUE!
A15: 90 | B15: Be Unto Your Name | C15: Gary Sadler, Lynn DeShazo | D15: 2177476 | E15: 1998 | F15: CcliTop100Canada | G15: =IF(COUNTIF([1]Index!$H$2:$H$187,D15)>0,"","NO") -> #VALUE! | H15: =IF(COUNTIF([2]Sheet1!$K$2:$K$233,D15)>0,"","NO") -> #VALUE!
A16: 69 | B16: Beautiful Saviour | C16: Stuart Townend | D16: 2492216 | F16: CcliTop100Uk | G16: =IF(COUNTIF([1]Index!$H$2:$H$187,D16)>0,"","NO") -> #VALUE! | H16: =IF(COUNTIF([2]Sheet1!$K$2:$K$233,D16)>0,"","NO") -> #VALUE!
A17: 98 | B17: Beautiful Things | C17: Michael Gungor | D17: 5665521 | F17: PraiseChartsTop100AllTime | G17: =IF(COUNTIF([1]Index!$H$2:$H$187,D17)>0,"","NO") -> #VALUE! | H17: =IF(COUNTIF([2]Sheet1!$K$2:$K$233,D17)>0,"","NO") -> #VALUE!
A18: 44 | B18: Because He Lives | C18: Gloria Gaither, William J. Gaither | D18: 16880 | E18: 1971 | F18: CcliTop100Canada | G18: =IF(COUNTIF([1]Index!$H$2:$H$187,D18)>0,"","NO") -> #VALUE!
A19: 80 | B19: Because He Lives (Amen) | C19: Chris Tomlin, Daniel Carson, Ed Cash, Gloria Gaither, Jason Ingram, Matt Maher, William J. Gaither | D19: 7027887 | F19: CcliTop100Usa | G19: =IF(COUNTIF([1]Index!$H$2:$H$187,D19)>0,"","NO") -> #VALUE! | H19: =IF(COUNTIF([2]Sheet1!$K$2:$K$233,D19)>0,"","NO") -> #VALUE!
A20: 91 | B20: Before The Throne Of God Above | C20: Charitie Lees Bancroft, Vikki Cook | D20: 2306412 | E20: 1997 | F20: CcliTop100Canada | G20: =IF(COUNTIF([1]Index!$H$2:$H$187,D20)>0,"","NO") -> #VALUE!
A21: 55 | B21: Behold Our God | C21: Jonathan Baird, Meghan Baird, Ryan Baird, Stephen Altrogge | D21: 5937510 | F21: CcliTop100Uk | G21: =IF(COUNTIF([1]Index!$H$2:$H$187,D21)>0,"","NO") -> #VALUE!
A22: 19 | B22: Blessed Be Your Name | C22: Beth Redman, Matt Redman | D22: 3798438 | E22: 2002 | F22: CcliTop100Canada | G22: =IF(COUNTIF([1]Index!$H$2:$H$187,D22)>0,"","NO") -> #VALUE!
A23: 3 | B23: Build My Life | C23: Brett Younker, Karl Martin, Kirby Kaple, Matt Redman, Pat Barrett | D23: 7070345 | E23: 2016 | F23: CcliTop100Canada | G23: =IF(COUNTIF([1]Index!$H$2:$H$187,D23)>0,"","NO") -> #VALUE!
A24: 46 | B24: Build Your Kingdom Here | C24: Chris Llewellyn, Gareth Gilkeson, William Herron | D24: 6186078 | E24: 2011 | F24: CcliTop100Canada | G24: =IF(COUNTIF([1]Index!$H$2:$H$187,D24)>0,"","NO") -> #VALUE!
A25: 85 | B25: By Faith | C25: Keith Getty, Kristyn Getty, Stuart Townend | D25: 5469291 | F25: CcliTop100Uk | G25: =IF(COUNTIF([1]Index!$H$2:$H$187,D25)>0,"","NO") -> #VALUE! | H25: =IF(COUNTIF([2]Sheet1!$K$2:$K$233,D25)>0,"","NO") -> #VALUE!
A26: 65 | B26: Chain Breaker | C26: Zach Williams | D26: 7060031 | F26: PraiseChartsTop100AllTime | G26: =IF(COUNTIF([1]Index!$H$2:$H$187,D26)>0,"","NO") -> #VALUE! | H26: =IF(COUNTIF([2]Sheet1!$K$2:$K$233,D26)>0,"","NO") -> #VALUE!
A27: 87 | B27: Christ Be Magnified | C27: Cody Carnes, Cory Asbury, Ethan Hulse | D27: 7139866 | F27: CcliTop100Usa | G27: =IF(COUNTIF([1]Index!$H$2:$H$187,D27)>0,"","NO") -> #VALUE! | H27: =IF(COUNTIF([2]Sheet1!$K$2:$K$233,D27)>0,"","NO") -> #VALUE!
A28: 52 | B28: Christ Is Enough | C28: Jonas Myrin, Reuben Morgan | D28: 6514035 | E28: 2012 | F28: CcliTop100Canada | G28: =IF(COUNTIF([1]Index!$H$2:$H$187,D28)>0,"","NO") -> #VALUE!
A29: 44 | B29: Christ Is Risen | C29: Matt Maher | D29: 5242683 | F29: PraiseChartsTop100AllTime | G29: =IF(COUNTIF([1]Index!$H$2:$H$187,D29)>0,"","NO") -> #VALUE! | H29: =IF(COUNTIF([2]Sheet1!$K$2:$K$233,D29)>0,"","NO") -> #VALUE!
A30: 84 | B30: Come As You Are | C30: Ben Glover, David Crowder, Matt Maher | D30: 7017790 | E30: 2014 | F30: CcliTop100Canada | G30: =IF(COUNTIF([1]Index!$H$2:$H$187,D30)>0,"","NO") -> #VALUE! | H30: =IF(COUNTIF([2]Sheet1!$K$2:$K$233,D30)>0,"","NO") -> #VALUE!
A31: 50 | B31: Come Now Is The Time To Worship | C31: Brian Doerksen | D31: 2430948 | E31: 1998 | F31: CcliTop100Canada | G31: =IF(COUNTIF([1]Index!$H$2:$H$187,D31)>0,"","NO") -> #VALUE!
A32: 24 | B32: Come People Of The Risen King | C32: Keith Getty, Kristyn Getty, Stuart Townend | D32: 5232617 | F32: CcliTop100Uk | G32: =IF(COUNTIF([1]Index!$H$2:$H$187,D32)>0,"","NO") -> #VALUE! | H32: =IF(COUNTIF([2]Sheet1!$K$2:$K$233,D32)>0,"","NO") -> #VALUE!
A33: 41 | B33: Come Thou Fount Come Thou King | C33: Gateway Worship | D33: 4775010 | F33: PraiseChartsTop100AllTime | G33: =IF(COUNTIF([1]Index!$H$2:$H$187,D33)>0,"","NO") -> #VALUE! | H33: =IF(COUNTIF([2]Sheet1!$K$2:$K$233,D33)>0,"","NO") -> #VALUE!
A34: 98 | B34: Consuming Fire | C34: Tim Hughes | D34: 3818569 | F34: CcliTop100Uk | G34: =IF(COUNTIF([1]Index!$H$2:$H$187,D34)>0,"","NO") -> #VALUE! | H34: =IF(COUNTIF([2]Sheet1!$K$2:$K$233,D34)>0,"","NO") -> #VALUE!
A35: 11 | B35: Cornerstone | C35: Edward Mote, Eric Liljero, Jonas Myrin, Reuben Morgan, William Batchelder Bradbury | D35: 6158927 | E35: 2011 | F35: CcliTop100Canada | G35: =IF(COUNTIF([1]Index!$H$2:$H$187,D35)>0,"","NO") -> #VALUE!
A36: 54 | B36: Crown Him (Majesty) | C36: Chris Tomlin | D36: 6463818 | F36: PraiseChartsTop100AllTime | G36: =IF(COUNTIF([1]Index!$H$2:$H$187,D36)>0,"","NO") -> #VALUE!
A37: 71 | B37: Days Of Elijah | C37: Robin Mark | D37: 1537904 | E37: 1996 | F37: CcliTop100Canada | G37: =IF(COUNTIF([1]Index!$H$2:$H$187,D37)>0,"","NO") -> #VALUE!
A38: 60 | B38: Death Was Arrested | C38: Adam Kersh, Brandon Coker, Heath Balltzglier, Paul Taylor Smith | D38: 7046448 | E38: 2015 | F38: CcliTop100Canada | G38: =IF(COUNTIF([1]Index!$H$2:$H$187,D38)>0,"","NO") -> #VALUE!
A39: 47 | B39: Do It Again | C39: Chris Brown, Mack Brock, Matt Redman, Steven Furtick | D39: 7067555 | E39: 2016 | F39: CcliTop100Canada | G39: =IF(COUNTIF([1]Index!$H$2:$H$187,D39)>0,"","NO") -> #VALUE!
A40: 72 | B40: Even So Come | C40: Passion / Chris Tomlin | D40: 7036288 | F40: PraiseChartsTop100AllTime | G40: =IF(COUNTIF([1]Index!$H$2:$H$187,D40)>0,"","NO") -> #VALUE!
...

Sheet CcliTop100Canada
A1: Index | B1: Title | C1: Author | D1: CCLI # | E1: Publication Year | F1: Source | G1: In S&S | H1: In CCWS | I1: In Usa? | J1: In Uk?
A2: 1 | B2: Way Maker | C2: Osinachi Kalu Okoro Egbu | D2: 7115744 | E2: 2016 | F2: CcliTop100Canada | G2: =IF(COUNTIF([2]Sheet1!$K$2:$K$229,D2)>0,"","NO") -> NO | H2: =IF(COUNTIF([1]Index!$H$2:$H$187,D2)>0,"","NO") | I2: =IF(COUNTIF(CcliTop100Usa!$D$2:$D$101,D2)>0,"","NO") | J2: =IF(COUNTIF(CcliTop100Uk!$D$2:$D$101,D2)>0,"","NO")
A3: 2 | B3: Living Hope | C3: Brian Johnson, Phil Wickham | D3: 7106807 | E3: 2017 | F3: CcliTop100Canada | G3: =IF(COUNTIF([2]Sheet1!$K$2:$K$229,D3)>0,"","NO") | H3: =IF(COUNTIF([1]Index!$H$2:$H$187,D3)>0,"","NO") | I3: =IF(COUNTIF(CcliTop100Usa!$D$2:$D$101,D3)>0,"","NO") | J3: =IF(COUNTIF(CcliTop100Uk!$D$2:$D$101,D3)>0,"","NO")
A4: 3 | B4: Build My Life | C4: Brett Younker, Karl Martin, Kirby Kaple, Matt Redman, Pat Barrett | D4: 7070345 | E4: 2016 | F4: CcliTop100Canada | G4: =IF(COUNTIF([2]Sheet1!$K$2:$K$229,D4)>0,"","NO") | H4: =IF(COUNTIF([1]Index!$H$2:$H$187,D4)>0,"","NO") | I4: =IF(COUNTIF(CcliTop100Usa!$D$2:$D$101,D4)>0,"","NO") | J4: =IF(COUNTIF(CcliTop100Uk!$D$2:$D$101,D4)>0,"","NO")
A5: 4 | B5: What A Beautiful Name | C5: Ben Fielding, Brooke Ligertwood | D5: 7068424 | E5: 2016 | F5: CcliTop100Canada | G5: =IF(COUNTIF([2]Sheet1!$K$2:$K$229,D5)>0,"","NO") | H5: =IF(COUNTIF([1]Index!$H$2:$H$187,D5)>0,"","NO") | I5: =IF(COUNTIF(CcliTop100Usa!$D$2:$D$101,D5)>0,"","NO") | J5: =IF(COUNTIF(CcliTop100Uk!$D$2:$D$101,D5)>0,"","NO")
A6: 5 | B6: 10,000 Reasons (Bless The Lord) | C6: Jonas Myrin, Matt Redman | D6: 6016351 | E6: 2011 | F6: CcliTop100Canada | G6: =IF(COUNTIF([2]Sheet1!$K$2:$K$229,D6)>0,"","NO") | H6: =IF(COUNTIF([1]Index!$H$2:$H$187,D6)>0,"","NO") | I6: =IF(COUNTIF(CcliTop100Usa!$D$2:$D$101,D6)>0,"","NO") | J6: =IF(COUNTIF(CcliTop100Uk!$D$2:$D$101,D6)>0,"","NO")
A7: 6 | B7: Who You Say I Am | C7: Ben Fielding, Reuben Morgan | D7: 7102401 | E7: 2017 | F7: CcliTop100Canada | G7: =IF(COUNTIF([2]Sheet1!$K$2:$K$229,D7)>0,"","NO") | H7: =IF(COUNTIF([1]Index!$H$2:$H$187,D7)>0,"","NO") | I7: =IF(COUNTIF(CcliTop100Usa!$D$2:$D$101,D7)>0,"","NO") | J7: =IF(COUNTIF(CcliTop100Uk!$D$2:$D$101,D7)>0,"","NO")
A8: 7 | B8: Great Are You Lord | C8: David Leonard, Jason Ingram, Leslie Jordan | D8: 6460220 | E8: 2012 | F8: CcliTop100Canada | G8: =IF(COUNTIF([2]Sheet1!$K$2:$K$229,D8)>0,"","NO") | H8: =IF(COUNTIF([1]Index!$H$2:$H$187,D8)>0,"","NO") | I8: =IF(COUNTIF(CcliTop100Usa!$D$2:$D$101,D8)>0,"","NO") | J8: =IF(COUNTIF(CcliTop100Uk!$D$2:$D$101,D8)>0,"","NO")
A9: 8 | B9: This Is Amazing Grace | C9: Jeremy Riddle, Josh Farro, Phil Wickham | D9: 6333821 | E9: 2012 | F9: CcliTop100Canada | G9: =IF(COUNTIF([2]Sheet1!$K$2:$K$229,D9)>0,"","NO") | H9: =IF(COUNTIF([1]Index!$H$2:$H$187,D9)>0,"","NO") | I9: =IF(COUNTIF(CcliTop100Usa!$D$2:$D$101,D9)>0,"","NO") | J9: =IF(COUNTIF(CcliTop100Uk!$D$2:$D$101,D9)>0,"","NO")
A10: 9 | B10: Lord I Need You | C10: Christy Nockels, Daniel Carson, Jesse Reeves, Kristian Stanfill, Matt Maher | D10: 5925687 | E10: 2011 | F10: CcliTop100Canada | G10: =IF(COUNTIF([2]Sheet1!$K$2:$K$229,D10)>0,"","NO") | H10: =IF(COUNTIF([1]Index!$H$2:$H$187,D10)>0,"","NO") | I10: =IF(COUNTIF(CcliTop100Usa!$D$2:$D$101,D10)>0,"","NO") | J10: =IF(COUNTIF(CcliTop100Uk!$D$2:$D$101,D10)>0,"","NO") -> NO
A11: 10 | B11: Goodness Of God | C11: Ben Fielding, Brian Johnson, Ed Cash, Jason Ingram, Jenn Johnson | D11: 7117726 | E11: 2018 | F11: CcliTop100Canada | G11: =IF(COUNTIF([2]Sheet1!$K$2:$K$229,D11)>0,"","NO") | H11: =IF(COUNTIF([1]Index!$H$2:$H$187,D11)>0,"","NO") -> NO | I11: =IF(COUNTIF(CcliTop100Usa!$D$2:$D$101,D11)>0,"","NO") | J11: =IF(COUNTIF(CcliTop100Uk!$D$2:$D$101,D11)>0,"","NO")
A12: 11 | B12: Cornerstone | C12: Edward Mote, Eric Liljero, Jonas Myrin, Reuben Morgan, William Batchelder Bradbury | D12: 6158927 | E12: 2011 | F12: CcliTop100Canada | G12: =IF(COUNTIF([2]Sheet1!$K$2:$K$229,D12)>0,"","NO") | H12: =IF(COUNTIF([1]Index!$H$2:$H$187,D12)>0,"","NO") | I12: =IF(COUNTIF(CcliTop100Usa!$D$2:$D$101,D12)>0,"","NO") | J12: =IF(COUNTIF(CcliTop100Uk!$D$2:$D$101,D12)>0,"","NO")
A13: 12 | B13: Good Good Father | C13: Anthony Brown, Pat Barrett | D13: 7036612 | E13: 2014 | F13: CcliTop100Canada | G13: =IF(COUNTIF([2]Sheet1!$K$2:$K$229,D13)>0,"","NO") | H13: =IF(COUNTIF([1]Index!$H$2:$H$187,D13)>0,"","NO") | I13: =IF(COUNTIF(CcliTop100Usa!$D$2:$D$101,D13)>0,"","NO") | J13: =IF(COUNTIF(CcliTop100Uk!$D$2:$D$101,D13)>0,"","NO")
... A101: 100 | B101: God Is So Good (You Are Worthy) | C101: Ben Smith, Daniel Bashta, Pat Barrett | D101: 7100964 | E101: 2017 | F101: CcliTop100Canada | G101: =IF(COUNTIF([2]Sheet1!$K$2:$K$229,D101)>0,"","NO") -> NO | H101: =IF(COUNTIF([1]Index!$H$2:$H$187,D101)>0,"","NO") -> NO | I101: =IF(COUNTIF(CcliTop100Usa!$D$2:$D$101,D101)>0,"","NO") -> NO | J101: =IF(COUNTIF(CcliTop100Uk!$D$2:$D$101,D101)>0,"","NO") -> NO
E102: =COUNTBLANK(E2:E101) -> 0 | G102: =COUNTIF(G2:G101, "NO") -> 30 | H102: =COUNTIF(H2:H101, "NO") -> 34 | I102: =COUNTIF(I2:I101, "NO") -> 23 | J102: =COUNTIF(J2:J101, "NO") -> 39

Sheet CcliTop100Usa
A1: Index | B1: Title | C1: Author | D1: CCLI # | E1: Publication Year | F1: Source | G1: In Canada?
A2: 1 | B2: Way Maker | C2: Osinachi Kalu Okoro Egbu | D2: 7115744 | F2: CcliTop100Usa | G2: =IF(COUNTIF(CcliTop100Canada!$D$2:$D$101,D2)>0,"","NO")
A3: 2 | B3: Build My Life | C3: Brett Younker, Karl Martin, Kirby Kaple, Matt Redman, Pat Barrett | D3: 7070345 | F3: CcliTop100Usa | G3: =IF(COUNTIF(CcliTop100Canada!$D$2:$D$101,D3)>0,"","NO")
A4: 3 | B4: Living Hope | C4: Brian Johnson, Phil Wickham | D4: 7106807 | F4: CcliTop100Usa | G4: =IF(COUNTIF(CcliTop100Canada!$D$2:$D$101,D4)>0,"","NO")
A5: 4 | B5: Who You Say I Am | C5: Ben Fielding, Reuben Morgan | D5: 7102401 | F5: CcliTop100Usa | G5: =IF(COUNTIF(CcliTop100Canada!$D$2:$D$101,D5)>0,"","NO")
A6: 5 | B6: What A Beautiful Name | C6: Ben Fielding, Brooke Ligertwood | D6: 7068424 | F6: CcliTop100Usa | G6: =IF(COUNTIF(CcliTop100Canada!$D$2:$D$101,D6)>0,"","NO")
A7: 6 | B7: Raise A Hallelujah | C7: Jake Stevens, Jonathan David Helser, Melissa Helser, Molly Skaggs | D7: 7119315 | F7: CcliTop100Usa | G7: =IF(COUNTIF(CcliTop100Canada!$D$2:$D$101,D7)>0,"","NO")
A8: 7 | B8: Great Are You Lord | C8: David Leonard, Jason Ingram, Leslie Jordan | D8: 6460220 | F8: CcliTop100Usa | G8: =IF(COUNTIF(CcliTop100Canada!$D$2:$D$101,D8)>0,"","NO")
A9: 8 | B9: Goodness Of God | C9: Ben Fielding, Brian Johnson, Ed Cash, Jason Ingram, Jenn Johnson | D9: 7117726 | F9: CcliTop100Usa | G9: =IF(COUNTIF(CcliTop100Canada!$D$2:$D$101,D9)>0,"","NO")
A10: 9 | B10: This Is Amazing Grace | C10: Jeremy Riddle, Josh Farro, Phil Wickham | D10: 6333821 | F10: CcliTop100Usa | G10: =IF(COUNTIF(CcliTop100Canada!$D$2:$D$101,D10)>0,"","NO")
A11: 10 | B11: 10,000 Reasons (Bless The Lord) | C11: Jonas Myrin, Matt Redman | D11: 6016351 | F11: CcliTop100Usa | G11: =IF(COUNTIF(CcliTop100Canada!$D$2:$D$101,D11)>0,"","NO")
A12: 11 | B12: The Blessing | C12: Chris Brown, Cody Carnes, Kari Jobe, Steven Furtick | D12: 7147007 | F12: CcliTop100Usa | G12: =IF(COUNTIF(CcliTop100Canada!$D$2:$D$101,D12)>0,"","NO")
A13: 12 | B13: Glorious Day | C13: Jason Ingram, Jonathan Smith, Kristian Stanfill, Sean Curran | D13: 7081388 | F13: CcliTop100Usa | G13: =IF(COUNTIF(CcliTop100Canada!$D$2:$D$101,D13)>0,"","NO")
... A101: 100 | B101: Ever Be | C101: Bobby Strand, Chris Greely, Gabriel Wilson, Kalley Heiligenthal | D101: 7030065 | F101: CcliTop100Usa | G101: =IF(COUNTIF(CcliTop100Canada!$D$2:$D$101,D101)>0,"","NO") -> NO
G102: =COUNTIF(G2:G101, "NO") -> 23
G103: =COUNTIF(G2:G101, "NO") -> 23

Sheet CcliTop100Uk
A1: Index | B1: Title | C1: Author | D1: CCLI # | E1: Publication Year | F1: Source | G1: In Canada? | H1: In Usa?
A2: 1 | B2: 10,000 Reasons (Bless The Lord) | C2: Jonas Myrin, Matt Redman | D2: 6016351 | F2: CcliTop100Uk | G2: =IF(COUNTIF(CcliTop100Canada!$D$2:$D$101,D2)>0,"","NO") | H2: =IF(COUNTIF(CcliTop100Usa!$D$2:$D$101,D2)>0,"","NO")
A3: 2 | B3: In Christ Alone | C3: Keith Getty, Stuart Townend | D3: 3350395 | F3: CcliTop100Uk | G3: =IF(COUNTIF(CcliTop100Canada!$D$2:$D$101,D3)>0,"","NO") | H3: =IF(COUNTIF(CcliTop100Usa!$D$2:$D$101,D3)>0,"","NO")
A4: 3 | B4: Cornerstone | C4: Edward Mote, Eric Liljero, Jonas Myrin, Reuben Morgan, William Batchelder Bradbury | D4: 6158927 | F4: CcliTop100Uk | G4: =IF(COUNTIF(CcliTop100Canada!$D$2:$D$101,D4)>0,"","NO") | H4: =IF(COUNTIF(CcliTop100Usa!$D$2:$D$101,D4)>0,"","NO")
A5: 4 | B5: O Praise The Name (Anástasis) | C5: Benjamin Hastings, Dean Ussher, Marty Sampson | D5: 7037787 | F5: CcliTop100Uk | G5: =IF(COUNTIF(CcliTop100Canada!$D$2:$D$101,D5)>0,"","NO") | H5: =IF(COUNTIF(CcliTop100Usa!$D$2:$D$101,D5)>0,"","NO")
A6: 5 | B6: What A Beautiful Name | C6: Ben Fielding, Brooke Ligertwood | D6: 7068424 | F6: CcliTop100Uk | G6: =IF(COUNTIF(CcliTop100Canada!$D$2:$D$101,D6)>0,"","NO") | H6: =IF(COUNTIF(CcliTop100Usa!$D$2:$D$101,D6)>0,"","NO")
A7: 6 | B7: How Great Is Our God | C7: Chris Tomlin, Ed Cash, Jesse Reeves | D7: 4348399 | F7: CcliTop100Uk | G7: =IF(COUNTIF(CcliTop100Canada!$D$2:$D$101,D7)>0,"","NO") | H7: =IF(COUNTIF(CcliTop100Usa!$D$2:$D$101,D7)>0,"","NO")
A8: 7 | B8: This Is Amazing Grace | C8: Jeremy Riddle, Josh Farro, Phil Wickham | D8: 6333821 | F8: CcliTop100Uk | G8: =IF(COUNTIF(CcliTop100Canada!$D$2:$D$101,D8)>0,"","NO") | H8: =IF(COUNTIF(CcliTop100Usa!$D$2:$D$101,D8)>0,"","NO")
A9: 8 | B9: Way Maker | C9: Osinachi Kalu Okoro Egbu | D9: 7115744 | F9: CcliTop100Uk | G9: =IF(COUNTIF(CcliTop100Canada!$D$2:$D$101,D9)>0,"","NO") | H9: =IF(COUNTIF(CcliTop100Usa!$D$2:$D$101,D9)>0,"","NO")
A10: 9 | B10: Living Hope | C10: Brian Johnson, Phil Wickham | D10: 7106807 | F10: CcliTop100Uk | G10: =IF(COUNTIF(CcliTop100Canada!$D$2:$D$101,D10)>0,"","NO") | H10: =IF(COUNTIF(CcliTop100Usa!$D$2:$D$101,D10)>0,"","NO")
A11: 10 | B11: Psalm 23 | C11: Stuart Townend | D11: 1585970 | F11: CcliTop100Uk | G11: =IF(COUNTIF(CcliTop100Canada!$D$2:$D$101,D11)>0,"","NO") -> NO | H11: =IF(COUNTIF(CcliTop100Usa!$D$2:$D$101,D11)>0,"","NO") -> NO
A12: 11 | B12: Build My Life | C12: Brett Younker, Karl Martin, Kirby Kaple, Matt Redman, Pat Barrett | D12: 7070345 | F12: CcliTop100Uk | G12: =IF(COUNTIF(CcliTop100Canada!$D$2:$D$101,D12)>0,"","NO") | H12: =IF(COUNTIF(CcliTop100Usa!$D$2:$D$101,D12)>0,"","NO")
A13: 12 | B13: How Great Thou Art | C13: Stuart Wesley Keene Hine | D13: 14181 | F13: CcliTop100Uk | G13: =IF(COUNTIF(CcliTop100Canada!$D$2:$D$101,D13)>0,"","NO") | H13: =IF(COUNTIF(CcliTop100Usa!$D$2:$D$101,D13)>0,"","NO")
... A101: 100 | B101: Great Is The Lord | C101: Steve McEwan | D101: 10769 | F101: CcliTop100Uk | G101: =IF(COUNTIF(CcliTop100Canada!$D$2:$D$101,D101)>0,"","NO") -> NO | H101: =IF(COUNTIF(CcliTop100Usa!$D$2:$D$101,D101)>0,"","NO") -> NO
G102: =COUNTIF(G2:G101, "NO") -> 39 | H102: =COUNTIF(H2:H101, "NO") -> 48

Sheet PraiseChartsTop100AllTime
A1: Index | B1: Title | C1: Author | D1: CCLI # | E1: Publication Year | F1: Source | G1: In Canada? | H1: dup/xmas
A2: 1 | B2: 10,000 Reasons (Bless The Lord) | C2: Matt Redman / Passion | D2: 6016351 | F2: PraiseChartsTop100AllTime | G2: =IF(COUNTIF(CcliTop100Canada!$D$2:$D$163,D2)>0,"","NO")
A3: 2 | B3: Amazing Grace (My Chains Are Gone) | C3: Chris Tomlin | D3: 4768151 | F3: PraiseChartsTop100AllTime | G3: =IF(COUNTIF(CcliTop100Canada!$D$2:$D$163,D3)>0,"","NO")
A4: 29 | B4: Angels We Have Heard On High | C4: Chris Tomlin | D4: #N/A | F4: PraiseChartsTop100AllTime | G4: =IF(COUNTIF(CcliTop100Canada!$D$2:$D$163,D4)>0,"","NO") -> NO | H4: xmas
A5: 73 | B5: At The Cross | C5: Hillsong Worship | D5: 29499 | F5: PraiseChartsTop100AllTime | G5: =IF(COUNTIF(CcliTop100Canada!$D$2:$D$163,D5)>0,"","NO") -> NO
A6: 84 | B6: At The Cross (Love Ran Red) | C6: Chris Tomlin | D6: 7017786 | F6: PraiseChartsTop100AllTime | G6: =IF(COUNTIF(CcliTop100Canada!$D$2:$D$163,D6)>0,"","NO")
A7: 98 | B7: Beautiful Things | C7: Michael Gungor | D7: 5665521 | F7: PraiseChartsTop100AllTime | G7: =IF(COUNTIF(CcliTop100Canada!$D$2:$D$163,D7)>0,"","NO") -> NO
A8: 25 | B8: Because He Lives (Amen) | C8: Matt Maher | D8: 7027887 | F8: PraiseChartsTop100AllTime | G8: =IF(COUNTIF(CcliTop100Canada!$D$2:$D$163,D8)>0,"","NO") -> NO
A9: 83 | B9: Blessed Be Your Name | C9: Matt Redman | D9: 3798438 | F9: PraiseChartsTop100AllTime | G9: =IF(COUNTIF(CcliTop100Canada!$D$2:$D$163,D9)>0,"","NO")
A10: 63 | B10: Build My Life | C10: Passion / Brett Younker | D10: 7070345 | F10: PraiseChartsTop100AllTime | G10: =IF(COUNTIF(CcliTop100Canada!$D$2:$D$163,D10)>0,"","NO")
A11: 71 | B11: Build Your Kingdom Here | C11: Rend Collective | D11: 6186078 | F11: PraiseChartsTop100AllTime | G11: =IF(COUNTIF(CcliTop100Canada!$D$2:$D$163,D11)>0,"","NO")
A12: 65 | B12: Chain Breaker | C12: Zach Williams | D12: 7060031 | F12: PraiseChartsTop100AllTime | G12: =IF(COUNTIF(CcliTop100Canada!$D$2:$D$163,D12)>0,"","NO") -> NO
A13: 44 | B13: Christ Is Risen | C13: Matt Maher | D13: 5242683 | F13: PraiseChartsTop100AllTime | G13: =IF(COUNTIF(CcliTop100Canada!$D$2:$D$163,D13)>0,"","NO") -> NO
A14: 41 | B14: Come Thou Fount Come Thou King | C14: Gateway Worship | D14: 4775010 | F14: PraiseChartsTop100AllTime | G14: =IF(COUNTIF(CcliTop100Canada!$D$2:$D$163,D14)>0,"","NO") -> NO
A15: 3 | B15: Cornerstone | C15: Hillsong Worship | D15: 6158927 | F15: PraiseChartsTop100AllTime | G15: =IF(COUNTIF(CcliTop100Canada!$D$2:$D$163,D15)>0,"","NO")
A16: 54 | B16: Crown Him (Majesty) | C16: Chris Tomlin | D16: 6463818 | F16: PraiseChartsTop100AllTime | G16: =IF(COUNTIF(CcliTop100Canada!$D$2:$D$163,D16)>0,"","NO") -> NO
... A32: 56 | B32: Happy Day | C32: Tim Hughes | D32: 4847027 | F32: PraiseChartsTop100AllTime | G32: =IF(COUNTIF(CcliTop100Canada!$D$2:$D$163,D32)>0,"","NO") -> NO
A33: 59 | B33: Hark The Herald (with King Of Heaven) | C33: Paul Baloche | D33: #N/A | F33: PraiseChartsTop100AllTime | G33: =IF(COUNTIF(CcliTop100Canada!$D$2:$D$163,D33)>0,"","NO") -> NO | H33: xmas
A34: 70 | B34: He Shall Reign Forevermore | C34: Chris Tomlin | D34: 7050416 | F34: PraiseChartsTop100AllTime | G34: =IF(COUNTIF(CcliTop100Canada!$D$2:$D$163,D34)>0,"","NO") -> NO
A35: 86 | B35: Holy Is The Lord | C35: Chris Tomlin / Passion | D35: 4158039 | F35: PraiseChartsTop100AllTime | G35: =IF(COUNTIF(CcliTop100Canada!$D$2:$D$163,D35)>0,"","NO") -> NO
A36: 87 | B36: Holy Spirit | C36: Francesca Battistelli | D36: 6087919 | F36: PraiseChartsTop100AllTime | G36: =IF(COUNTIF(CcliTop100Canada!$D$2:$D$163,D36)>0,"","NO")
A37: 39 | B37: Hosanna | C37: Hillsong UNITED | D37: 21545 | F37: PraiseChartsTop100AllTime | G37: =IF(COUNTIF(CcliTop100Canada!$D$2:$D$163,D37)>0,"","NO") -> NO
A38: 31 | B38: Hosanna (Praise Is Rising) | C38: Paul Baloche | D38: 4662491 | F38: PraiseChartsTop100AllTime | G38: =IF(COUNTIF(CcliTop100Canada!$D$2:$D$163,D38)>0,"","NO")
A39: 92 | B39: How Deep The Father's Love For Us | C39: Stuart Townend | D39: 1558110 | F39: PraiseChartsTop100AllTime | G39: =IF(COUNTIF(CcliTop100Canada!$D$2:$D$163,D39)>0,"","NO")
A40: 8 | B40: How Great Is Our God | C40: Chris Tomlin | D40: 4348399 | F40: PraiseChartsTop100AllTime | G40: =IF(COUNTIF(CcliTop100Canada!$D$2:$D$163,D40)>0,"","NO")
A41: 43 | B41: How Great Thou Art | C41: Paul Baloche | D41: 14181 | F41: PraiseChartsTop100AllTime | G41: =IF(COUNTIF(CcliTop100Canada!$D$2:$D$163,D41)>0,"","NO")
A42: 64 | B42: How Marvelous (I Stand Amazed) | C42: Chris Tomlin / Passion | D42: 4674207 | F42: PraiseChartsTop100AllTime | G42: =IF(COUNTIF(CcliTop100Canada!$D$2:$D$163,D42)>0,"","NO")
A43: 97 | B43: I Can Only Imagine | C43: MercyMe | D43: 2978857 | F43: PraiseChartsTop100AllTime | G43: =IF(COUNTIF(CcliTop100Canada!$D$2:$D$163,D43)>0,"","NO") -> NO
A44: 48 | B44: I Heard The Bells On Christmas Day | C44: Casting Crowns | D44: 5466490 | F44: PraiseChartsTop100AllTime | G44: =IF(COUNTIF(CcliTop100Canada!$D$2:$D$163,D44)>0,"","NO") -> NO | H44: xmas
A45: 78 | B45: I Will Follow | C45: Chris Tomlin | D45: 5806878 | F45: PraiseChartsTop100AllTime | G45: =IF(COUNTIF(CcliTop100Canada!$D$2:$D$163,D45)>0,"","NO") -> NO
A46: 20 | B46: I Will Rise | C46: Chris Tomlin | D46: 5183450 | F46: PraiseChartsTop100AllTime | G46: =IF(COUNTIF(CcliTop100Canada!$D$2:$D$163,D46)>0,"","NO") -> NO
A47: 15 | B47: In Christ Alone | C47: Travis Cottrell | D47: 3350395 | F47: PraiseChartsTop100AllTime | G47: =IF(COUNTIF(CcliTop100Canada!$D$2:$D$163,D47)>0,"","NO") | H47: dup
A48: 38 | B48: In Christ Alone | C48: Kristian Stanfill / Passion | D48: 3350395 | F48: PraiseChartsTop100AllTime | G48: =IF(COUNTIF(CcliTop100Canada!$D$2:$D$163,D48)>0,"","NO")
A49: 75 | B49: Indescribable | C49: Chris Tomlin / Passion | D49: 4403076 | F49: PraiseChartsTop100AllTime | G49: =IF(COUNTIF(CcliTop100Canada!$D$2:$D$163,D49)>0,"","NO") -> NO
A50: 42 | B50: It Is Well (Grander Earth) | C50: Kristene DiMarco / Bethel Music | D50: 7021972 | F50: PraiseChartsTop100AllTime | G50: =IF(COUNTIF(CcliTop100Canada!$D$2:$D$163,D50)>0,"","NO")
A51: 68 | B51: It's Christmas | C51: Chris Tomlin | D51: #N/A | F51: PraiseChartsTop100AllTime | G51: =IF(COUNTIF(CcliTop100Canada!$D$2:$D$163,D51)>0,"","NO") -> NO | H51: xmas
A52: 89 | B52: Jesus | C52: Chris Tomlin | D52: 7067249 | F52: PraiseChartsTop100AllTime | G52: =IF(COUNTIF(CcliTop100Canada!$D$2:$D$163,D52)>0,"","NO") -> NO
A53: 10 | B53: Jesus Messiah | C53: Chris Tomlin | D53: 5183443 | F53: PraiseChartsTop100AllTime | G53: =IF(COUNTIF(CcliTop100Canada!$D$2:$D$163,D53)>0,"","NO")
A54: 14 | B54: Jesus Paid It All | C54: Kristian Stanfill / Passion | D54: 22331 | F54: PraiseChartsTop100AllTime | G54: =IF(COUNTIF(CcliTop100Canada!$D$2:$D$163,D54)>0,"","NO") -> NO
A55: 6 | B55: Joy To The World (Unspeakable Joy) | C55: Chris Tomlin | D55: #N/A | F55: PraiseChartsTop100AllTime | G55: =IF(COUNTIF(CcliTop100Canada!$D$2:$D$163,D55)>0,"","NO") -> NO | H55: xmas
...

Sheet MultiTracksTop120
A1: Index | B1: Title | C1: Author | D1: CCLI # | E1: Publication Year | F1: Source
A2: 1 | B2: Battle Belongs | C2: Phil Wickham | F2: MultiTracksTop120
A3: 2 | B3: Graves Into Gardens | C3: Elevation Worship | F3: MultiTracksTop120
A4: 3 | B4: Champion | C4: Bethel Music | F4: MultiTracksTop120
A5: 4 | B5: The Blessing | C5: Elevation Worship | F5: MultiTracksTop120
A6: 5 | B6: See a Victory | C6: Elevation Worship | F6: MultiTracksTop120
A7: 6 | B7: Promises | C7: Maverick City Music | F7: MultiTracksTop120
A8: 7 | B8: Goodness of God | C8: Bethel Music | F8: MultiTracksTop120
A9: 8 | B9: God So Loved | C9: We the Kingdom | F9: MultiTracksTop120
A10: 9 | B10: My Testimony | C10: Elevation Worship | F10: MultiTracksTop120
A11: 10 | B11: Never Lost | C11: Elevation Worship | F11: MultiTracksTop120
A12: 11 | B12: We Praise You | C12: Bethel Music | F12: MultiTracksTop120
A13: 12 | B13: There's Nothing That Our God Can't Do (Live) | C13: Passion | F13: MultiTracksTop120
... A121: 120 | B121: Awake My Soul (Live) | C121: Hillsong Worship | F121: MultiTracksTop120

Sheet MultiTracksTop120Global
A1: Index | B1: Title | C1: Author | D1: CCLI # | E1: Publication Year | F1: Source
A2: 1 | B2: Battle Belongs | C2: Phil Wickham | F2: MultiTracksTop120Global
A3: 2 | B3: Graves Into Gardens | C3: Elevation Worship | F3: MultiTracksTop120Global
A4: 3 | B4: Champion | C4: Bethel Music | F4: MultiTracksTop120Global
A5: 4 | B5: The Blessing | C5: Elevation Worship | F5: MultiTracksTop120Global
A6: 5 | B6: See a Victory | C6: Elevation Worship | F6: MultiTracksTop120Global
A7: 6 | B7: Promises | C7: Maverick City Music | F7: MultiTracksTop120Global
A8: 7 | B8: Goodness of God | C8: Bethel Music | F8: MultiTracksTop120Global
A9: 8 | B9: God So Loved | C9: We the Kingdom | F9: MultiTracksTop120Global
A10: 9 | B10: My Testimony | C10: Elevation Worship | F10: MultiTracksTop120Global
A11: 10 | B11: Never Lost | C11: Elevation Worship | F11: MultiTracksTop120Global
A12: 11 | B12: We Praise You | C12: Bethel Music | F12: MultiTracksTop120Global
A13: 12 | B13: Way Maker | C13: Leeland | F13: MultiTracksTop120Global
... A121: 120 | B121: Defender | C121: Jesus Culture | F121: MultiTracksTop120Global

Sheet Top100HymnsBBC
A1: Title | B1: CCLI# | I1: https://www.bbc.co.uk/programmes/articles/42TSJ0LNMfp0h0wNvxqlw93/2013-the-uks-top-100-hymns
A2: How Great Thou Art
A3: In Christ Alone
A4: Be Still, For The Presence Of The Lord
A5: Dear Lord And Father Of Mankind
A6: Here I Am, Lord (I, The Lord Of Sea And Sky)
A7: And Can It Be
A8: Abide With Me
A9: Guide Me, O Thou Great Redeemer/Jehova
A10: Make Me A Channel Of Your Peace
A11: The Day Thou Gavest, Lord, Is Ended
A12: Jerusalem
A13: Great Is Thy Faithfulness
... A101: God Is Love, Let Heaven Adore Him

Sheet Top100HymnsPopularHymns
A1: Title | B1: CCLI# | I1: https://popularhymns.com/top100
A2: A Mighty Fortress Is Our God
A3: Abide With Me
A4: Alas And Did My Savior Bleed?
A5: All Creatures of our God and King
A6: All Hail The Power of Jesus' Name
A7: All The Way My Savior Leads Me
A8: Amazing Grace
A9: Are You Washed in the Blood?
A10: At Calvary
A11: Battle Hymn of the Republic
A12: Be Thou My Vision
A13: Before The Throne of God Above
... A101: Yesterday, Today, Forever

Sheet Top100HymnsJWPepper
A1: Title | B1: CCLI# | I1: https://www.jwpepper.com/Top-100-Hymns-Guitar-Songbook/10089160.item#/submit
A2: A Mighty Fortress Is Our God
A3: Abide With Me
A4: All Creatures Of Our God And King
A5: All Hail The Power Of Jesus Name
A6: Amazing Grace
A7: And Can It Be
A8: Are You Washed In The Blood
A9: At The Cross
A10: Be Thou My Vision
A11: Because He Lives
A12: Bless The Lord O My Soul
A13: Blessed Assurance
... A101: When We All Get To Heaven

Sheet Top100HymnsLifewayWorship
A1: Title | B1: CCLI# | I1: https://genius.com/albums/Lifeway-worship/Top-100-hymns
A2: Holy, Holy, Holy
A3: Crown Him with Many Crowns
A4: All Creatures of Our God and King
A5: It Is Well with My Soul
A6: Great Is Thy Faithfulness
A7: To God Be the Glory
A8: Be Thou My Vision
A9: Amazing Grace! How Sweet the Sound
A10: How Great Thou Art
A11: Come, Thou Fount of Every Blessing
A12: Blessed Assurance, Jesus Is Mine
A13: In Christ Alone (My Hope Is Found)
... A101: The Communion Hymn (Behold the Lamb)
