Workbook

Sheet Statistics
A1: Section | B1: Publication Date | C1: Album | D1: Song Count
A2: 1990-1999 | B2: 1988 | C2: Spirit and Truth | D2: 11
B3: 1990 | C3: Show Your Glory | D3: 14
B4: 1992 | C4: The Power of Your Love | D4: 16
B5: 1993 | C5: Stone's Been Rolled Away | D5: 14
B6: 1994 | C6: People Just Like Us | D6: 14
B7: 1995 | C7: Friends in High Places | D7: 15
B8: 1996 | C8: God Is in the House | D8: 15
B9: 1997 | C9: All Things Are Possible | D9: 15
B10: 1998 | C10: Touching Heaven Changing Earth | D10: 15
B11: 1999 | C11: By Your Side | D11: 14 | E11: =SUM(D2:D11) -> 143
A12: 2000-2009 | B12: 2000 | C12: For This Cause | D12: 14
B13: 2001 | C13: You Are My World | D13: 13
B14: 2002 | C14: Blessed | D14: 14
B15: 2003 | C15: Hope | D15: 18
B16: 2004 | C16: For All You've Done | D16: 15
B17: 2005 | C17: God He Reigns | D17: 15
B18: 2006 | C18: Mighty to Save | D18: 14
B19: 2007 | C19: Saviour King | D19: 14
B20: 2008 | C20: This Is Our God | D20: 16
B21: 2009 | C21: Faith + Hope + Love | D21: 13 | E21: =SUM(D12:D21) -> 146
A22: 2010-2020 | B22: 2010 | C22: A Beautiful Exchange | D22: 13
B23: 2011 | C23: God Is Able | D23: 13
B24: 2012 | C24: Cornerstone | D24: 13
B25: 2013 | C25: Glorious Ruins | D25: 11
B26: 2014 | C26: No Other Name | D26: 11
B27: 2015 | C27: Open Heaven / River Wild | D27: 12
B28: 2016 | C28: Let There Be Light | D28: 12
B29: 2017 | C29: The Peace Project | D29: 12
B30: 2018 | C30: There Is More | D30: 12
B31: 2019 | C31: Awake | D31: 15
B32: 2020 | C32: Take Heart (Again) | D32: 12 | E32: =SUM(D22:D32) -> 136

Sheet Albums
A1: Album # | B1: Album | C1: Publication Date | D1: Type | E1: Category | F1: Song Count | G1: Spotify? | H1: In List? | I1: Exclude
A2: 1 | B2: Spirit and Truth | C2: 1988 | D2: Studio | F2: 11 | G2: not | H2: =IF(COUNTIF(Songs!$B:$B,B2)>0,"","NO") | I2: Exclude
A3: 2 | B3: Show Your Glory | C3: 1990 | D3: Studio | F3: 14 | G3: not | H3: =IF(COUNTIF(Songs!$B:$B,B3)>0,"","NO") | I3: Exclude
A4: 3 | B4: The Power of Your Love | C4: 1992 | D4: Live | F4: 16 | G4: not | H4: =IF(COUNTIF(Songs!$B:$B,B4)>0,"","NO") | I4: Exclude
A5: 4 | B5: Stone's Been Rolled Away | C5: 1993 | D5: Live | F5: 14 | G5: not | H5: =IF(COUNTIF(Songs!$B:$B,B5)>0,"","NO") | I5: Exclude
A6: 5 | B6: People Just Like Us | C6: 1994 | D6: Live | F6: 14 | G6: x | H6: =IF(COUNTIF(Songs!$B:$B,B6)>0,"","NO")
A7: 6 | B7: Friends in High Places | C7: 1995 | D7: Live | F7: 15 | G7: x | H7: =IF(COUNTIF(Songs!$B:$B,B7)>0,"","NO")
B8: Shout To The Lord | C8: 1996 | D8: Live | F8: 16 | G8: only | H8: =IF(COUNTIF(Songs!$B:$B,B8)>0,"","NO") -> NO
A9: 7 | B9: God Is in the House | C9: 1996 | D9: Live | F9: 15 | G9: x | H9: =IF(COUNTIF(Songs!$B:$B,B9)>0,"","NO")
B10: Simply Worship 2 | C10: 1996 | D10: Live | E10: Compilation | F10: 12 | G10: only | H10: =IF(COUNTIF(Songs!$B:$B,B10)>0,"","NO") -> NO | I10: Exclude
B11: Simply Worship | C11: 1996 | D11: Live | E11: Compilation | F11: 12 | G11: only | H11: =IF(COUNTIF(Songs!$B:$B,B11)>0,"","NO") -> NO | I11: Exclude
A12: 8 | B12: All Things Are Possible | C12: 1997 | D12: Live | F12: 15 | G12: x | H12: =IF(COUNTIF(Songs!$B:$B,B12)>0,"","NO")
A13: 9 | B13: Touching Heaven Changing Earth | C13: 1998 | D13: Live | F13: 15 | G13: x | H13: =IF(COUNTIF(Songs!$B:$B,B13)>0,"","NO")
B14: Shout to the Lord 2 | C14: 1997 | D14: Live | F14: 16 | G14: only | H14: =IF(COUNTIF(Songs!$B:$B,B14)>0,"","NO") -> NO
B15: Simply Worship 3 | C15: 1997 | D15: Live | E15: Compilation | F15: 12 | G15: only | H15: =IF(COUNTIF(Songs!$B:$B,B15)>0,"","NO") -> NO | I15: Exclude
A16: 10 | B16: By Your Side | C16: 1999 | D16: Live | F16: 14 | G16: x | H16: =IF(COUNTIF(Songs!$B:$B,B16)>0,"","NO")
B17: The Secret Place | C17: 1999 | D17: Live | F17: 10 | G17: only | H17: =IF(COUNTIF(Songs!$B:$B,B17)>0,"","NO") -> NO
B18: Overwhelmed | C18: 2000 | D18: Live | F18: 12 | G18: only | H18: =IF(COUNTIF(Songs!$B:$B,B18)>0,"","NO") -> NO
A19: 11 | B19: For This Cause | C19: 2000 | D19: Live | F19: 14 | G19: x | H19: =IF(COUNTIF(Songs!$B:$B,B19)>0,"","NO")
B20: Jesus Christmas | C20: 2001 | D20: Live | E20: Christmas | F20: 14 | G20: only | H20: =IF(COUNTIF(Songs!$B:$B,B20)>0,"","NO") -> NO
A21: 12 | B21: You Are My World | C21: 2001 | D21: Live | F21: 13 | G21: x | H21: =IF(COUNTIF(Songs!$B:$B,B21)>0,"","NO")
B22: Extravagant Worship: The Songs Of Reuben Morgan | C22: 2002 | D22: Live | E22: Compilation | F22: 22 | G22: only | H22: =IF(COUNTIF(Songs!$B:$B,B22)>0,"","NO") -> NO | I22: Exclude
B23: Extravagant Worship: The Songs Of Darlene Zschech | C23: 2002 | D23: Live | E23: Compilation | F23: 23 | G23: only | H23: =IF(COUNTIF(Songs!$B:$B,B23)>0,"","NO") -> NO | I23: Exclude
A24: 13 | B24: Blessed | C24: 2002 | D24: Live | F24: 14 | G24: x | H24: =IF(COUNTIF(Songs!$B:$B,B24)>0,"","NO")
B25: Forever | C25: 2003 | D25: Live | F25: 10 | G25: only | H25: =IF(COUNTIF(Songs!$B:$B,B25)>0,"","NO") -> NO
A26: 14 | B26: Hope | C26: 2003 | D26: Live | F26: 18 | G26: x | H26: =IF(COUNTIF(Songs!$B:$B,B26)>0,"","NO")
B27: Faithful | C27: 2004 | D27: Live | F27: 12 | G27: only | H27: =IF(COUNTIF(Songs!$B:$B,B27)>0,"","NO") -> NO
A28: 15 | B28: For All You've Done | C28: 2004 | D28: Live | F28: 15 | G28: x | H28: =IF(COUNTIF(Songs!$B:$B,B28)>0,"","NO")
B29: Unified: Praise | C29: 2004 | D29: Live | E29: Compilation | F29: 11 | G29: only | H29: =IF(COUNTIF(Songs!$B:$B,B29)>0,"","NO") -> NO | I29: Exclude
A30: 16 | B30: God He Reigns | C30: 2005 | D30: Live | F30: 15 | G30: x | H30: =IF(COUNTIF(Songs!$B:$B,B30)>0,"","NO")
B31: Ultimate Worship: Hillsong | C31: 2005 | D31: Live | E31: Compilation | F31: 17 | G31: only | H31: =IF(COUNTIF(Songs!$B:$B,B31)>0,"","NO") -> NO | I31: Exclude
B32: Songs For Communion | C32: 2006 | D32: Live | E32: Compilation | F32: 14 | G32: only | H32: =IF(COUNTIF(Songs!$B:$B,B32)>0,"","NO") -> NO | I32: Exclude
A33: 17 | B33: Mighty to Save | C33: 2006 | D33: Live | F33: 14 | G33: x | H33: =IF(COUNTIF(Songs!$B:$B,B33)>0,"","NO")
B34: Celebrating Christmas | C34: 2006 | D34: Live | E34: Christmas | F34: 12 | G34: only | H34: =IF(COUNTIF(Songs!$B:$B,B34)>0,"","NO") -> NO
A35: 18 | B35: Saviour King | C35: 2007 | D35: Live | F35: 14 | G35: x | H35: =IF(COUNTIF(Songs!$B:$B,B35)>0,"","NO")
A36: 19 | B36: This Is Our God | C36: 2008 | D36: Live | F36: 16 | G36: x | H36: =IF(COUNTIF(Songs!$B:$B,B36)>0,"","NO")
B37: Ultimate Worship 2 | C37: 2008 | D37: Live | E37: Compilation | F37: 17 | G37: only | H37: =IF(COUNTIF(Songs!$B:$B,B37)>0,"","NO") -> NO | I37: Exclude
A38: 20 | B38: Faith + Hope + Love | C38: 2009 | D38: Live | F38: 13 | G38: x | H38: =IF(COUNTIF(Songs!$B:$B,B38)>0,"","NO")
A39: 21 | B39: A Beautiful Exchange | C39: 2010 | D39: Live | F39: 13 | G39: x | H39: =IF(COUNTIF(Songs!$B:$B,B39)>0,"","NO")
A40: 22 | B40: God Is Able | C40: 2011 | D40: Live | F40: 13 | G40: x | H40: =IF(COUNTIF(Songs!$B:$B,B40)>0,"","NO")
...

Sheet Songs
A1: Album Year | B1: Album | C1: Song # | D1: Title | E1: Author | F1: Worship leader(s) | G1: Length | H1: CCLI# | I1: Original Key | J1: Notes
A2: 2020 | B2: Take Heart (Again) | C2: 1 | D2: Hosanna | E2: Brooke Ligertwood | H2: 4785835 | I2: E
A3: 2020 | B3: Take Heart (Again) | C3: 2 | D3: For Those Who Are To Come | E3: Brooke Ligertwood | H3: 4785842 | I3: D
A4: 2020 | B4: Take Heart (Again) | C4: 3 | D4: New Wine | E4: Brooke Ligertwood | H4: 7102397 | I4: Bb
A5: 2020 | B5: Take Heart (Again) | C5: 4 | D5: Heart of God | E5: Aodhan King, Jonas Myrin | H5: 7109453 | I5: C
A6: 2020 | B6: Take Heart (Again) | C6: 5 | D6: I Surrender | E6: Matt Crocker | H6: 6177317 | I6: F
A7: 2020 | B7: Take Heart (Again) | C7: 6 | D7: Selah / All My Life | E7: Bede Benjamin-Korporaal, Ben Tan, Hannah Hobbs, Renee Sieff | H7: 7162357 | I7: B | J7: combo
A8: 2020 | B8: Take Heart (Again) | C8: 7 | D8: Take Heart (MMXX) | E8: Joel Houston | H8: 7162731 | I8: C
A9: 2020 | B9: Take Heart (Again) | C9: 8 | D9: Broken Vessels (Amazing Grace) / Life | E9: Joel Houston, Jonas Myrin | H9: 7019974 | I9: G | J9: combo
A10: 2020 | B10: Take Heart (Again) | C10: 9 | D10: Who You Say I Am | E10: Reuben Morgan, Ben Fielding | H10: 7102401 | I10: A
A11: 2020 | B11: Take Heart (Again) | C11: 10 | D11: Highs, Lows | E11: Aodhan King, Ben Tan, Joel Houston | H11: 7109454 | I11: F
A12: 2020 | B12: Take Heart (Again) | C12: 11 | D12: Eagle's Wings | E12: Reuben Morgan | H12: 2478168 | I12: G
A13: 2020 | B13: Take Heart (Again) | C13: 12 | D13: Still / P E A C E | E13: Benjamin Hastings, Melodie Wagner, Michael Fatkin, Reuben Morgan | H13: 7163384 | I13: A | J13: combo
A14: 2019 | B14: Awake | C14: 1 | D14: Dawn | E14: Brooke Ligertwood | G14: 0.063194444 | H14: N/A | J14: Intro
A15: 2019 | B15: Awake | C15: 2 | D15: Awake My Soul | E15: Brooke Ligertwood | F15: Brooke Ligertwood | G15: 0.18333333 | H15: 7134998 | I15: F
A16: 2019 | B16: Awake | C16: 3 | D16: Come Alive | E16: Michael Fatkin, Benjamin Hastings, Scott Ligertwood | F16: Benjamin Hastings | G16: 0.18888889 | H16: 7134993 | I16: C
A17: 2019 | B17: Awake | C17: 4 | D17: See the Light | E17: Ben Fielding, Reuben Morgan | F17: David Ware | G17: 0.17152778 | H17: 7134996 | I17: F
A18: 2019 | B18: Awake | C18: 5 | D18: No One but You | E18: Scott Ligertwood, Aodhan King, Brooke Ligertwood | F18: Aodhan King, Brooke Ligertwood | G18: 0.37152778 | H18: 7135000 | I18: D
A19: 2019 | B19: Awake | C19: 6 | D19: King of Kings | E19: Jason Ingram, Brooke Ligertwood, Scott Ligertwood | F19: Brooke Ligertwood | G19: 0.18402778 | H19: 7127647 | I19: D
A20: 2019 | B20: Awake | C20: 7 | D20: I Will Praise You | E20: Joel Houston, Ben Fielding, Dylan Thomas, Matt Crocker | F20: Ben Fielding | G20: 0.24305556 | H20: N/A
A21: 2019 | B21: Awake | C21: 8 | D21: From Whom All Blessings Flow (Doxology) | E21: Chris Davenport, Brooke Ligertwood, Scott Ligertwood | F21: Jad Gillies | G21: 0.2 | H21: 7134995 | I21: A
A22: 2019 | B22: Awake | C22: 9 | D22: Every Breath | E22: Hannah Hobbs, Ben Tan | F22: Hannah Hobbs | G22: 0.20208333 | H22: 7134999 | I22: G
A23: 2019 | B23: Awake | C23: 10 | D23: Bright as the Sun | E23: Joel Houston | F23: Joel Houston, Brooke Ligertwood | G23: 0.2625 | H23: 7135001 | I23: F
A24: 2019 | B24: Awake | C24: 11 | D24: Upper Room | E24: Benjamin Hastings, Joel Houston | F24: Taya Gaukrodger | G24: 0.16666667 | H24: 7134994 | I24: E
A25: 2019 | B25: Awake | C25: 12 | D25: He Shall Reign | E25: Ben Fielding, Reuben Morgan | F25: Reuben Morgan | G25: 0.27569444 | H25: 7134997 | I25: E
A26: 2019 | B26: Awake | C26: 13 | D26: See the Light (live) | E26: Ben Fielding, Reuben Morgan | F26: David Ware, Brooke Ligertwood | G26: 0.17361111 | H26: 7134996 | I26: F
A27: 2019 | B27: Awake | C27: 14 | D27: King of Kings (live) | E27: Jason Ingram, Brooke Ligertwood, Scott Ligertwood | F27: Brooke Ligertwood | G27: 0.20208333 | H27: 7127647 | I27: D
A28: 2019 | B28: Awake | C28: 15 | D28: No One but You (live) | E28: Scott Ligertwood, Aodhan King, Brooke Ligertwood | F28: Aodhan King, Brooke Ligertwood | G28: 0.3625 | H28: 7135000 | I28: D
A29: 2018 | B29: There Is More | C29: 1 | D29: Who You Say I Am | E29: Reuben Morgan, Ben Fielding | F29: Brooke Ligertwood, Reuben Morgan | G29: 0.22847222 | H29: 7102401 | I29: A
A30: 2018 | B30: There Is More | C30: 2 | D30: You Are Life | E30: Scott Ligertwood, Aodhan King, Ben Tan, Michael Guy Chislett | F30: Matt Crocker, Karina Wykes | G30: 0.14097222 | H30: 7102402 | I30: C
A31: 2018 | B31: There Is More | C31: 3 | D31: The Passion | E31: Brooke Ligertwood, S. Ligertwood, Chris Davenport | F31: Brooke Ligertwood, Jad Gillies | G31: 0.18888889 | H31: 7102399 | I31: D
A32: 2018 | B32: There Is More | C32: 4 | D32: God So Loved | E32: Matt Crocker, Marty Sampson | F32: David Ware | G32: 0.18819444 | H32: 7102394 | I32: A
... A40: 2018 | B40: There Is More | C40: 12 | D40: So Will I (100 Billion X) | E40: Houston, Fatkin, Hastings | F40: Taya Smith | G40: 0.29444444 | H40: 7084123 | I40: A
A41: 2017 | B41: The Peace Project | C41: 1 | D41: Joy to the World | E41: Isaac Watts, Lowell Mason | F41: Aodhan King | G41: 0.15625 | J41: Uncertain
A42: 2017 | B42: The Peace Project | C42: 2 | D42: Hark | E42: Felix Mendelssohn, Charles Wesley, George Whitefield, William H. Cummings | F42: Taya Smith | G42: 0.21041667 | J42: Uncertain
A43: 2017 | B43: The Peace Project | C43: 3 | D43: Seasons | E43: Chris Davenport, Ben Tan, Benjamin Hastings | F43: Benjamin Hastings | G43: 0.19027778 | H43: 7095538 | I43: C
A44: 2017 | B44: The Peace Project | C44: 4 | D44: Prince of Heaven | E44: Scott Ligertwood, Brooke Ligertwood | F44: Brooke Ligertwood, Matt Crocker | G44: 0.25833333 | H44: 7095645 | I44: Bb
A45: 2017 | B45: The Peace Project | C45: 5 | D45: O Come All Ye Faithful | E45: John Francis Wade, Frederick Oakeley | F45: Karina Wykes | G45: 0.17916667 | H45: 31054 | I45: G
A46: 2017 | B46: The Peace Project | C46: 6 | D46: Noel | E46: William Sandys, Davies Gilbert, John Stainer, Davenport, Benjamin Hastings | F46: Michelle Cook | G46: 0.16736111 | J46: Uncertain
A47: 2017 | B47: The Peace Project | C47: 7 | D47: When I Think Upon Christmas | E47: Aodhan King, Tan, Renee Sieff | F47: Renee Sieff | G47: 0.16388889 | H47: 7095539 | I47: C
...
