Workbook

Sheet Statistics
A1: Category | B1: Count | D1: Volume | E1: Category | F1: Count
A2: TWI Total | B2: 232 | D2: Volume 1 | E2: Vol. 1-12 | F2: 124
A3: ALL CCWS | B3: 186 | E3: Hymns | F3: 20
A4: ALL Other | B4: 163 | E4: Psalms | F4: 12
F5: =SUM(F2:F4) -> 156
A6: Category | B6: Count
A7: Vol. 1-12 | B7: 124 | D7: Volume 2 | E7: Vol. 13-23 | F7: 98
A8: Vol. 13-23 | B8: 98 | E8: TWI Special | F8: 10
A9: TWI Special | B9: 10 | E9: WI Lite | F9: 10
A10: WI Lite | B10: 10 | E10: WI Singles | F10: 1
A11: WI Singles | B11: 1 | E11: Christmas | F11: 20
A12: Hymns | B12: 20 | E12: From CCWS Xmas | F12: 6
A13: Christmas | B13: 20 | F13: =SUM(F7:F12) -> 145
A14: Psalms | B14: 12
A15: From CCWS | B15: 94 | D15: Extra | E15: From CCWS | F15: 94
A16: From CCWS Xmas | B16: 6 | E16: Other | F16: 69
A17: Other | B17: 69 | F17: =SUM(F15:F16) -> 163
B18: =SUM(B7:B17) -> 464

Sheet Albums
A1: # | B1: Year | C1: Title | D1: Tracks | E1: In List? | F1: Year | G1: Notes
A2: 1 | B2: 2014 | C2: The Worship Initiative, Vol. 01 | D2: 10 | E2: =IF(COUNTIF(Songs!$C:$C,C2),"","NO") | F2: 41765
A3: 1 | B3: 2014 | C3: The Worship Initiative, Vol. 02 | D3: 10 | E3: =IF(COUNTIF(Songs!$C:$C,C3),"","NO") | F3: 41786
A4: 1 | B4: 2014 | C4: The Worship Initiative, Vol. 03 | D4: 10 | E4: =IF(COUNTIF(Songs!$C:$C,C4),"","NO") | F4: 41807
A5: 1 | B5: 2014 | C5: The Worship Initiative, Vol. 04 | D5: 10 | E5: =IF(COUNTIF(Songs!$C:$C,C5),"","NO") | F5: 41828
A6: 1 | B6: 2014 | C6: The Worship Initiative, Vol. 05 | D6: 10 | E6: =IF(COUNTIF(Songs!$C:$C,C6),"","NO") | F6: 41849
A7: 1 | B7: 2014 | C7: The Worship Initiative, Vol. 06 | D7: 10 | E7: =IF(COUNTIF(Songs!$C:$C,C7),"","NO") | F7: 41872
A8: 1 | B8: 2014 | C8: The Worship Initiative, Vol. 07 | D8: 10 | E8: =IF(COUNTIF(Songs!$C:$C,C8),"","NO") | F8: 41891
A9: 1 | B9: 2014 | C9: The Worship Initiative, Vol. 08 | D9: 10 | E9: =IF(COUNTIF(Songs!$C:$C,C9),"","NO") | F9: 41912
A10: 1 | B10: 2014 | C10: The Worship Initiative, Vol. 09 | D10: 10 | E10: =IF(COUNTIF(Songs!$C:$C,C10),"","NO") | F10: 41933
A11: 1 | B11: 2014 | C11: The Worship Initiative, Vol. 10 | D11: 10 | E11: =IF(COUNTIF(Songs!$C:$C,C11),"","NO") | F11: 41961
A12: 1 | B12: 2015 | C12: The Worship Initiative | D12: 10 | E12: =IF(COUNTIF(Songs!$C:$C,C12),"","NO") | F12: 42122 | G12: Kickstarter Project
A13: 1 | B13: 2016 | C13: The Worship Initiative, Vol. 11 | D13: 11 | E13: =IF(COUNTIF(Songs!$C:$C,C13),"","NO") | F13: 42643
A14: 1 | B14: 2017 | C14: The Worship Initiative, Vol. 12 | D14: 13 | E14: =IF(COUNTIF(Songs!$C:$C,C14),"","NO") | F14: 42839
A15: 1 | B15: 2017 | C15: The Worship Initiative, Vol. 13 | D15: 5 | E15: =IF(COUNTIF(Songs!$C:$C,C15),"","NO") | F15: 43000
A16: 1 | B16: 2017 | C16: The Worship Initiative, Vol. 14 | D16: 5 | E16: =IF(COUNTIF(Songs!$C:$C,C16),"","NO") | F16: 43039
A17: 1 | B17: 2018 | C17: The Worship Initiative, Vol. 15 | D17: 5 | E17: =IF(COUNTIF(Songs!$C:$C,C17),"","NO") | F17: 43145
A18: 1 | B18: 2018 | C18: The Worship Initiative, Vol. 16 | D18: 10 | E18: =IF(COUNTIF(Songs!$C:$C,C18),"","NO") | F18: 43297
A19: 1 | B19: 2019 | C19: The Worship Initiative, Vol. 17 | D19: 12 | E19: =IF(COUNTIF(Songs!$C:$C,C19),"","NO") | F19: 43630
A20: 1 | B20: 2020 | C20: The Worship Initiative, Vol. 18 | D20: 10 | E20: =IF(COUNTIF(Songs!$C:$C,C20),"","NO") | F20: 43847
A21: 1 | B21: 2020 | C21: The Worship Initiative, Vol. 19 | D21: 10 | E21: =IF(COUNTIF(Songs!$C:$C,C21),"","NO") | F21: 43889
A22: 1 | B22: 2020 | C22: The Worship Initiative, Vol. 20 | D22: 10 | E22: =IF(COUNTIF(Songs!$C:$C,C22),"","NO") | F22: 43924
A23: 1 | B23: 2020 | C23: The Worship Initiative, Vol. 21 | D23: 10 | E23: =IF(COUNTIF(Songs!$C:$C,C23),"","NO") | F23: 44001
A24: 1 | B24: 2020 | C24: The Worship Initiative, Vol. 22 | D24: 11 | E24: =IF(COUNTIF(Songs!$C:$C,C24),"","NO") | F24: 44099
A25: 1 | B25: 2021 | C25: The Worship Initiative, Vol. 23 | D25: 10 | E25: =IF(COUNTIF(Songs!$C:$C,C25),"","NO") | F25: 44204 | G25: Prerelease
A26: 2 | B26: 2018 | C26: Hymns, Vol. 1 | D26: 10 | E26: =IF(COUNTIF(Songs!$C:$C,C26),"","NO") | F26: 43350
A27: 2 | B27: 2018 | C27: Hymns, Vol. 2 | D27: 10 | E27: =IF(COUNTIF(Songs!$C:$C,C27),"","NO") | F27: 43700
A28: 3 | B28: 2017 | C28: A Worship Initiative Christmas, Vol. 1 | D28: 10 | E28: =IF(COUNTIF(Songs!$C:$C,C28),"","NO") | F28: 42839
A29: 3 | B29: 2017 | C29: A Worship Initiative Christmas, Vol. 2 | D29: 10 | E29: =IF(COUNTIF(Songs!$C:$C,C29),"","NO") | F29: 42839
A30: 4 | B30: 2015 | C30: Psalms, Vol. 2 | D30: 12 | E30: =IF(COUNTIF(Songs!$C:$C,C30),"","NO") | F30: 42300
A31: 5 | C31: WI Lite | D31: 10 | E31: =IF(COUNTIF(Songs!$C:$C,C31),"","NO") | G31: Played live but not included on any album
A32: 5 | C32: WI Singles | D32: 1
A33: 6 | C33: CCWS
A34: 7 | C34: CCWS Christmas
A35: 8 | C35: Other
D36: =SUM(D2:D32) -> 295

Sheet Songs
A1: # | B1: Year | C1: Album | D1: Track | E1: Title | F1: Alt Title | G1: Author | H1: Key | I1: Original Key | J1: Tempo (BPM) | K1: Time Signature | L1: CCLI# | M1: Publication Year | N1: Copyright Holder | O1: Category | P1: S&S Author | Q1: S&S Tempo | R1: S&S Key | S1: S&S Adj Key | T1: Files Done | U1: Info Done | V1: CCWS? | W1: S&S? | X1: CCLI100? | Y1: Hillsong? | Z1: Source | AA1: S&S Original | AB1: Other ID | AC1: Notes | AD1: All Keys | AE1: Other CCLI# | AF1: Exclude
A2: =INDEX(Albums!$A:$A, MATCH(C2,Albums!$C:$C,0)) -> 1 | B2: =INDEX(Albums!$B:$B, MATCH(C2,Albums!$C:$C,0)) -> 2014 | C2: The Worship Initiative, Vol. 01 | D2: 1 | E2: Oceans | G2: Joel Houston, Matt Crocker | H2: D | I2: D | J2: 60 | K2: 4/4 | L2: 6428767 | M2: 2012 | N2: Hillsong Music Publishing Australia | O2: Main | P2: Hillsong | Q2: 130 | R2: G | S2: G | T2: Done | U2: Done | V2: =IF(AND(ISNUMBER(L2),COUNTIF([1]Songs!$L:$L,L2)>0),"YES","") -> YES | W2: =IF(AND(ISNUMBER(L2),COUNTIF([2]Songs!$J:$J,L2)>0),"YES","") -> #VALUE! | X2: =IF(AND(ISNUMBER(L2),COUNTIF([3]CcliCombined!$D:$D,L2)>0),"YES","") -> #VALUE! | Y2: =IF(AND(ISNUMBER(L2),COUNTIF([4]Songs!$H:$H,L2)>0),"YES","") -> #VALUE! | Z2: S&S | AB2: 1 | AD2: =I2 &IF(H2=I2,""," "&H2) &IF(OR(R2=I2,R2=H2),""," "&R2) &IF(R2=S2,""," "&S2) -> D G
A3: =INDEX(Albums!$A:$A, MATCH(C3,Albums!$C:$C,0)) -> 1 | B3: =INDEX(Albums!$B:$B, MATCH(C3,Albums!$C:$C,0)) -> 2014 | C3: The Worship Initiative, Vol. 01 | D3: 2 | E3: This Is Amazing Grace | G3: Jeremy Riddle, Josh Farro | H3: G | I3: Bb | J3: 100 | K3: 4/4 | L3: 6333821 | M3: 2012 | N3: Phil Wickham Music | O3: Main | P3: Phil Wickham | Q3: 99 | R3: Bb | S3: A | T3: Done | U3: Done | V3: =IF(AND(ISNUMBER(L3),COUNTIF([1]Songs!$L:$L,L3)>0),"YES","") -> YES | W3: =IF(AND(ISNUMBER(L3),COUNTIF([2]Songs!$J:$J,L3)>0),"YES","") -> #VALUE! | X3: =IF(AND(ISNUMBER(L3),COUNTIF([3]CcliCombined!$D:$D,L3)>0),"YES","") -> #VALUE! | Y3: =IF(AND(ISNUMBER(L3),COUNTIF([4]Songs!$H:$H,L3)>0),"YES","") -> #VALUE! | Z3: S&S | AB3: 2 | AD3: =I3 &IF(H3=I3,""," "&H3) &IF(OR(R3=I3,R3=H3),""," "&R3) &IF(R3=S3,""," "&S3) -> Bb G A
A4: =INDEX(Albums!$A:$A, MATCH(C4,Albums!$C:$C,0)) -> 1 | B4: =INDEX(Albums!$B:$B, MATCH(C4,Albums!$C:$C,0)) -> 2014 | C4: The Worship Initiative, Vol. 01 | D4: 3 | E4: All the Poor and Powerless | G4: David Leonard, Leslie Jordan | H4: A | I4: A | J4: 76 | K4: 4/4 | L4: 5881130 | M4: 2011 | N4: Integrity's Alleluia! Music | O4: Main | P4: All Sons & Daughters | Q4: 72 | R4: B | S4: B | T4: Done | U4: Done | V4: =IF(AND(ISNUMBER(L4),COUNTIF([1]Songs!$L:$L,L4)>0),"YES","") -> YES | W4: =IF(AND(ISNUMBER(L4),COUNTIF([2]Songs!$J:$J,L4)>0),"YES","") -> #VALUE! | X4: =IF(AND(ISNUMBER(L4),COUNTIF([3]CcliCombined!$D:$D,L4)>0),"YES","") -> #VALUE! | Y4: =IF(AND(ISNUMBER(L4),COUNTIF([4]Songs!$H:$H,L4)>0),"YES","") -> #VALUE! | Z4: S&S | AB4: 3 | AD4: =I4 &IF(H4=I4,""," "&H4) &IF(OR(R4=I4,R4=H4),""," "&R4) &IF(R4=S4,""," "&S4) -> A B
A5: =INDEX(Albums!$A:$A, MATCH(C5,Albums!$C:$C,0)) -> 1 | B5: =INDEX(Albums!$B:$B, MATCH(C5,Albums!$C:$C,0)) -> 2014 | C5: The Worship Initiative, Vol. 01 | D5: 4 | E5: Lord I Need You | G5: Christy Nockels, Daniel Carson | H5: B | I5: B | J5: 74 | K5: 4/4 | L5: 5925687 | M5: 2011 | N5: sixsteps Music | O5: Main | P5: Matt Maher | Q5: 72 | R5: B | S5: B | T5: Done | U5: Done | V5: =IF(AND(ISNUMBER(L5),COUNTIF([1]Songs!$L:$L,L5)>0),"YES","") -> YES | W5: =IF(AND(ISNUMBER(L5),COUNTIF([2]Songs!$J:$J,L5)>0),"YES","") -> #VALUE! | X5: =IF(AND(ISNUMBER(L5),COUNTIF([3]CcliCombined!$D:$D,L5)>0),"YES","") -> #VALUE! | Y5: =IF(AND(ISNUMBER(L5),COUNTIF([4]Songs!$H:$H,L5)>0),"YES","") -> #VALUE! | Z5: S&S | AB5: 4 | AD5: =I5 &IF(H5=I5,""," "&H5) &IF(OR(R5=I5,R5=H5),""," "&R5) &IF(R5=S5,""," "&S5) -> B
A6: =INDEX(Albums!$A:$A, MATCH(C6,Albums!$C:$C,0)) -> 1 | B6: =INDEX(Albums!$B:$B, MATCH(C6,Albums!$C:$C,0)) -> 2014 | C6: The Worship Initiative, Vol. 01 | D6: 5 | E6: In Christ Alone | F6: Passion | G6: Keith Getty, Stuart Townend | H6: D | I6: D | J6: 60 | K6: 3/4 | L6: 3350395 | M6: 2001 | N6: Thankyou Music | O6: Main | P6: Passion | Q6: 64 | R6: E | S6: E | T6: Done | U6: Done | V6: =IF(AND(ISNUMBER(L6),COUNTIF([1]Songs!$L:$L,L6)>0),"YES","") -> YES | W6: =IF(AND(ISNUMBER(L6),COUNTIF([2]Songs!$J:$J,L6)>0),"YES","") -> #VALUE! | X6: =IF(AND(ISNUMBER(L6),COUNTIF([3]CcliCombined!$D:$D,L6)>0),"YES","") -> #VALUE! | Y6: =IF(AND(ISNUMBER(L6),COUNTIF([4]Songs!$H:$H,L6)>0),"YES","") -> #VALUE! | Z6: S&S | AB6: 5 | AD6: =I6 &IF(H6=I6,""," "&H6) &IF(OR(R6=I6,R6=H6),""," "&R6) &IF(R6=S6,""," "&S6) -> D E
A7: =INDEX(Albums!$A:$A, MATCH(C7,Albums!$C:$C,0)) -> 1 | B7: =INDEX(Albums!$B:$B, MATCH(C7,Albums!$C:$C,0)) -> 2014 | C7: The Worship Initiative, Vol. 01 | D7: 6 | E7: Beautiful Things | G7: Lisa Gungor, Michael Gungor | H7: D | I7: D | J7: 82 | K7: 4/4 | L7: 5665521 | M7: 2009 | N7: worshiptogether.com | O7: Main | P7: Gungor | Q7: 78 | R7: D | S7: D | T7: Done | U7: Done | V7: =IF(AND(ISNUMBER(L7),COUNTIF([1]Songs!$L:$L,L7)>0),"YES","") | W7: =IF(AND(ISNUMBER(L7),COUNTIF([2]Songs!$J:$J,L7)>0),"YES","") -> #VALUE! | X7: =IF(AND(ISNUMBER(L7),COUNTIF([3]CcliCombined!$D:$D,L7)>0),"YES","") -> #VALUE! | Y7: =IF(AND(ISNUMBER(L7),COUNTIF([4]Songs!$H:$H,L7)>0),"YES","") -> #VALUE! | Z7: S&S | AB7: 6 | AD7: =I7 &IF(H7=I7,""," "&H7) &IF(OR(R7=I7,R7=H7),""," "&R7) &IF(R7=S7,""," "&S7) -> D
A8: =INDEX(Albums!$A:$A, MATCH(C8,Albums!$C:$C,0)) -> 1 | B8: =INDEX(Albums!$B:$B, MATCH(C8,Albums!$C:$C,0)) -> 2014 | C8: The Worship Initiative, Vol. 01 | D8: 7 | E8: Come Thou Fount | F8: Vol. 1 | G8: Robert Robinson, John Wyeth | H8: D | I8: D | J8: 68 | K8: 3/4 | L8: 7029505 | M8: 2013 | N8: Songs From Wellhouse | O8: Main | P8: The Worship Initiative | Q8: 68 | R8: D | S8: D | T8: Done | U8: Done | V8: =IF(AND(ISNUMBER(L8),COUNTIF([1]Songs!$L:$L,L8)>0),"YES","") | W8: =IF(AND(ISNUMBER(L8),COUNTIF([2]Songs!$J:$J,L8)>0),"YES","") -> #VALUE! | X8: =IF(AND(ISNUMBER(L8),COUNTIF([3]CcliCombined!$D:$D,L8)>0),"YES","") -> #VALUE! | Y8: =IF(AND(ISNUMBER(L8),COUNTIF([4]Songs!$H:$H,L8)>0),"YES","") -> #VALUE! | Z8: S&S | AB8: 7 | AD8: =I8 &IF(H8=I8,""," "&H8) &IF(OR(R8=I8,R8=H8),""," "&R8) &IF(R8=S8,""," "&S8) -> D
A9: =INDEX(Albums!$A:$A, MATCH(C9,Albums!$C:$C,0)) -> 1 | B9: =INDEX(Albums!$B:$B, MATCH(C9,Albums!$C:$C,0)) -> 2014 | C9: The Worship Initiative, Vol. 01 | D9: 8 | E9: 10,000 Reasons | G9: Jonas Myrin, Matt Redman | H9: G | I9: G | J9: 73 | K9: 4/4 | L9: 6016351 | M9: 2011 | N9: Atlas Mountain Songs | O9: Main | P9: Matt Redman | Q9: 70 | R9: G | S9: G | T9: Done | U9: Done | V9: =IF(AND(ISNUMBER(L9),COUNTIF([1]Songs!$L:$L,L9)>0),"YES","") -> YES | W9: =IF(AND(ISNUMBER(L9),COUNTIF([2]Songs!$J:$J,L9)>0),"YES","") -> #VALUE! | X9: =IF(AND(ISNUMBER(L9),COUNTIF([3]CcliCombined!$D:$D,L9)>0),"YES","") -> #VALUE! | Y9: =IF(AND(ISNUMBER(L9),COUNTIF([4]Songs!$H:$H,L9)>0),"YES","") -> #VALUE! | Z9: S&S | AB9: 8 | AD9: =I9 &IF(H9=I9,""," "&H9) &IF(OR(R9=I9,R9=H9),""," "&R9) &IF(R9=S9,""," "&S9) -> G
A10: =INDEX(Albums!$A:$A, MATCH(C10,Albums!$C:$C,0)) -> 1 | B10: =INDEX(Albums!$B:$B, MATCH(C10,Albums!$C:$C,0)) -> 2014 | C10: The Worship Initiative, Vol. 01 | D10: 9 | E10: Whom Shall I Fear | F10: God of Angel Armies | G10: Chris Tomlin, Ed Cash | H10: C | I10: C | J10: 75 | K10: 4/4 | L10: 6440288 | M10: 2012 | N10: Alletrop Music | O10: Main | P10: Chris Tomlin | Q10: 74 | R10: C | S10: C | T10: Done | U10: Done | V10: =IF(AND(ISNUMBER(L10),COUNTIF([1]Songs!$L:$L,L10)>0),"YES","") -> YES | W10: =IF(AND(ISNUMBER(L10),COUNTIF([2]Songs!$J:$J,L10)>0),"YES","") -> #VALUE! | X10: =IF(AND(ISNUMBER(L10),COUNTIF([3]CcliCombined!$D:$D,L10)>0),"YES","") -> #VALUE! | Y10: =IF(AND(ISNUMBER(L10),COUNTIF([4]Songs!$H:$H,L10)>0),"YES","") -> #VALUE! | Z10: S&S | AB10: 9 | AD10: =I10 &IF(H10=I10,""," "&H10) &IF(OR(R10=I10,R10=H10),""," "&R10) &IF(R10=S10,""," "&S10) -> C
A11: =INDEX(Albums!$A:$A, MATCH(C11,Albums!$C:$C,0)) -> 1 | B11: =INDEX(Albums!$B:$B, MATCH(C11,Albums!$C:$C,0)) -> 2014 | C11: The Worship Initiative, Vol. 01 | D11: 10 | E11: Happy Day | G11: Ben Cantelon, Tim Hughes | H11: C | I11: C | J11: 152 | K11: 4/4 | L11: 4847027 | M11: 2006 | N11: Thankyou Music | O11: Main | P11: Tim Hughes | Q11: 132 | R11: C | S11: C | T11: Done | U11: Done | V11: =IF(AND(ISNUMBER(L11),COUNTIF([1]Songs!$L:$L,L11)>0),"YES","") | W11: =IF(AND(ISNUMBER(L11),COUNTIF([2]Songs!$J:$J,L11)>0),"YES","") -> #VALUE! | X11: =IF(AND(ISNUMBER(L11),COUNTIF([3]CcliCombined!$D:$D,L11)>0),"YES","") -> #VALUE! | Y11: =IF(AND(ISNUMBER(L11),COUNTIF([4]Songs!$H:$H,L11)>0),"YES","") -> #VALUE! | Z11: S&S | AB11: 10 | AD11: =I11 &IF(H11=I11,""," "&H11) &IF(OR(R11=I11,R11=H11),""," "&R11) &IF(R11=S11,""," "&S11) -> C
A12: =INDEX(Albums!$A:$A, MATCH(C12,Albums!$C:$C,0)) -> 1 | B12: =INDEX(Albums!$B:$B, MATCH(C12,Albums!$C:$C,0)) -> 2014 | C12: The Worship Initiative, Vol. 02 | D12: 1 | E12: Heart Starts Beating | L12: N/A | N12: Seems Like Music | P12: Tim Neufeld | Q12: 112 | R12: A | S12: A | T12: N/A | V12: =IF(AND(ISNUMBER(L12),COUNTIF([1]Songs!$L:$L,L12)>0),"YES","") | W12: =IF(AND(ISNUMBER(L12),COUNTIF([2]Songs!$J:$J,L12)>0),"YES","") -> #VALUE! | X12: =IF(AND(ISNUMBER(L12),COUNTIF([3]CcliCombined!$D:$D,L12)>0),"YES","") -> #VALUE! | Y12: =IF(AND(ISNUMBER(L12),COUNTIF([4]Songs!$H:$H,L12)>0),"YES","") -> #VALUE! | Z12: S&S | AB12: 11 | AC12: Does Not Exist | AD12: =I12 &IF(H12=I12,""," "&H12) &IF(OR(R12=I12,R12=H12),""," "&R12) &IF(R12=S12,""," "&S12) -> A | AF12: Exclude
A13: =INDEX(Albums!$A:$A, MATCH(C13,Albums!$C:$C,0)) -> 1 | B13: =INDEX(Albums!$B:$B, MATCH(C13,Albums!$C:$C,0)) -> 2014 | C13: The Worship Initiative, Vol. 02 | D13: 2 | E13: Hosanna | F13: Praise is Rising | G13: Brenton Brown, Paul Baloche | H13: G | I13: G | J13: 114 | K13: 4/4 | L13: 4662491 | M13: 2006 | N13: Thankyou Music | O13: Main | P13: Paul Baloche | Q13: 106 | R13: A | S13: A | T13: Done | U13: Done | V13: =IF(AND(ISNUMBER(L13),COUNTIF([1]Songs!$L:$L,L13)>0),"YES","") -> YES | W13: =IF(AND(ISNUMBER(L13),COUNTIF([2]Songs!$J:$J,L13)>0),"YES","") -> #VALUE! | X13: =IF(AND(ISNUMBER(L13),COUNTIF([3]CcliCombined!$D:$D,L13)>0),"YES","") -> #VALUE! | Y13: =IF(AND(ISNUMBER(L13),COUNTIF([4]Songs!$H:$H,L13)>0),"YES","") -> #VALUE! | Z13: S&S | AB13: 12 | AD13: =I13 &IF(H13=I13,""," "&H13) &IF(OR(R13=I13,R13=H13),""," "&R13) &IF(R13=S13,""," "&S13) -> G A
A14: =INDEX(Albums!$A:$A, MATCH(C14,Albums!$C:$C,0)) -> 1 | B14: =INDEX(Albums!$B:$B, MATCH(C14,Albums!$C:$C,0)) -> 2014 | C14: The Worship Initiative, Vol. 02 | D14: 3 | E14: Forever Reign | G14: Jason Ingram, Reuben Morgan | H14: C | I14: C | J14: 83 | K14: 4/4 | L14: 5639997 | M14: 2009 | N14: Hillsong Music Publishing Australia | O14: Main | P14: Hillsong | Q14: 83 | R14: C | S14: C | T14: Done | U14: Done | V14: =IF(AND(ISNUMBER(L14),COUNTIF([1]Songs!$L:$L,L14)>0),"YES","") | W14: =IF(AND(ISNUMBER(L14),COUNTIF([2]Songs!$J:$J,L14)>0),"YES","") -> #VALUE! | X14: =IF(AND(ISNUMBER(L14),COUNTIF([3]CcliCombined!$D:$D,L14)>0),"YES","") -> #VALUE! | Y14: =IF(AND(ISNUMBER(L14),COUNTIF([4]Songs!$H:$H,L14)>0),"YES","") -> #VALUE! | Z14: S&S | AB14: 13 | AD14: =I14 &IF(H14=I14,""," "&H14) &IF(OR(R14=I14,R14=H14),""," "&R14) &IF(R14=S14,""," "&S14) -> C
A15: =INDEX(Albums!$A:$A, MATCH(C15,Albums!$C:$C,0)) -> 1 | B15: =INDEX(Albums!$B:$B, MATCH(C15,Albums!$C:$C,0)) -> 2014 | C15: The Worship Initiative, Vol. 02 | D15: 4 | E15: Mercy | G15: Matt Redman, Jonas Myrin | H15: C | I15: C | J15: 73 | K15: 4/4 | L15: 7000689 | M15: 2013 | N15: Atlas Mountain Songs | O15: Main | P15: Matt Redman | Q15: 73 | R15: C | S15: C | T15: Done | U15: Done | V15: =IF(AND(ISNUMBER(L15),COUNTIF([1]Songs!$L:$L,L15)>0),"YES","") -> YES | W15: =IF(AND(ISNUMBER(L15),COUNTIF([2]Songs!$J:$J,L15)>0),"YES","") -> #VALUE! | X15: =IF(AND(ISNUMBER(L15),COUNTIF([3]CcliCombined!$D:$D,L15)>0),"YES","") -> #VALUE! | Y15: =IF(AND(ISNUMBER(L15),COUNTIF([4]Songs!$H:$H,L15)>0),"YES","") -> #VALUE! | Z15: S&S | AB15: 14 | AD15: =I15 &IF(H15=I15,""," "&H15) &IF(OR(R15=I15,R15=H15),""," "&R15) &IF(R15=S15,""," "&S15) -> C
A16: =INDEX(Albums!$A:$A, MATCH(C16,Albums!$C:$C,0)) -> 1 | B16: =INDEX(Albums!$B:$B, MATCH(C16,Albums!$C:$C,0)) -> 2014 | C16: The Worship Initiative, Vol. 02 | D16: 5 | E16: How Great Is Our God | G16: Chris Tomlin, Ed Cash | H16: C | I16: C | J16: 76 | K16: 4/4 | L16: 4348399 | M16: 2004 | N16: sixsteps Music | O16: Main | P16: Chris Tomlin | Q16: 84 | R16: C | S16: C | T16: Done | U16: Done | V16: =IF(AND(ISNUMBER(L16),COUNTIF([1]Songs!$L:$L,L16)>0),"YES","") -> YES | W16: =IF(AND(ISNUMBER(L16),COUNTIF([2]Songs!$J:$J,L16)>0),"YES","") -> #VALUE! | X16: =IF(AND(ISNUMBER(L16),COUNTIF([3]CcliCombined!$D:$D,L16)>0),"YES","") -> #VALUE! | Y16: =IF(AND(ISNUMBER(L16),COUNTIF([4]Songs!$H:$H,L16)>0),"YES","") -> #VALUE! | Z16: S&S | AB16: 15 | AD16: =I16 &IF(H16=I16,""," "&H16) &IF(OR(R16=I16,R16=H16),""," "&R16) &IF(R16=S16,""," "&S16) -> C
A17: =INDEX(Albums!$A:$A, MATCH(C17,Albums!$C:$C,0)) -> 1 | B17: =INDEX(Albums!$B:$B, MATCH(C17,Albums!$C:$C,0)) -> 2014 | C17: The Worship Initiative, Vol. 02 | D17: 6 | E17: You Are My All In All | G17: Dennis Jernigan | H17: F | I17: F | J17: 80 | K17: 4/4 | L17: 825356 | M17: 1991 | N17: Shepherd's Heart Music, Inc. | O17: Main | P17: Dennis Jernigan | Q17: 128 | R17: G | S17: G | T17: Done | U17: Done | V17: =IF(AND(ISNUMBER(L17),COUNTIF([1]Songs!$L:$L,L17)>0),"YES","") -> YES | W17: =IF(AND(ISNUMBER(L17),COUNTIF([2]Songs!$J:$J,L17)>0),"YES","") -> #VALUE! | X17: =IF(AND(ISNUMBER(L17),COUNTIF([3]CcliCombined!$D:$D,L17)>0),"YES","") -> #VALUE! | Y17: =IF(AND(ISNUMBER(L17),COUNTIF([4]Songs!$H:$H,L17)>0),"YES","") -> #VALUE! | Z17: S&S | AB17: 16 | AD17: =I17 &IF(H17=I17,""," "&H17) &IF(OR(R17=I17,R17=H17),""," "&R17) &IF(R17=S17,""," "&S17) -> F G
A18: =INDEX(Albums!$A:$A, MATCH(C18,Albums!$C:$C,0)) -> 1 | B18: =INDEX(Albums!$B:$B, MATCH(C18,Albums!$C:$C,0)) -> 2014 | C18: The Worship Initiative, Vol. 02 | D18: 7 | E18: We Exalt Thee | G18: Pete Sanchez Jr. | I18: F | J18: 70 | K18: 4/4 | L18: 17803 | M18: 1977 | N18: Sanchez, Pete, Jr. | O18: Main | P18: Pete Sanchez Jr. | Q18: 68 | R18: G | S18: G | T18: N/A | U18: Done | V18: =IF(AND(ISNUMBER(L18),COUNTIF([1]Songs!$L:$L,L18)>0),"YES","") | W18: =IF(AND(ISNUMBER(L18),COUNTIF([2]Songs!$J:$J,L18)>0),"YES","") -> #VALUE! | X18: =IF(AND(ISNUMBER(L18),COUNTIF([3]CcliCombined!$D:$D,L18)>0),"YES","") -> #VALUE! | Y18: =IF(AND(ISNUMBER(L18),COUNTIF([4]Songs!$H:$H,L18)>0),"YES","") -> #VALUE! | Z18: S&S | AB18: 17 | AD18: =I18 &IF(H18=I18,""," "&H18) &IF(OR(R18=I18,R18=H18),""," "&R18) &IF(R18=S18,""," "&S18) -> F G
A19: =INDEX(Albums!$A:$A, MATCH(C19,Albums!$C:$C,0)) -> 1 | B19: =INDEX(Albums!$B:$B, MATCH(C19,Albums!$C:$C,0)) -> 2014 | C19: The Worship Initiative, Vol. 02 | D19: 8 | E19: Our God | G19: Chris Tomlin, Jesse Reeves | H19: B | I19: B | J19: 105 | K19: 4/4 | L19: 5677416 | M19: 2010 | N19: Atlas Mountain Songs | O19: Main | P19: Chris Tomlin | Q19: 106 | R19: B | S19: B | T19: Done | U19: Done | V19: =IF(AND(ISNUMBER(L19),COUNTIF([1]Songs!$L:$L,L19)>0),"YES","") -> YES | W19: =IF(AND(ISNUMBER(L19),COUNTIF([2]Songs!$J:$J,L19)>0),"YES","") -> #VALUE! | X19: =IF(AND(ISNUMBER(L19),COUNTIF([3]CcliCombined!$D:$D,L19)>0),"YES","") -> #VALUE! | Y19: =IF(AND(ISNUMBER(L19),COUNTIF([4]Songs!$H:$H,L19)>0),"YES","") -> #VALUE! | Z19: S&S | AB19: 18 | AD19: =I19 &IF(H19=I19,""," "&H19) &IF(OR(R19=I19,R19=H19),""," "&R19) &IF(R19=S19,""," "&S19) -> B
A20: =INDEX(Albums!$A:$A, MATCH(C20,Albums!$C:$C,0)) -> 1 | B20: =INDEX(Albums!$B:$B, MATCH(C20,Albums!$C:$C,0)) -> 2014 | C20: The Worship Initiative, Vol. 02 | D20: 9 | E20: Open the Eyes of My Heart | G20: Paul Baloche | H20: E | I20: E | J20: 112 | K20: 4/4 | L20: 2298355 | M20: 1997 | N20: Integrity's Hosanna! Music | O20: Main | P20: Paul Baloche | Q20: 110 | R20: B | S20: B | T20: Done | U20: Done | V20: =IF(AND(ISNUMBER(L20),COUNTIF([1]Songs!$L:$L,L20)>0),"YES","") -> YES | W20: =IF(AND(ISNUMBER(L20),COUNTIF([2]Songs!$J:$J,L20)>0),"YES","") -> #VALUE! | X20: =IF(AND(ISNUMBER(L20),COUNTIF([3]CcliCombined!$D:$D,L20)>0),"YES","") -> #VALUE! | Y20: =IF(AND(ISNUMBER(L20),COUNTIF([4]Songs!$H:$H,L20)>0),"YES","") -> #VALUE! | Z20: S&S | AB20: 19 | AD20: =I20 &IF(H20=I20,""," "&H20) &IF(OR(R20=I20,R20=H20),""," "&R20) &IF(R20=S20,""," "&S20) -> E B
A21: =INDEX(Albums!$A:$A, MATCH(C21,Albums!$C:$C,0)) -> 1 | B21: =INDEX(Albums!$B:$B, MATCH(C21,Albums!$C:$C,0)) -> 2014 | C21: The Worship Initiative, Vol. 02 | D21: 10 | E21: Better Is One Day | G21: Matt Redman | H21: E | I21: E | J21: 77 | K21: 4/4 | L21: 1097451 | M21: 1995 | N21: Thankyou Music | O21: Main | P21: Matt Redman | Q21: 79 | R21: E | S21: E | T21: Done | U21: Done | V21: =IF(AND(ISNUMBER(L21),COUNTIF([1]Songs!$L:$L,L21)>0),"YES","") -> YES | W21: =IF(AND(ISNUMBER(L21),COUNTIF([2]Songs!$J:$J,L21)>0),"YES","") -> #VALUE! | X21: =IF(AND(ISNUMBER(L21),COUNTIF([3]CcliCombined!$D:$D,L21)>0),"YES","") -> #VALUE! | Y21: =IF(AND(ISNUMBER(L21),COUNTIF([4]Songs!$H:$H,L21)>0),"YES","") -> #VALUE! | Z21: S&S | AB21: 20 | AD21: =I21 &IF(H21=I21,""," "&H21) &IF(OR(R21=I21,R21=H21),""," "&R21) &IF(R21=S21,""," "&S21) -> E
A22: =INDEX(Albums!$A:$A, MATCH(C22,Albums!$C:$C,0)) -> 1 | B22: =INDEX(Albums!$B:$B, MATCH(C22,Albums!$C:$C,0)) -> 2014 | C22: The Worship Initiative, Vol. 03 | D22: 1 | E22: So I Can Love | G22: Chad Cates, Jonathan Abel | L22: 7031125 | M22: 2014 | N22: Icing on the Cates Music | P22: The Worship Initiative | Q22: 124 | R22: Ab | S22: G | T22: N/A | V22: =IF(AND(ISNUMBER(L22),COUNTIF([1]Songs!$L:$L,L22)>0),"YES","") | W22: =IF(AND(ISNUMBER(L22),COUNTIF([2]Songs!$J:$J,L22)>0),"YES","") -> #VALUE! | X22: =IF(AND(ISNUMBER(L22),COUNTIF([3]CcliCombined!$D:$D,L22)>0),"YES","") -> #VALUE! | Y22: =IF(AND(ISNUMBER(L22),COUNTIF([4]Songs!$H:$H,L22)>0),"YES","") -> #VALUE! | Z22: S&S | AB22: 21 | AC22: Lyrics Only | AD22: =I22 &IF(H22=I22,""," "&H22) &IF(OR(R22=I22,R22=H22),""," "&R22) &IF(R22=S22,""," "&S22) -> Ab G | AF22: Exclude
A23: =INDEX(Albums!$A:$A, MATCH(C23,Albums!$C:$C,0)) -> 1 | B23: =INDEX(Albums!$B:$B, MATCH(C23,Albums!$C:$C,0)) -> 2014 | C23: The Worship Initiative, Vol. 03 | D23: 2 | E23: I Will Follow | G23: Jonathan Abel | H23: A | I23: Bb | J23: 96 | K23: 4/4 | L23: 5806878 | M23: 2010 | N23: SHOUT! Music Publishing Australia | O23: Main | P23: Chris Tomlin | Q23: 96 | R23: G | S23: G | T23: Done | U23: Done | V23: =IF(AND(ISNUMBER(L23),COUNTIF([1]Songs!$L:$L,L23)>0),"YES","") -> YES | W23: =IF(AND(ISNUMBER(L23),COUNTIF([2]Songs!$J:$J,L23)>0),"YES","") -> #VALUE! | X23: =IF(AND(ISNUMBER(L23),COUNTIF([3]CcliCombined!$D:$D,L23)>0),"YES","") -> #VALUE! | Y23: =IF(AND(ISNUMBER(L23),COUNTIF([4]Songs!$H:$H,L23)>0),"YES","") -> #VALUE! | Z23: S&S | AB23: 22 | AD23: =I23 &IF(H23=I23,""," "&H23) &IF(OR(R23=I23,R23=H23),""," "&R23) &IF(R23=S23,""," "&S23) -> Bb A G
A24: =INDEX(Albums!$A:$A, MATCH(C24,Albums!$C:$C,0)) -> 1 | B24: =INDEX(Albums!$B:$B, MATCH(C24,Albums!$C:$C,0)) -> 2014 | C24: The Worship Initiative, Vol. 03 | D24: 3 | E24: Liberty | G24: Shane Barnard | L24: 6186872 | M24: 2011 | N24: River Oaks Music Company | P24: Shane & Shane | Q24: 111 | R24: G | S24: G | T24: N/A | V24: =IF(AND(ISNUMBER(L24),COUNTIF([1]Songs!$L:$L,L24)>0),"YES","") | W24: =IF(AND(ISNUMBER(L24),COUNTIF([2]Songs!$J:$J,L24)>0),"YES","") -> #VALUE! | X24: =IF(AND(ISNUMBER(L24),COUNTIF([3]CcliCombined!$D:$D,L24)>0),"YES","") -> #VALUE! | Y24: =IF(AND(ISNUMBER(L24),COUNTIF([4]Songs!$H:$H,L24)>0),"YES","") -> #VALUE! | Z24: S&S | AA24: YES | AB24: 23 | AC24: Lyrics Only | AD24: =I24 &IF(H24=I24,""," "&H24) &IF(OR(R24=I24,R24=H24),""," "&R24) &IF(R24=S24,""," "&S24) -> G | AF24: Exclude
A25: =INDEX(Albums!$A:$A, MATCH(C25,Albums!$C:$C,0)) -> 1 | B25: =INDEX(Albums!$B:$B, MATCH(C25,Albums!$C:$C,0)) -> 2014 | C25: The Worship Initiative, Vol. 03 | D25: 4 | E25: Oh Lord, You're Beautiful | G25: Keith Green | H25: D | I25: D | J25: 54 | K25: 4/4 | L25: 14514 | M25: 1980 | N25: Universal Music | O25: Main | P25: Keith Green | Q25: 56 | R25: G | S25: G | T25: Done | U25: Done | V25: =IF(AND(ISNUMBER(L25),COUNTIF([1]Songs!$L:$L,L25)>0),"YES","") | W25: =IF(AND(ISNUMBER(L25),COUNTIF([2]Songs!$J:$J,L25)>0),"YES","") -> #VALUE! | X25: =IF(AND(ISNUMBER(L25),COUNTIF([3]CcliCombined!$D:$D,L25)>0),"YES","") -> #VALUE! | Y25: =IF(AND(ISNUMBER(L25),COUNTIF([4]Songs!$H:$H,L25)>0),"YES","") -> #VALUE! | Z25: S&S | AB25: 24 | AD25: =I25 &IF(H25=I25,""," "&H25) &IF(OR(R25=I25,R25=H25),""," "&R25) &IF(R25=S25,""," "&S25) -> D G
A26: =INDEX(Albums!$A:$A, MATCH(C26,Albums!$C:$C,0)) -> 1 | B26: =INDEX(Albums!$B:$B, MATCH(C26,Albums!$C:$C,0)) -> 2014 | C26: The Worship Initiative, Vol. 03 | D26: 5 | E26: How He Loves | G26: John Mark McMillan | H26: C | I26: C | J26: 49 | K26: 6/8 | L26: 5032549 | M26: 2005 | N26: Integrity's Hosanna! Music | O26: Main | P26: John Mark McMillan | Q26: 72.5 | R26: C | S26: C | T26: Done | U26: Done | V26: =IF(AND(ISNUMBER(L26),COUNTIF([1]Songs!$L:$L,L26)>0),"YES","") | W26: =IF(AND(ISNUMBER(L26),COUNTIF([2]Songs!$J:$J,L26)>0),"YES","") -> #VALUE! | X26: =IF(AND(ISNUMBER(L26),COUNTIF([3]CcliCombined!$D:$D,L26)>0),"YES","") -> #VALUE! | Y26: =IF(AND(ISNUMBER(L26),COUNTIF([4]Songs!$H:$H,L26)>0),"YES","") -> #VALUE! | Z26: S&S | AB26: 25 | AD26: =I26 &IF(H26=I26,""," "&H26) &IF(OR(R26=I26,R26=H26),""," "&R26) &IF(R26=S26,""," "&S26) -> C
A27: =INDEX(Albums!$A:$A, MATCH(C27,Albums!$C:$C,0)) -> 1 | B27: =INDEX(Albums!$B:$B, MATCH(C27,Albums!$C:$C,0)) -> 2014 | C27: The Worship Initiative, Vol. 03 | D27: 6 | E27: Never Once | G27: Jason Ingram, Matt Redman | H27: B | I27: B | J27: 68 | K27: 4/4 | L27: 5997055 | M27: 2011 | N27: Chrysalis Music Ltd. | O27: Main | P27: Matt Redman | Q27: 70 | R27: C | S27: C | T27: Done | U27: Done | V27: =IF(AND(ISNUMBER(L27),COUNTIF([1]Songs!$L:$L,L27)>0),"YES","") | W27: =IF(AND(ISNUMBER(L27),COUNTIF([2]Songs!$J:$J,L27)>0),"YES","") -> #VALUE! | X27: =IF(AND(ISNUMBER(L27),COUNTIF([3]CcliCombined!$D:$D,L27)>0),"YES","") -> #VALUE! | Y27: =IF(AND(ISNUMBER(L27),COUNTIF([4]Songs!$H:$H,L27)>0),"YES","") -> #VALUE! | Z27: S&S | AB27: 26 | AD27: =I27 &IF(H27=I27,""," "&H27) &IF(OR(R27=I27,R27=H27),""," "&R27) &IF(R27=S27,""," "&S27) -> B C
A28: =INDEX(Albums!$A:$A, MATCH(C28,Albums!$C:$C,0)) -> 1 | B28: =INDEX(Albums!$B:$B, MATCH(C28,Albums!$C:$C,0)) -> 2014 | C28: The Worship Initiative, Vol. 03 | D28: 7 | E28: Shout to the Lord | G28: Darlene Zschech | H28: A | I28: A | J28: 76 | K28: 4/4 | L28: 1406918 | M28: 1993 | N28: Wondrous Worship | O28: Main | P28: Hillsong | Q28: 80 | R28: B | S28: B | T28: Done | U28: Done | V28: =IF(AND(ISNUMBER(L28),COUNTIF([1]Songs!$L:$L,L28)>0),"YES","") -> YES | W28: =IF(AND(ISNUMBER(L28),COUNTIF([2]Songs!$J:$J,L28)>0),"YES","") -> #VALUE! | X28: =IF(AND(ISNUMBER(L28),COUNTIF([3]CcliCombined!$D:$D,L28)>0),"YES","") -> #VALUE! | Y28: =IF(AND(ISNUMBER(L28),COUNTIF([4]Songs!$H:$H,L28)>0),"YES","") -> #VALUE! | Z28: S&S | AB28: 27 | AD28: =I28 &IF(H28=I28,""," "&H28) &IF(OR(R28=I28,R28=H28),""," "&R28) &IF(R28=S28,""," "&S28) -> A B
A29: =INDEX(Albums!$A:$A, MATCH(C29,Albums!$C:$C,0)) -> 1 | B29: =INDEX(Albums!$B:$B, MATCH(C29,Albums!$C:$C,0)) -> 2014 | C29: The Worship Initiative, Vol. 03 | D29: 8 | E29: Before The Throne of God Above | G29: Charitie L. Bancroft, Vikki Cook | H29: D | I29: D | J29: 76 | K29: 3/4 | L29: 2306412 | M29: 1997 | N29: Sovereign Grace Worship | O29: Main | P29: Shane & Shane | Q29: 68 | R29: Eb | S29: D | T29: Done | U29: Done | V29: =IF(AND(ISNUMBER(L29),COUNTIF([1]Songs!$L:$L,L29)>0),"YES","") -> YES | W29: =IF(AND(ISNUMBER(L29),COUNTIF([2]Songs!$J:$J,L29)>0),"YES","") -> #VALUE! | X29: =IF(AND(ISNUMBER(L29),COUNTIF([3]CcliCombined!$D:$D,L29)>0),"YES","") -> #VALUE! | Y29: =IF(AND(ISNUMBER(L29),COUNTIF([4]Songs!$H:$H,L29)>0),"YES","") -> #VALUE! | Z29: S&S | AB29: 28 | AD29: =I29 &IF(H29=I29,""," "&H29) &IF(OR(R29=I29,R29=H29),""," "&R29) &IF(R29=S29,""," "&S29) -> D Eb D
A30: =INDEX(Albums!$A:$A, MATCH(C30,Albums!$C:$C,0)) -> 1 | B30: =INDEX(Albums!$B:$B, MATCH(C30,Albums!$C:$C,0)) -> 2014 | C30: The Worship Initiative, Vol. 03 | D30: 9 | E30: Beautiful One | G30: Tim Hughes | H30: D | I30: D | J30: 122 | K30: 4/4 | L30: 3915912 | M30: 2002 | N30: Thankyou Music | O30: Main | P30: Tim Hughes | Q30: 120 | R30: Eb | S30: D | T30: Done | U30: Done | V30: =IF(AND(ISNUMBER(L30),COUNTIF([1]Songs!$L:$L,L30)>0),"YES","") -> YES | W30: =IF(AND(ISNUMBER(L30),COUNTIF([2]Songs!$J:$J,L30)>0),"YES","") -> #VALUE! | X30: =IF(AND(ISNUMBER(L30),COUNTIF([3]CcliCombined!$D:$D,L30)>0),"YES","") -> #VALUE! | Y30: =IF(AND(ISNUMBER(L30),COUNTIF([4]Songs!$H:$H,L30)>0),"YES","") -> #VALUE! | Z30: S&S | AB30: 29 | AD30: =I30 &IF(H30=I30,""," "&H30) &IF(OR(R30=I30,R30=H30),""," "&R30) &IF(R30=S30,""," "&S30) -> D Eb D
A31: =INDEX(Albums!$A:$A, MATCH(C31,Albums!$C:$C,0)) -> 1 | B31: =INDEX(Albums!$B:$B, MATCH(C31,Albums!$C:$C,0)) -> 2014 | C31: The Worship Initiative, Vol. 03 | D31: 10 | E31: Blessed Be Your Name | G31: Beth Redman, Matt Redman | H31: B | I31: B | J31: 116 | K31: 4/4 | L31: 3798438 | M31: 2002 | N31: Thankyou Music | O31: Main | P31: Matt Redman | Q31: 114 | R31: B | S31: B | T31: Done | U31: Done | V31: =IF(AND(ISNUMBER(L31),COUNTIF([1]Songs!$L:$L,L31)>0),"YES","") -> YES | W31: =IF(AND(ISNUMBER(L31),COUNTIF([2]Songs!$J:$J,L31)>0),"YES","") -> #VALUE! | X31: =IF(AND(ISNUMBER(L31),COUNTIF([3]CcliCombined!$D:$D,L31)>0),"YES","") -> #VALUE! | Y31: =IF(AND(ISNUMBER(L31),COUNTIF([4]Songs!$H:$H,L31)>0),"YES","") -> #VALUE! | Z31: S&S | AB31: 30 | AD31: =I31 &IF(H31=I31,""," "&H31) &IF(OR(R31=I31,R31=H31),""," "&R31) &IF(R31=S31,""," "&S31) -> B
A32: =INDEX(Albums!$A:$A, MATCH(C32,Albums!$C:$C,0)) -> 1 | B32: =INDEX(Albums!$B:$B, MATCH(C32,Albums!$C:$C,0)) -> 2014 | C32: The Worship Initiative, Vol. 04 | D32: 1 | E32: I Stand Amazed | F32: How Marvelous | G32: Charles Hutchinson Gabriel, Chris Tomlin | H32: G | I32: Ab | J32: 68 | K32: 4/4 | L32: 4674207 | M32: 2006 | N32: sixsteps Music | O32: Main | P32: Chris Tomlin | Q32: 104 | R32: A | S32: A | T32: Done | U32: Done | V32: =IF(AND(ISNUMBER(L32),COUNTIF([1]Songs!$L:$L,L32)>0),"YES","") | W32: =IF(AND(ISNUMBER(L32),COUNTIF([2]Songs!$J:$J,L32)>0),"YES","") -> #VALUE! | X32: =IF(AND(ISNUMBER(L32),COUNTIF([3]CcliCombined!$D:$D,L32)>0),"YES","") -> #VALUE! | Y32: =IF(AND(ISNUMBER(L32),COUNTIF([4]Songs!$H:$H,L32)>0),"YES","") -> #VALUE! | Z32: S&S | AB32: 31 | AD32: =I32 &IF(H32=I32,""," "&H32) &IF(OR(R32=I32,R32=H32),""," "&R32) &IF(R32=S32,""," "&S32) -> Ab G A | AE32: 7029507
A33: =INDEX(Albums!$A:$A, MATCH(C33,Albums!$C:$C,0)) -> 1 | B33: =INDEX(Albums!$B:$B, MATCH(C33,Albums!$C:$C,0)) -> 2014 | C33: The Worship Initiative, Vol. 04 | D33: 2 | E33: Our God Is Love | G33: Joel Houston, Scott Ligertwood | H33: F# | I33: F | J33: 121 | K33: 4/4 | L33: 5636866 | M33: 2009 | N33: Hillsong Music Publishing Australia | O33: Main | P33: Hillsong | Q33: 118 | R33: F# | S33: F | T33: Done | U33: Done | V33: =IF(AND(ISNUMBER(L33),COUNTIF([1]Songs!$L:$L,L33)>0),"YES","") | W33: =IF(AND(ISNUMBER(L33),COUNTIF([2]Songs!$J:$J,L33)>0),"YES","") -> #VALUE! | X33: =IF(AND(ISNUMBER(L33),COUNTIF([3]CcliCombined!$D:$D,L33)>0),"YES","") -> #VALUE! | Y33: =IF(AND(ISNUMBER(L33),COUNTIF([4]Songs!$H:$H,L33)>0),"YES","") -> #VALUE! | Z33: S&S | AB33: 32 | AD33: =I33 &IF(H33=I33,""," "&H33) &IF(OR(R33=I33,R33=H33),""," "&R33) &IF(R33=S33,""," "&S33) -> F F# F
A34: =INDEX(Albums!$A:$A, MATCH(C34,Albums!$C:$C,0)) -> 1 | B34: =INDEX(Albums!$B:$B, MATCH(C34,Albums!$C:$C,0)) -> 2014 | C34: The Worship Initiative, Vol. 04 | D34: 3 | E34: Holy Is The Lord | G34: Chris Tomlin, Louie Giglio | H34: A | I34: A | J34: 84 | K34: 4/4 | L34: 4158039 | M34: 2003 | N34: sixsteps Music | O34: Main | P34: Chris Tomlin | Q34: 77 | R34: G | S34: G | T34: Done | U34: Done | V34: =IF(AND(ISNUMBER(L34),COUNTIF([1]Songs!$L:$L,L34)>0),"YES","") | W34: =IF(AND(ISNUMBER(L34),COUNTIF([2]Songs!$J:$J,L34)>0),"YES","") -> #VALUE! | X34: =IF(AND(ISNUMBER(L34),COUNTIF([3]CcliCombined!$D:$D,L34)>0),"YES","") -> #VALUE! | Y34: =IF(AND(ISNUMBER(L34),COUNTIF([4]Songs!$H:$H,L34)>0),"YES","") -> #VALUE! | Z34: S&S | AB34: 33 | AD34: =I34 &IF(H34=I34,""," "&H34) &IF(OR(R34=I34,R34=H34),""," "&R34) &IF(R34=S34,""," "&S34) -> A G
A35: =INDEX(Albums!$A:$A, MATCH(C35,Albums!$C:$C,0)) -> 1 | B35: =INDEX(Albums!$B:$B, MATCH(C35,Albums!$C:$C,0)) -> 2014 | C35: The Worship Initiative, Vol. 04 | D35: 4 | E35: Here For You | G35: Jesse Reeves, Matt Maher | H35: G | I35: Ab | J35: 85 | K35: 4/4 | L35: 5925649 | M35: 2011 | N35: Chrysalis Music Ltd. | O35: Main | P35: Matt Redman | Q35: 86 | R35: C | S35: C | T35: Done | U35: Done | V35: =IF(AND(ISNUMBER(L35),COUNTIF([1]Songs!$L:$L,L35)>0),"YES","") -> YES | W35: =IF(AND(ISNUMBER(L35),COUNTIF([2]Songs!$J:$J,L35)>0),"YES","") -> #VALUE! | X35: =IF(AND(ISNUMBER(L35),COUNTIF([3]CcliCombined!$D:$D,L35)>0),"YES","") -> #VALUE! | Y35: =IF(AND(ISNUMBER(L35),COUNTIF([4]Songs!$H:$H,L35)>0),"YES","") -> #VALUE! | Z35: S&S | AB35: 34 | AD35: =I35 &IF(H35=I35,""," "&H35) &IF(OR(R35=I35,R35=H35),""," "&R35) &IF(R35=S35,""," "&S35) -> Ab G C
A36: =INDEX(Albums!$A:$A, MATCH(C36,Albums!$C:$C,0)) -> 1 | B36: =INDEX(Albums!$B:$B, MATCH(C36,Albums!$C:$C,0)) -> 2014 | C36: The Worship Initiative, Vol. 04 | D36: 5 | E36: Always | G36: Jason Ingram, Kristian Stanfill | H36: B | I36: B | J36: 70 | K36: 4/4 | L36: 5881037 | M36: 2010 | N36: sixsteps Music | O36: Main | P36: Passion | Q36: 72 | R36: C | S36: C | T36: Done | U36: Done | V36: =IF(AND(ISNUMBER(L36),COUNTIF([1]Songs!$L:$L,L36)>0),"YES","") | W36: =IF(AND(ISNUMBER(L36),COUNTIF([2]Songs!$J:$J,L36)>0),"YES","") -> #VALUE! | X36: =IF(AND(ISNUMBER(L36),COUNTIF([3]CcliCombined!$D:$D,L36)>0),"YES","") -> #VALUE! | Y36: =IF(AND(ISNUMBER(L36),COUNTIF([4]Songs!$H:$H,L36)>0),"YES","") -> #VALUE! | Z36: S&S | AB36: 35 | AD36: =I36 &IF(H36=I36,""," "&H36) &IF(OR(R36=I36,R36=H36),""," "&R36) &IF(R36=S36,""," "&S36) -> B C
A37: =INDEX(Albums!$A:$A, MATCH(C37,Albums!$C:$C,0)) -> 1 | B37: =INDEX(Albums!$B:$B, MATCH(C37,Albums!$C:$C,0)) -> 2014 | C37: The Worship Initiative, Vol. 04 | D37: 6 | E37: Here I Am To Worship | G37: Tim Hughes | H37: E | I37: E | J37: 75 | K37: 4/4 | L37: 3266032 | M37: 2000 | N37: Thankyou Music | O37: Main | P37: Tim Hughes | Q37: 69 | R37: C | S37: C | T37: Done | U37: Done | V37: =IF(AND(ISNUMBER(L37),COUNTIF([1]Songs!$L:$L,L37)>0),"YES","") -> YES | W37: =IF(AND(ISNUMBER(L37),COUNTIF([2]Songs!$J:$J,L37)>0),"YES","") -> #VALUE! | X37: =IF(AND(ISNUMBER(L37),COUNTIF([3]CcliCombined!$D:$D,L37)>0),"YES","") -> #VALUE! | Y37: =IF(AND(ISNUMBER(L37),COUNTIF([4]Songs!$H:$H,L37)>0),"YES","") -> #VALUE! | Z37: S&S | AB37: 36 | AD37: =I37 &IF(H37=I37,""," "&H37) &IF(OR(R37=I37,R37=H37),""," "&R37) &IF(R37=S37,""," "&S37) -> E C
A38: =INDEX(Albums!$A:$A, MATCH(C38,Albums!$C:$C,0)) -> 1 | B38: =INDEX(Albums!$B:$B, MATCH(C38,Albums!$C:$C,0)) -> 2014 | C38: The Worship Initiative, Vol. 04 | D38: 7 | E38: Worthy of Affection | G38: Shane Barnard, Shane Everett | H38: C | I38: C | J38: 56 | K38: 4/4 | L38: 5627772 | M38: 2009 | N38: River Oaks Music Company | O38: Main | P38: Shane & Shane | Q38: 58 | R38: C | S38: C | T38: NoNumber | U38: Done | V38: =IF(AND(ISNUMBER(L38),COUNTIF([1]Songs!$L:$L,L38)>0),"YES","") | W38: =IF(AND(ISNUMBER(L38),COUNTIF([2]Songs!$J:$J,L38)>0),"YES","") -> #VALUE! | X38: =IF(AND(ISNUMBER(L38),COUNTIF([3]CcliCombined!$D:$D,L38)>0),"YES","") -> #VALUE! | Y38: =IF(AND(ISNUMBER(L38),COUNTIF([4]Songs!$H:$H,L38)>0),"YES","") -> #VALUE! | Z38: S&S | AA38: YES | AB38: 37 | AD38: =I38 &IF(H38=I38,""," "&H38) &IF(OR(R38=I38,R38=H38),""," "&R38) &IF(R38=S38,""," "&S38) -> C
A39: =INDEX(Albums!$A:$A, MATCH(C39,Albums!$C:$C,0)) -> 1 | B39: =INDEX(Albums!$B:$B, MATCH(C39,Albums!$C:$C,0)) -> 2014 | C39: The Worship Initiative, Vol. 04 | D39: 8 | E39: Healer | G39: Mike Guglielmucci | H39: B | I39: B | J39: 80 | K39: 4/4 | L39: 4873981 | M39: 2007 | N39: Planetshakers Ministries Int. Inc. | O39: Main | P39: Hillsong | Q39: 77 | R39: A | S39: A | T39: Done | U39: Done | V39: =IF(AND(ISNUMBER(L39),COUNTIF([1]Songs!$L:$L,L39)>0),"YES","") -> YES | W39: =IF(AND(ISNUMBER(L39),COUNTIF([2]Songs!$J:$J,L39)>0),"YES","") -> #VALUE! | X39: =IF(AND(ISNUMBER(L39),COUNTIF([3]CcliCombined!$D:$D,L39)>0),"YES","") -> #VALUE! | Y39: =IF(AND(ISNUMBER(L39),COUNTIF([4]Songs!$H:$H,L39)>0),"YES","") -> #VALUE! | Z39: S&S | AB39: 38 | AD39: =I39 &IF(H39=I39,""," "&H39) &IF(OR(R39=I39,R39=H39),""," "&R39) &IF(R39=S39,""," "&S39) -> B A
A40: =INDEX(Albums!$A:$A, MATCH(C40,Albums!$C:$C,0)) -> 1 | B40: =INDEX(Albums!$B:$B, MATCH(C40,Albums!$C:$C,0)) -> 2014 | C40: The Worship Initiative, Vol. 04 | D40: 9 | E40: It Is Well | F40: Hymn | G40: Horatio Gates Spafford, Philip Paul Bliss | H40: C | I40: C | J40: 82 | K40: 4/4 | L40: 25376 | M40: 1873 | N40: Public Domain | O40: Main | P40: The Worship Initiative | Q40: 68 | R40: Db | S40: C | T40: Done | U40: Done | V40: =IF(AND(ISNUMBER(L40),COUNTIF([1]Songs!$L:$L,L40)>0),"YES","") -> YES | W40: =IF(AND(ISNUMBER(L40),COUNTIF([2]Songs!$J:$J,L40)>0),"YES","") -> #VALUE! | X40: =IF(AND(ISNUMBER(L40),COUNTIF([3]CcliCombined!$D:$D,L40)>0),"YES","") -> #VALUE! | Y40: =IF(AND(ISNUMBER(L40),COUNTIF([4]Songs!$H:$H,L40)>0),"YES","") -> #VALUE! | Z40: S&S | AB40: 39 | AD40: =I40 &IF(H40=I40,""," "&H40) &IF(OR(R40=I40,R40=H40),""," "&R40) &IF(R40=S40,""," "&S40) -> C Db C | AE40: 7029513
...
