Workbook

Sheet Statistics
A1: Category | B1: Count | D1: Volume | E1: Category | F1: Count
A2: TWI Total | B2: 232 | D2: Volume 1 | E2: Vol. 1-12 | F2: 124
A3: ALL CCWS | B3: 186 | E3: Hymns | F3: 20
A4: ALL Other | B4: 163 | E4: Psalms | F4: 12
F5: =SUM(F2:F4) -> 156
A6: Category | B6: Count
A7: Vol. 1-12 | B7: 124 | D7: Volume 2 | E7: Vol. 13-23 | F7: 98
A8: Vol. 13-23 | B8: 98 | E8: TWI Special | F8: 10
A9: TWI Special | B9: 10 | E9: WI Lite | F9: 10
A10: WI Lite | B10: 10 | E10: WI Singles | F10: 1
A11: WI Singles | B11: 1 | E11: Christmas | F11: 20
A12: Hymns | B12: 20 | E12: From CCWS Xmas | F12: 6
A13: Christmas | B13: 20 | F13: =SUM(F7:F12) -> 145
A14: Psalms | B14: 12
A15: From CCWS | B15: 94 | D15: Extra | E15: From CCWS | F15: 94
A16: From CCWS Xmas | B16: 6 | E16: Other | F16: 69
A17: Other | B17: 69 | F17: =SUM(F15:F16) -> 163
B18: =SUM(B7:B17) -> 464

Sheet Albums
A1: # | B1: Year | C1: Title | D1: Tracks | E1: In List? | F1: Band | G1: Type | H1: Category | I1: Exclude | J1: Release Date | K1: AlbumArt | L1: Notes
A2: 1 | B2: 2002 | C2: Psalms, Vol. 1 | D2: 13 | E2: =IF(COUNTIF(Songs!$C:$C,C2)>0,"","NO") | G2: Studio | H2: Psalms | I2: Exclude | J2: 37411 | K2: YES | L2: Not on TWI
A3: 2 | B3: 2003 | C3: Carry Away | D3: 13 | E3: =IF(COUNTIF(Songs!$C:$C,C3)>0,"","NO") | F3: Original | G3: Studio | I3: Exclude | J3: April 22, 2003 | K3: YES
A4: 3 | B4: 2004 | C4: Clean | D4: 11 | E4: =IF(COUNTIF(Songs!$C:$C,C4)>0,"","NO") | F4: Original | G4: Studio | I4: Exclude | J4: October 19, 2004 | K4: YES
A5: 4 | B5: 2004 | C5: Upstairs | D5: 10 | E5: =IF(COUNTIF(Songs!$C:$C,C5)>0,"","NO") | F5: Original | G5: Studio | I5: Exclude | J5: May 18, 2004 | K5: YES
A6: 5 | B6: 2007 | C6: Pages | D6: 15 | E6: =IF(COUNTIF(Songs!$C:$C,C6)>0,"","NO") | F6: Original | G6: Studio | I6: Exclude | J6: August 28, 2007 | K6: YES
A7: 6 | B7: 2008 | C7: Glory in the Highest, A Christmas Record | D7: 10 | E7: =IF(COUNTIF(Songs!$C:$C,C7)>0,"","NO") | G7: Studio | H7: Christmas | I7: Exclude | J7: 39735 | K7: YES | L7: Not on TWI
A8: 7 | B8: 2009 | C8: Everything Is Different | D8: 15 | E8: =IF(COUNTIF(Songs!$C:$C,C8)>0,"","NO") | F8: Original | G8: Studio | I8: Exclude | J8: 40120 | K8: YES
A9: 8 | B9: 2010 | C9: Dare 2 Share, Unending Worship | D9: 10 | E9: =IF(COUNTIF(Songs!$C:$C,C9)>0,"","NO") | F9: Original | G9: Studio | I9: Exclude | J9: 40470 | K9: YES
A10: 9 | B10: 2011 | C10: The One You Need | D10: 12 | E10: =IF(COUNTIF(Songs!$C:$C,C10)>0,"","NO") | F10: Original | G10: Studio | I10: Exclude | J10: 40820 | K10: YES
A11: 10 | B11: 2013 | C11: Bring Your Nothing | D11: 11 | E11: =IF(COUNTIF(Songs!$C:$C,C11)>0,"","NO") | F11: Original | G11: Studio | I11: Exclude | J11: 41408 | K11: YES
A12: 11 | B12: 2014 | C12: The Worship Initiative, Vol. 01 | D12: 10 | E12: =IF(COUNTIF(Songs!$C:$C,C12)>0,"","NO") | F12: TWI | G12: Studio | J12: 41765 | K12: YES
A13: 12 | B13: 2014 | C13: The Worship Initiative, Vol. 02 | D13: 10 | E13: =IF(COUNTIF(Songs!$C:$C,C13)>0,"","NO") | F13: TWI | G13: Studio | J13: 41786 | K13: YES
A14: 13 | B14: 2014 | C14: The Worship Initiative, Vol. 03 | D14: 10 | E14: =IF(COUNTIF(Songs!$C:$C,C14)>0,"","NO") | F14: TWI | G14: Studio | J14: 41807 | K14: YES
A15: 14 | B15: 2014 | C15: The Worship Initiative, Vol. 04 | D15: 10 | E15: =IF(COUNTIF(Songs!$C:$C,C15)>0,"","NO") | F15: TWI | G15: Studio | J15: 41828 | K15: YES
A16: 15 | B16: 2014 | C16: The Worship Initiative, Vol. 05 | D16: 10 | E16: =IF(COUNTIF(Songs!$C:$C,C16)>0,"","NO") | F16: TWI | G16: Studio | J16: 41849 | K16: YES
A17: 16 | B17: 2014 | C17: The Worship Initiative, Vol. 06 | D17: 10 | E17: =IF(COUNTIF(Songs!$C:$C,C17)>0,"","NO") | F17: TWI | G17: Studio | J17: 41872 | K17: YES
A18: 17 | B18: 2014 | C18: The Worship Initiative, Vol. 07 | D18: 10 | E18: =IF(COUNTIF(Songs!$C:$C,C18)>0,"","NO") | F18: TWI | G18: Studio | J18: 41891 | K18: YES
A19: 18 | B19: 2014 | C19: The Worship Initiative, Vol. 08 | D19: 10 | E19: =IF(COUNTIF(Songs!$C:$C,C19)>0,"","NO") | F19: TWI | G19: Studio | J19: 41912 | K19: YES
A20: 19 | B20: 2014 | C20: The Worship Initiative, Vol. 09 | D20: 10 | E20: =IF(COUNTIF(Songs!$C:$C,C20)>0,"","NO") | F20: TWI | G20: Studio | J20: 41933 | K20: YES
A21: 20 | B21: 2014 | C21: The Worship Initiative, Vol. 10 | D21: 10 | E21: =IF(COUNTIF(Songs!$C:$C,C21)>0,"","NO") | F21: TWI | G21: Studio | J21: 41961 | K21: YES
A22: 21 | B22: 2015 | C22: Psalms, Vol. 2 | D22: 12 | E22: =IF(COUNTIF(Songs!$C:$C,C22)>0,"","NO") | G22: Studio | H22: Psalms | J22: 42300 | K22: YES
A23: 22 | B23: 2015 | C23: The Worship Initiative | D23: 10 | E23: =IF(COUNTIF(Songs!$C:$C,C23)>0,"","NO") | F23: TWI | G23: Studio | J23: 42122 | K23: YES | L23: Kickstarter Project
A24: 23 | B24: 2016 | C24: Psalms (Live) | D24: 13 | E24: =IF(COUNTIF(Songs!$C:$C,C24)>0,"","NO") | G24: Live | H24: Psalms | I24: Exclude | J24: 42698 | K24: YES | L24: Not on TWI
A25: 24 | B25: 2016 | C25: The Worship Initiative, Vol. 11 | D25: 11 | E25: =IF(COUNTIF(Songs!$C:$C,C25)>0,"","NO") | F25: TWI | G25: Studio | J25: 42643 | K25: YES
A26: 25 | B26: 2017 | C26: A Worship Initiative Christmas, Vol. 1 | D26: 10 | E26: =IF(COUNTIF(Songs!$C:$C,C26)>0,"","NO") | G26: Studio | H26: Christmas | J26: 42839 | K26: YES
A27: 26 | B27: 2017 | C27: A Worship Initiative Christmas, Vol. 2 | D27: 10 | E27: =IF(COUNTIF(Songs!$C:$C,C27)>0,"","NO") | G27: Studio | H27: Christmas | J27: 42839 | K27: YES
A28: 27 | B28: 2017 | C28: The Worship Initiative, Vol. 12 | D28: 13 | E28: =IF(COUNTIF(Songs!$C:$C,C28)>0,"","NO") | F28: TWI | G28: Studio | J28: 42839 | K28: YES
A29: 28 | B29: 2017 | C29: The Worship Initiative, Vol. 13 | D29: 5 | E29: =IF(COUNTIF(Songs!$C:$C,C29)>0,"","NO") | F29: TWI | G29: Studio | J29: 43000 | K29: YES
A30: 29 | B30: 2017 | C30: The Worship Initiative, Vol. 14 | D30: 5 | E30: =IF(COUNTIF(Songs!$C:$C,C30)>0,"","NO") | F30: TWI | G30: Studio | J30: 43039 | K30: YES
A31: 30 | B31: 2018 | C31: Hymns, Vol. 1 | D31: 10 | E31: =IF(COUNTIF(Songs!$C:$C,C31)>0,"","NO") | G31: Studio | H31: Hymns | J31: 43350 | K31: YES
A32: 31 | B32: 2018 | C32: Hymns, Vol. 2 | D32: 10 | E32: =IF(COUNTIF(Songs!$C:$C,C32)>0,"","NO") | G32: Studio | H32: Hymns | J32: 43700 | K32: YES
A33: 32 | B33: 2018 | C33: The Worship Initiative, Vol. 15 | D33: 5 | E33: =IF(COUNTIF(Songs!$C:$C,C33)>0,"","NO") | F33: TWI | G33: Studio | J33: 43145 | K33: YES
A34: 33 | B34: 2018 | C34: The Worship Initiative, Vol. 16 | D34: 10 | E34: =IF(COUNTIF(Songs!$C:$C,C34)>0,"","NO") | F34: TWI | G34: Studio | J34: 43297 | K34: YES
A35: 34 | B35: 2019 | C35: Hymns (Live) | D35: 13 | E35: =IF(COUNTIF(Songs!$C:$C,C35)>0,"","NO") | G35: Live | H35: Hymns | J35: 43504 | K35: YES | L35: Lots of duplicates
A36: 35 | B36: 2019 | C36: A Worship Initiative Christmas, Vol. 3 | D36: 5 | E36: =IF(COUNTIF(Songs!$C:$C,C36)>0,"","NO") | G36: Studio | H36: Christmas | I36: Exclude | J36: 43797 | K36: YES | L36: Mainly duplicates of Vol. 1
A37: 36 | B37: 2019 | C37: The Worship Initiative, Vol. 17 | D37: 12 | E37: =IF(COUNTIF(Songs!$C:$C,C37)>0,"","NO") | F37: TWI | G37: Studio | J37: 43630 | K37: YES
A38: 37 | B38: 2020 | C38: The Worship Initiative, Vol. 18 | D38: 10 | E38: =IF(COUNTIF(Songs!$C:$C,C38)>0,"","NO") | F38: TWI | G38: Studio | J38: 43847 | K38: YES
A39: 38 | B39: 2020 | C39: The Worship Initiative, Vol. 19 | D39: 10 | E39: =IF(COUNTIF(Songs!$C:$C,C39)>0,"","NO") | F39: TWI | G39: Studio | J39: 43889 | K39: YES
A40: 39 | B40: 2020 | C40: The Worship Initiative, Vol. 20 | D40: 10 | E40: =IF(COUNTIF(Songs!$C:$C,C40)>0,"","NO") | F40: TWI | G40: Studio | J40: 43924 | K40: YES
...

Sheet Songs
A1: # | B1: Year | C1: Album | D1: Track | E1: Title | F1: Alt Title | G1: Author | H1: Key | I1: Tempo | J1: CCLI# | K1: Notes | L1: Status | M1: CCWS? | N1: Author | O1: Key | P1: Original Key | Q1: Tempo (BPM) | R1: Time Signature | S1: CCLI Song # | T1: Publication Year | U1: Copyright Holder | V1: CCLI# Accurate
A2: =INDEX(Albums!$A:$A, MATCH(C2,Albums!$C:$C,0)) -> 1 | B2: =INDEX(Albums!$B:$B, MATCH(C2,Albums!$C:$C,0)) -> 2002 | C2: Psalms, Vol. 1 | D2: 1 | E2: Breath of God
A3: =INDEX(Albums!$A:$A, MATCH(C3,Albums!$C:$C,0)) -> 1 | B3: =INDEX(Albums!$B:$B, MATCH(C3,Albums!$C:$C,0)) -> 2002 | C3: Psalms, Vol. 1 | D3: 2 | E3: Unto You
A4: =INDEX(Albums!$A:$A, MATCH(C4,Albums!$C:$C,0)) -> 1 | B4: =INDEX(Albums!$B:$B, MATCH(C4,Albums!$C:$C,0)) -> 2002 | C4: Psalms, Vol. 1 | D4: 3 | E4: Revive Me | F4: Psalm 143
A5: =INDEX(Albums!$A:$A, MATCH(C5,Albums!$C:$C,0)) -> 1 | B5: =INDEX(Albums!$B:$B, MATCH(C5,Albums!$C:$C,0)) -> 2002 | C5: Psalms, Vol. 1 | D5: 4 | E5: The Answer
A6: =INDEX(Albums!$A:$A, MATCH(C6,Albums!$C:$C,0)) -> 1 | B6: =INDEX(Albums!$B:$B, MATCH(C6,Albums!$C:$C,0)) -> 2002 | C6: Psalms, Vol. 1 | D6: 5 | E6: Psalm 13
A7: =INDEX(Albums!$A:$A, MATCH(C7,Albums!$C:$C,0)) -> 1 | B7: =INDEX(Albums!$B:$B, MATCH(C7,Albums!$C:$C,0)) -> 2002 | C7: Psalms, Vol. 1 | D7: 6 | E7: Psalm 145
A8: =INDEX(Albums!$A:$A, MATCH(C8,Albums!$C:$C,0)) -> 1 | B8: =INDEX(Albums!$B:$B, MATCH(C8,Albums!$C:$C,0)) -> 2002 | C8: Psalms, Vol. 1 | D8: 7 | E8: Waiting Room
A9: =INDEX(Albums!$A:$A, MATCH(C9,Albums!$C:$C,0)) -> 1 | B9: =INDEX(Albums!$B:$B, MATCH(C9,Albums!$C:$C,0)) -> 2002 | C9: Psalms, Vol. 1 | D9: 8 | E9: Job 19
A10: =INDEX(Albums!$A:$A, MATCH(C10,Albums!$C:$C,0)) -> 1 | B10: =INDEX(Albums!$B:$B, MATCH(C10,Albums!$C:$C,0)) -> 2002 | C10: Psalms, Vol. 1 | D10: 9 | E10: This Is the Day | F10: Psalm 118
A11: =INDEX(Albums!$A:$A, MATCH(C11,Albums!$C:$C,0)) -> 1 | B11: =INDEX(Albums!$B:$B, MATCH(C11,Albums!$C:$C,0)) -> 2002 | C11: Psalms, Vol. 1 | D11: 10 | E11: Praise the Name of Jesus
A12: =INDEX(Albums!$A:$A, MATCH(C12,Albums!$C:$C,0)) -> 1 | B12: =INDEX(Albums!$B:$B, MATCH(C12,Albums!$C:$C,0)) -> 2002 | C12: Psalms, Vol. 1 | D12: 11 | E12: We've Come to Declare
A13: =INDEX(Albums!$A:$A, MATCH(C13,Albums!$C:$C,0)) -> 1 | B13: =INDEX(Albums!$B:$B, MATCH(C13,Albums!$C:$C,0)) -> 2002 | C13: Psalms, Vol. 1 | D13: 12 | E13: You Said
A14: =INDEX(Albums!$A:$A, MATCH(C14,Albums!$C:$C,0)) -> 1 | B14: =INDEX(Albums!$B:$B, MATCH(C14,Albums!$C:$C,0)) -> 2002 | C14: Psalms, Vol. 1 | D14: 13 | E14: Hosea
A15: =INDEX(Albums!$A:$A, MATCH(C15,Albums!$C:$C,0)) -> 2 | B15: =INDEX(Albums!$B:$B, MATCH(C15,Albums!$C:$C,0)) -> 2003 | C15: Carry Away | D15: 1 | E15: Barren Land
A16: =INDEX(Albums!$A:$A, MATCH(C16,Albums!$C:$C,0)) -> 2 | B16: =INDEX(Albums!$B:$B, MATCH(C16,Albums!$C:$C,0)) -> 2003 | C16: Carry Away | D16: 2 | E16: Carry Away
A17: =INDEX(Albums!$A:$A, MATCH(C17,Albums!$C:$C,0)) -> 2 | B17: =INDEX(Albums!$B:$B, MATCH(C17,Albums!$C:$C,0)) -> 2003 | C17: Carry Away | D17: 3 | E17: Be Near
A18: =INDEX(Albums!$A:$A, MATCH(C18,Albums!$C:$C,0)) -> 2 | B18: =INDEX(Albums!$B:$B, MATCH(C18,Albums!$C:$C,0)) -> 2003 | C18: Carry Away | D18: 4 | E18: Mercy Reigns
A19: =INDEX(Albums!$A:$A, MATCH(C19,Albums!$C:$C,0)) -> 2 | B19: =INDEX(Albums!$B:$B, MATCH(C19,Albums!$C:$C,0)) -> 2003 | C19: Carry Away | D19: 5 | E19: Song of Surrender
A20: =INDEX(Albums!$A:$A, MATCH(C20,Albums!$C:$C,0)) -> 2 | B20: =INDEX(Albums!$B:$B, MATCH(C20,Albums!$C:$C,0)) -> 2003 | C20: Carry Away | D20: 6 | E20: I Want It All
A21: =INDEX(Albums!$A:$A, MATCH(C21,Albums!$C:$C,0)) -> 2 | B21: =INDEX(Albums!$B:$B, MATCH(C21,Albums!$C:$C,0)) -> 2003 | C21: Carry Away | D21: 7 | E21: When I Think About the Lord | G21: James Huey
A22: =INDEX(Albums!$A:$A, MATCH(C22,Albums!$C:$C,0)) -> 2 | B22: =INDEX(Albums!$B:$B, MATCH(C22,Albums!$C:$C,0)) -> 2003 | C22: Carry Away | D22: 8 | E22: Beauty for Ashes | G22: Barnard, Kendall Combs
A23: =INDEX(Albums!$A:$A, MATCH(C23,Albums!$C:$C,0)) -> 2 | B23: =INDEX(Albums!$B:$B, MATCH(C23,Albums!$C:$C,0)) -> 2003 | C23: Carry Away | D23: 9 | E23: Sweet Illumination | G23: Barnard, Shane Everett
A24: =INDEX(Albums!$A:$A, MATCH(C24,Albums!$C:$C,0)) -> 2 | B24: =INDEX(Albums!$B:$B, MATCH(C24,Albums!$C:$C,0)) -> 2003 | C24: Carry Away | D24: 10 | E24: Hearts of Servants
A25: =INDEX(Albums!$A:$A, MATCH(C25,Albums!$C:$C,0)) -> 2 | B25: =INDEX(Albums!$B:$B, MATCH(C25,Albums!$C:$C,0)) -> 2003 | C25: Carry Away | D25: 11 | E25: The Blood
A26: =INDEX(Albums!$A:$A, MATCH(C26,Albums!$C:$C,0)) -> 2 | B26: =INDEX(Albums!$B:$B, MATCH(C26,Albums!$C:$C,0)) -> 2003 | C26: Carry Away | D26: 12 | E26: Water of the Word
A27: =INDEX(Albums!$A:$A, MATCH(C27,Albums!$C:$C,0)) -> 2 | B27: =INDEX(Albums!$B:$B, MATCH(C27,Albums!$C:$C,0)) -> 2003 | C27: Carry Away | D27: 13 | E27: Be Near | F27: Radio Version
A28: =INDEX(Albums!$A:$A, MATCH(C28,Albums!$C:$C,0)) -> 3 | B28: =INDEX(Albums!$B:$B, MATCH(C28,Albums!$C:$C,0)) -> 2004 | C28: Clean | D28: 1 | E28: Saved by Grace | G28: Shane Barnard
A29: =INDEX(Albums!$A:$A, MATCH(C29,Albums!$C:$C,0)) -> 3 | B29: =INDEX(Albums!$B:$B, MATCH(C29,Albums!$C:$C,0)) -> 2004 | C29: Clean | D29: 2 | E29: Fringes | G29: Barnard
A30: =INDEX(Albums!$A:$A, MATCH(C30,Albums!$C:$C,0)) -> 3 | B30: =INDEX(Albums!$B:$B, MATCH(C30,Albums!$C:$C,0)) -> 2004 | C30: Clean | D30: 3 | E30: He Is Exalted | G30: Twila Paris
A31: =INDEX(Albums!$A:$A, MATCH(C31,Albums!$C:$C,0)) -> 3 | B31: =INDEX(Albums!$B:$B, MATCH(C31,Albums!$C:$C,0)) -> 2004 | C31: Clean | D31: 4 | E31: Waging War | G31: Barnard
A32: =INDEX(Albums!$A:$A, MATCH(C32,Albums!$C:$C,0)) -> 3 | B32: =INDEX(Albums!$B:$B, MATCH(C32,Albums!$C:$C,0)) -> 2004 | C32: Clean | D32: 5 | E32: Make Believe Jesus | G32: Barnard
A33: =INDEX(Albums!$A:$A, MATCH(C33,Albums!$C:$C,0)) -> 3 | B33: =INDEX(Albums!$B:$B, MATCH(C33,Albums!$C:$C,0)) -> 2004 | C33: Clean | D33: 6 | E33: You and I | G33: Barnard, Shane Everett
A34: =INDEX(Albums!$A:$A, MATCH(C34,Albums!$C:$C,0)) -> 3 | B34: =INDEX(Albums!$B:$B, MATCH(C34,Albums!$C:$C,0)) -> 2004 | C34: Clean | D34: 7 | E34: Yearn | G34: Barnard
A35: =INDEX(Albums!$A:$A, MATCH(C35,Albums!$C:$C,0)) -> 3 | B35: =INDEX(Albums!$B:$B, MATCH(C35,Albums!$C:$C,0)) -> 2004 | C35: Clean | D35: 8 | E35: God Did | G35: Barnard
A36: =INDEX(Albums!$A:$A, MATCH(C36,Albums!$C:$C,0)) -> 3 | B36: =INDEX(Albums!$B:$B, MATCH(C36,Albums!$C:$C,0)) -> 2004 | C36: Clean | D36: 9 | E36: Acres of Hope | G36: Barnard, Robbie Seay
A37: =INDEX(Albums!$A:$A, MATCH(C37,Albums!$C:$C,0)) -> 3 | B37: =INDEX(Albums!$B:$B, MATCH(C37,Albums!$C:$C,0)) -> 2004 | C37: Clean | D37: 10 | E37: There Is None Like You
A38: =INDEX(Albums!$A:$A, MATCH(C38,Albums!$C:$C,0)) -> 3 | B38: =INDEX(Albums!$B:$B, MATCH(C38,Albums!$C:$C,0)) -> 2004 | C38: Clean | D38: 11 | E38: Your Grace Is Sufficient | G38: Martin Nystrom
A39: =INDEX(Albums!$A:$A, MATCH(C39,Albums!$C:$C,0)) -> 4 | B39: =INDEX(Albums!$B:$B, MATCH(C39,Albums!$C:$C,0)) -> 2004 | C39: Upstairs | D39: 1 | E39: Psalm 13
A40: =INDEX(Albums!$A:$A, MATCH(C40,Albums!$C:$C,0)) -> 4 | B40: =INDEX(Albums!$B:$B, MATCH(C40,Albums!$C:$C,0)) -> 2004 | C40: Upstairs | D40: 2 | E40: Holy
...
